Workbook

Sheet 00_工作流总控
A1: 前景清单与绘图工作流 | K1: 实时检查 | L1: 结果
A2: 数据功能按用户确认的文献清单工作流推进；闸门 B 确认冻结范围后，绘图功能另行启动。 | K2: 未解决问题 | L2: =COUNTIF('问题与决策'!$I$5:$I$204,"未解决")
K3: BLOCKED 检查 | L3: =COUNTIF('核算检查'!$K$5:$K$204,"BLOCKED")
A4: 阶段 | B4: 任务 | C4: 输入 | D4: 输出 | E4: 完成条件 | F4: 状态 | G4: 负责人/确认人 | H4: 版本/日期 | I4: 备注 | K4: 数据功能确认 | L4: =COUNTIF('绘图确认'!$P$5:$P$204,"已确认")
A5: S01 | B5: S1.1–S1.3 课题、文献与原始清单 | C5: 研究课题与候选来源 | D5: 课题摘要和原始清单核验 | E5: C1 的完整指完整生命周期清单；缺文件已报告 | F5: 完成 | G5: 用户（2026-09-27） | H5: 2026-09-27 | I5: C1通过；S1.3多版本核验完成：DIB数据集原始版为权威版（Q-12），衍生版降级 | K5: 绘图功能入口 | L5: =IF(AND(L2=0,L3=0,L4>0),"可进入","暂不可进入")
A6: S02 | B6: S1.4 双文献池分类 | C6: 来源文件及依赖 | D6: 完整清单池、参数选取池 | E6: C2 完整清单池非空；一篇来源可兼任两池 | F6: 完成 | H6: 2026-09-27 | I6: 完整清单池=SYS-GUY-2024-DIB（SRC-RAW）；SYS-WHEY-2023（衍生版）入参数池
A7: S03 | B7: S2.1 分文献整理方案 | C7: 候选来源与课题 | D7: 方法、边界与取数方案 | E7: 目标口径及前景/背景接口已说明 | F7: 完成 | H7: 2026-09-27 | I7: 方法口径见项目说明
A8: S04 | B8: S2.2–S2.3 框架选择与闸门A | C8: 完整清单文献池 | D8: 框架文献及单元操作结构 | E8: 用户确认框架；否决理由及候选处理留痕 | F8: 已确认 | G8: 用户（2026-09-27） | H8: 2026-09-27 | I8: 框架D-A2：SRC-RAW 20步（用户2026-09-27确认）
A9: S05 | B9: S3.1–S3.3 基准、最小黑箱与覆盖度 | C9: 框架文献与附件 | D9: 模块划分和参数覆盖度矩阵 | E9: 功能单位、边界、操作粒度及缺口已登记 | F9: 完成 | H9: 2026-09-27 | I9: 19个单元操作，覆盖矩阵已建
A10: S06 | B10: S3.4 全部流识别 | C10: 模块与操作结构 | D10: 输入、输出、内部转移和循环流 | E10: 逐流端点、方向与边界已登记 | F10: 完成 | H10: 2026-09-27 | I10: 主物流10+条；能源/清洗/化学品/污水/资本品300+条（v2补入，含设备级资本品81条，WPI边界）
A11: S07 | B11: D1、S3.5–S3.7 公式溯源与逐流卡 | C11: 来源参数、公式和流 | D11: 采用参数、流及公式依赖 | E11: 公式递归到输入参数；流卡有证据和稳定ID | F11: 完成 | H11: 2026-09-27 | I11: 派生流公式见模型流与公式表
A12: S08 | B12: QC 清单复核 | C12: 参数、公式、流与覆盖矩阵 | D12: 核算检查与问题标记 | E12: 复查仍有问题已及时向用户报告并记录决定 | F12: 完成 | H12: 2026-09-27 | I12: 核算检查CH-01~CH-11、CH-15~CH-17（WPI边界）；Q-01~Q-17登记（Q-13/14随PR13-19移出不适用）
A13: S09 | B13: S4.1 汇报与闸门B | C13: 模块化清单、覆盖度、问题 | D13: Excel与待补参数清单 | E13: 用户确认清单、待补项及可冻结范围 | F13: 已确认 | G13: 用户（2026-09-28） | H13: 2026-09-27 | I13: v2.2冻结（2026-09-28用户确认）：WPI边界——系统边界至WPI浓缩液出厂，PR13-19（α/β蛋白分离）移出；基线SRC-RAW原始记录层；全产品系统清单；不分配/不替代/不做LCIA；资本品纳入；唯一开放待补项GB-04（污水站proxy口径）
A14: S10 | B14: 绘图功能内容蓝图 | C14: 冻结 Excel | D14: 绘图确认 | E14: 显示决定经用户另行确认 | F14: 未开始 | I14: 需冻结后启动
A15: S11 | B15: Draw.io 绘制复检 | C15: 已确认规格 | D15: 原生 .drawio | E15: 结构、内容与渲染检查通过 | F15: 未开始 | I15: 需冻结后启动

Sheet 项目说明
A1: 项目说明
A3: 字段 | B3: 填写值 | C3: 说明
A4: 项目编号 | B4: WHEY-LCI-2026-0927 | C4: 稳定工作编号
A5: 目标来源范围 | B5: SYS-GUY-2024-DIB（DIB开放数据集5文件：原始清单SRC-RAW为权威框架来源；SRC-COMP/SRC-MODEL同数据集；v231127两份为衍生版，降级为参数来源） | C5: 从完整清单文献池选择框架；没有候选则补充审查，不自动纯建模
A6: 目标产品系统 | B6: 乳清蛋白浓缩（WPI）产品系统：WPI浓缩液为主产品；奶油、胶束酪蛋白、浓缩乳糖、渗透水为联产品
A7: 产品名称 | B7: WPI浓缩液（Whey Protein Isolate concentrate，11.7 m³/d）
A8: 功能单位 | B8: 1 天生产（原始基准以体积 m³/d 为主；主产品 WPI 浓缩液 11.7 m³/d，对应原料奶 583 m³/d。用户决定不分配：全产品系统清单，主产品/联产品/废水并列输出）
A9: 系统边界 | B9: 原料奶接收（农场大门之后）→ WPI 浓缩液出厂（含第10步 4°C 100 km 冷藏运输）；含乳糖回收（PR11-12）、清洗废水处理（PR20，原文标注为背景过程但清单值给出）；含设备资本品（Machines段设备/部件级材料按天摊销）；α/β 乳清蛋白分离（PR13-19）按用户 2026-09-28 裁定移出系统边界；不含电力/化学品生产等背景过程
A10: 建模模式 | B10: consequential | C10: 用户确认目标 ALCA 或 CLCA；不得由来源自动代填
A11: 背景数据库类型 | B11: 未连接（缺口见 Q-08/待补参数清单） | C11: 按目标研究记录背景数据库及版本
A12: 分配政策 | B12: 用户决定（2026-09-29 更正，见 Q-19）：课题 CLCA 与框架文献（ALCA）范式不同——放弃文献分配因子（四套 AF 保留候选作对照留档，不进入课题模型）；边际供应商与副产品替代接口待功能三确定；物理流不执行分配/替代处理；不做 LCIA | C12: 物理流与 ALCA 分配或 CLCA 替代处理分开
A13: 副产品替代状态 | B13: 待建（用户 2026-09-29 更正，见 Q-19）：课题 CLCA——副产品替代接口与边际供应商由目标研究在功能三确定 | C13: 副产品替代接口及供应商待目标研究确认
A14: 数值情景 | B14: representative | C14: 经确认的图示代表情景；不把全部代表值称为中位数
A15: 工作簿版本 | B15: 4.2
A16: 数据功能状态 | B16: frozen
A17: 冻结版本 | B17: v2.2（2026-09-28 确认；WPI边界：原料奶→WPI浓缩液出厂，PR13-19 α/β蛋白分离移出；基线SRC-RAW原始记录层，体积基准 m³/d，功能单位1天生产；v2.1补3条联产品出厂流，v2.2补WPI出厂流FL-O-WPI）；2026-09-29 范式口径更正见 Q-19 | C17: 数据功能确认后填写
A18: 工艺路线 | B18: 主文献锚定 | C18: 当前工作流只允许经闸门A确认的主文献锚定路线
A19: 整链主来源体系ID | B19: SYS-GUY-2024-DIB | C19: 闸门A确认的框架来源体系ID
A20: 产品质量规格 | B20: 主产品：WPI 浓缩液 11.7 m³/d（8_UF1 输出、10_TS 后出厂；原文未给 WPI 干物质组成规格） | C20: 纯度、湿干基或其他可比性条件
A21: 来源路线确认记录 | B21: D-A2（用户2026-09-27确认：采用DIB数据集原始版为权威框架，取代v1.0之D-A1衍生版锚定） | C21: 关联问题与决策 ID 或确认日期
A22: 数据功能用户确认 | B22: 用户确认（2026-09-28，WPI边界重建）：功能单位按原文1天生产（原料奶583 m³/d，WPI浓缩液11.7 m³/d）；系统边界至WPI浓缩液出厂（含第10步4°C 100km冷藏运输），PR13-19 α/β蛋白分离移出，乳糖回收保留；基线=SRC-RAW原始记录层；全产品系统清单；不分配/不替代/不做LCIA；资本品纳入；唯一开放待补项GB-04（污水站proxy口径） | C22: 未明确确认不得将工作簿标为冻结

Sheet 数据来源
A1: 数据来源
A2: 一行一个文件；候选值的页码/单元格见“候选数据”。同一研究的正文、附件和代码共用来源体系ID。
A4: 来源ID | B4: 文件名 | C4: 来源类型 | D4: 页码/章节/工作表 | E4: 单元格/公式位置 | F4: 原始内容摘要 | G4: 适用对象ID | H4: 证据状态 | I4: 备注 | J4: 来源体系ID | K4: 文件角色 | L4: 来源独立性 | M4: 上游依赖 | N4: 原研究方法 | O4: 工艺覆盖 | P4: 原功能单位 | Q4: 详细提取状态 | R4: 文献池角色 | S4: 完整清单证据
A5: SRC-PDF | B5: LCI_Process_diagram_and_allocation_data_v231127.pdf | C5: 工艺图PDF（整链前景清单） | D5: p1（单页流程图） | E5: 19个步骤框及逐流参数表 | F5: 19步乳清蛋白分级工艺逐流 V/m/ρ/脂肪/DM/蛋白/价格/AF；水输入 63/35/31.1/2.7/66.93/4.6/5.7/1.0 m³/j；MF2两级计算框；干燥专家参数；组成小图（Figure n°X） | G5: PR01-PR19 | H5: 已提取 | I5: 数据集示意图层文件（v231127，与SRC-RAW同属DIB数据集包，recherche.data.gouv.fr DOI 10.57745/7D0ROH）：由原始体积×密度换算质量、AF修约至2位小数、丢弃能源/清洗/化学品/污水；独有内容：组成%%、虚构价格、干燥专家参数、Figure n°X组成图——保留为候选并标注衍生版来源。多版本核验见Q-12；用户2026-09-28指示：示意图层全部数据仅作简单参考，不作基准/标准；基线=数据集原始记录层（SRC-RAW） | J5: SYS-WHEY-2023 | K5: 主文（工艺图与清单） | L5: 独立（单源体系） | M5: 部分参数二手引用 Gesan-Guiziou et al (2019)（未核原文） | N5: ALCA（提供4种分配规则因子） | O5: 收奶→乳清蛋白分级全链（19步） | P5: 1 天生产（kg/j） | Q5: 已提取 | R5: 参数选取文献池 | S5: 整链清单：全工艺19步逐流数值表（本PDF单页，含全部输入/输出/内部流质量与组成）
A6: SRC-XLSX | B6: LCI_Allocations_factors_v231127.xlsx | C6: Excel附件（分配因子表） | D6: allocation_tables | E6: A1:T8 | F6: 8个分配步骤 × 4规则（mass/dry matter/protein/economic）共42个非零分配因子 | G6: 联产品分配参数 PA-AF-* | H6: 已提取 | I6: 衍生版分配因子表（2位小数修约）；数值与 SRC-COMP 未修约值一致；SRC-COMP 存在 cream AF eco 抄录疑似笔误，本表修约值经交叉核对采用 | J6: SYS-WHEY-2023 | K6: 附件（分配因子汇总表） | L6: 与 SRC-PDF 同源 | M6: 转引 SRC-PDF 各框 AF | N6: ALCA（4规则） | O6: 同上 | P6: 1 天生产（kg/j） | Q6: 已提取 | R6: 参数选取文献池 | S6: 分配因子汇总表（SRC-PDF 数值的结构化整理，同一来源体系）
A7: SRC-RAW | B7: WPI-Guyomarc'h2024.xlsx | C7: Excel原始清单（DIB数据集权威版） | D7: 20张步骤表(1_RCS~20_STEP)+Process diagram | E7: 每表 Materials/Energy/Others/Machines/TOTALs/Cleaning/Outputs 段 | F7: 逐步原始LCI：体积基准物料流、逐步电力(kWh/d)与燃气热(MJ/d)、化学品(NH3/柠檬酸/CaCl2/NaOH/FeCl)、清洗段(电/热/水/NaOH/HNO3/COD废水)、机器材料、第20步污水处理及出水负荷 | G7: PR01-PR20（本清单按WPI边界采用PR01-12+PR20；PR13-19 α/β蛋白分离移出） | H7: 已提取 | I7: Process diagram表自述：Figure 1 & Table 2 of Gesan-Guiziou et al. (2019) 的简化汇编；数据源自2009/2010实测campaign | J7: SYS-GUY-2024-DIB | K7: 框架主数据（原始清单） | L7: 独立 | M7: 底层引用 Gesan-Guiziou et al. (2019) | N7: ALCA（4种分配规则，分配表见SRC-XLSX） | O7: 收奶→WPI浓缩液出厂（PR01-12）＋乳糖回收＋清洗废水处理（PR20）；PR13-19 α/β蛋白分离按用户2026-09-28裁定移出系统边界 | P7: 1 天生产（体积基准 m³/d 为主） | Q7: 已提取 | R7: 完整清单文献池;参数选取文献池 | S7: 整链清单：20步逐步LCI（本工作簿框架来源，权威版）
A8: SRC-COMP | B8: WPI-流程-成分Guyomarc'h2024.xlsx | C8: Excel工作底稿（流程框全精度值） | D8: Feuil1 | E8: 框式布局 | F8: 各流V/m/ρ/组成/价格/AF未修约全精度值；与SRC-PDF框值同版（2位小数修约前） | G8: 组成/AF候选核对 | H8: 已提取 | I8: 排版为工作底稿（左右框行交错、cream AF eco疑似抄录笔误），仅作数值核对证据，不直接取数 | J8: SYS-GUY-2024-DIB | K8: 同数据集工作底稿 | L8: 与SRC-RAW同源 | M8: 转引SRC-PDF框值 | N8: ALCA | O8: 同上 | P8: 1 天生产 | Q8: 已提取 | R8: 参数选取文献池 | S8: 未修约数值核对证据
A9: SRC-MODEL | B9: WPI-建模Guyomarc'h2024.xlsx | C9: Excel建模实现（SimaPro版） | D9: 1_RCS~19_D2+Explorer | E9: 逐步背景映射表 | F9: 每步SimaPro实现：ecoinvent 3.8背景过程映射（电力/蒸汽/自来水/废水/钢材）、mass与dry matter两种分配变体 | G9: 背景接口元数据 | H9: 已提取 | I9: 提供背景数据库接口位置（未来接背景库时的映射依据）；本工作簿不计算LCIA | J9: SYS-GUY-2024-DIB | K9: 同数据集建模版 | L9: 与SRC-RAW同源 | M9: ecoinvent 3.8 | N9: ALCA（mass/dry matter两变体） | O9: 同上 | P9: 1 天生产 | Q9: 已提取 | R9: 参数选取文献池 | S9: 背景映射证据（ecoinvent 3.8）

Sheet 模型过程
A1: 模型过程
A2: 以作者实际计算过程为主骨架；设备操作默认写入内部操作说明。
A4: 过程ID | B4: 产品系统 | C4: 功能车间 | D4: 模型过程原名 | E4: 中文名称 | F4: 流程顺序 | G4: 模型粒度 | H4: 内部操作说明 | I4: 主支线角色 | J4: 来源ID | K4: 模型采用状态 | L4: 图中展开方式 | M4: 确认状态 | N4: 备注 | O4: 工艺骨架依据 | P4: 骨架确认决策ID
A5: PR01 | B5: 乳清蛋白分级产品系统 | C5: M1 收奶与分离 | D5: Reception (8°C) → Cooling (8°C-4°C) → Storage (4°C) | E5: 收奶冷却储存 | F5: 1 | G5: 单元操作 | I5: 主线 | J5: SRC-PDF | K5: 采用（草稿） | L5: 单操作框 | M5: 草稿 | N5: 骨架依据：SRC-PDF p1 步骤1框 | O5: SRC-RAW 01_* 步骤表＋SRC-PDF p1 步骤框 | P5: D-A2（用户2026-09-27确认）
A6: PR02 | B6: 乳清蛋白分级产品系统 | C6: M1 收奶与分离 | D6: Milk skimming (50°C) | E6: 奶脂离心分离 | F6: 2 | G6: 单元操作 | I6: 主线 | J6: SRC-PDF | K6: 采用（草稿） | L6: 单操作框 | M6: 草稿 | N6: 骨架依据：SRC-PDF p1 步骤2框 | O6: SRC-RAW 02_* 步骤表＋SRC-PDF p1 步骤框 | P6: D-A2（用户2026-09-27确认）
A7: PR03 | B7: 乳清蛋白分级产品系统 | C7: M1 收奶与分离 | D7: Cream cooling (50°C-8°C) → Storage (8°C) | E7: 奶油冷却储存 | F7: 3 | G7: 单元操作 | I7: 支线（奶油） | J7: SRC-PDF | K7: 采用（草稿） | L7: 单操作框 | M7: 草稿 | N7: 骨架依据：SRC-PDF p1 步骤3框 | O7: SRC-RAW 03_* 步骤表＋SRC-PDF p1 步骤框 | P7: D-A2（用户2026-09-27确认）
A8: PR04 | B8: 乳清蛋白分级产品系统 | C8: M1 收奶与分离 | D8: Pasteurization (72°C-20s) → Cooling (72°C-6°C) → Storage (6°C) | E8: 脱脂奶巴氏杀菌冷却储存 | F8: 4 | G8: 单元操作 | I8: 主线 | J8: SRC-PDF | K8: 采用（草稿） | L8: 单操作框 | M8: 草稿 | N8: 骨架依据：SRC-PDF p1 步骤4框 | O8: SRC-RAW 04_* 步骤表＋SRC-PDF p1 步骤框 | P8: D-A2（用户2026-09-27确认）
A9: PR05 | B9: 乳清蛋白分级产品系统 | C9: M2 牛奶蛋白分级 | D9: Heating (6°C-50°C) + Fractionation of milk proteins (MF–0.1μm), MF1 FRV=3 | E9: 牛奶蛋白微滤分级 | F9: 5 | G9: 单元操作 | I9: 主线 | J9: SRC-PDF | K9: 采用（草稿） | L9: 单操作框 | M9: 草稿 | N9: 骨架依据：SRC-PDF p1 步骤5框 | O9: SRC-RAW 05_* 步骤表＋SRC-PDF p1 步骤框 | P9: D-A2（用户2026-09-27确认）
A10: PR06 | B10: 乳清蛋白分级产品系统 | C10: M2 牛奶蛋白分级 | D10: Retentate cooling (50°C-4°C) → Storage (4°C) | E10: 胶束酪蛋白冷却储存 | F10: 6 | G10: 单元操作 | I10: 支线（胶束酪蛋白） | J10: SRC-PDF | K10: 采用（草稿） | L10: 单操作框 | M10: 草稿 | N10: 骨架依据：SRC-PDF p1 步骤6框 | O10: SRC-RAW 06_* 步骤表＋SRC-PDF p1 步骤框 | P10: D-A2（用户2026-09-27确认）
A11: PR07 | B11: 乳清蛋白分级产品系统 | C11: M2 牛奶蛋白分级 | D11: Whey cooling (50°C-15°C) → Storage (15°C) | E11: 乳清冷却储存 | F11: 7 | G11: 单元操作 | I11: 主线 | J11: SRC-PDF | K11: 采用（草稿） | L11: 单操作框 | M11: 草稿 | N11: 骨架依据：SRC-PDF p1 步骤7框 | O11: SRC-RAW 07_* 步骤表＋SRC-PDF p1 步骤框 | P11: D-A2（用户2026-09-27确认）
A12: PR08 | B12: 乳清蛋白分级产品系统 | C12: M3 乳清蛋白浓缩 | D12: Concentration of whey proteins (UF10 + diafiltration)，水 63 m³/j | E12: 乳清蛋白超滤浓缩透析 | F12: 8 | G12: 单元操作 | I12: 主线 | J12: SRC-PDF | K12: 采用（草稿） | L12: 单操作框 | M12: 草稿 | N12: 骨架依据：SRC-PDF p1 步骤8框 | O12: SRC-RAW 08_* 步骤表＋SRC-PDF p1 步骤框 | P12: D-A2（用户2026-09-27确认）
A13: PR09 | B13: 乳清蛋白分级产品系统 | C13: M3 乳清蛋白浓缩 | D13: Cooling (15°C-4°C) | E13: WPI冷却 | F13: 9 | G13: 单元操作 | I13: 主线 | J13: SRC-PDF | K13: 采用（草稿） | L13: 单操作框 | M13: 草稿 | N13: 骨架依据：SRC-PDF p1 步骤9框 | O13: SRC-RAW 09_* 步骤表＋SRC-PDF p1 步骤框 | P13: D-A2（用户2026-09-27确认）
A14: PR10 | B14: 乳清蛋白分级产品系统 | C14: M3 乳清蛋白浓缩 | D14: Transport (4°C, 100 km) → Storage (4°C) | E14: WPI冷藏运输储存 | F14: 10 | G14: 单元操作 | I14: 主线 | J14: SRC-PDF | K14: 采用（草稿） | L14: 单操作框 | M14: 草稿 | N14: 骨架依据：SRC-PDF p1 步骤10框 | O14: SRC-RAW 10_* 步骤表＋SRC-PDF p1 步骤框 | P14: D-A2（用户2026-09-27确认）
A15: PR11 | B15: 乳清蛋白分级产品系统 | C15: M4 乳糖回收 | D15: Concentration of lactose (RO) FRV=4.7 | E15: 乳糖反渗透浓缩 | F15: 11 | G15: 单元操作 | I15: 支线（乳糖） | J15: SRC-PDF | K15: 采用（草稿） | L15: 单操作框 | M15: 草稿 | N15: 骨架依据：SRC-PDF p1 步骤11框 | O15: SRC-RAW 11_* 步骤表＋SRC-PDF p1 步骤框 | P15: D-A2（用户2026-09-27确认）
A16: PR12 | B16: 乳清蛋白分级产品系统 | C16: M4 乳糖回收 | D16: Lactose cooling (15°C-4°C) → Storage (4°C) | E16: 浓缩乳糖冷却储存 | F16: 12 | G16: 单元操作 | I16: 支线（乳糖） | J16: SRC-PDF | K16: 采用（草稿） | L16: 单操作框 | M16: 草稿 | N16: 骨架依据：SRC-PDF p1 步骤12框 | O16: SRC-RAW 12_* 步骤表＋SRC-PDF p1 步骤框 | P16: D-A2（用户2026-09-27确认）
A17: PR20 | B17: 乳清蛋白分级产品系统 | C17: M5 污水处理 | D17: 20_Wastewater treatment | E17: 清洗废水处理 | F17: 20 | G17: 单元操作 | I17: 支线（三废处理） | J17: SRC-RAW | K17: 采用（草稿） | L17: 单操作框 | M17: 草稿 | N17: 背景过程标注（原文：taken from databases），清单值给出；进水191.7 m³/d来自清洗段汇总 | O17: SRC-RAW 20_STEP 表 | P17: D-A2（用户2026-09-27确认）
A198: M1 | B198: 乳清蛋白分级产品系统 | C198: M1 | D198: M1 收奶与分离 | E198: M1 收奶与分离 | F198: 1 | G198: 计算过程 | J198: SRC-RAW | K198: 已审查 | O198: SRC-RAW 20步步骤表模块分段 | P198: D-A2＋WPI边界（用户2026-09-28确认）
A199: M2 | B199: 乳清蛋白分级产品系统 | C199: M2 | D199: M2 牛奶蛋白分级 | E199: M2 牛奶蛋白分级 | F199: 2 | G199: 计算过程 | J199: SRC-RAW | K199: 已审查 | O199: SRC-RAW 20步步骤表模块分段 | P199: D-A2＋WPI边界（用户2026-09-28确认）
A200: M3 | B200: 乳清蛋白分级产品系统 | C200: M3 | D200: M3 乳清蛋白浓缩 | E200: M3 乳清蛋白浓缩 | F200: 3 | G200: 计算过程 | J200: SRC-RAW | K200: 已审查 | O200: SRC-RAW 20步步骤表模块分段 | P200: D-A2＋WPI边界（用户2026-09-28确认）
A201: M4 | B201: 乳清蛋白分级产品系统 | C201: M4 | D201: M4 乳糖回收 | E201: M4 乳糖回收 | F201: 4 | G201: 计算过程 | J201: SRC-RAW | K201: 已审查 | O201: SRC-RAW 20步步骤表模块分段 | P201: D-A2＋WPI边界（用户2026-09-28确认）
A202: M5 | B202: 乳清蛋白分级产品系统 | C202: M5 | D202: M5 污水处理 | E202: M5 污水处理 | F202: 5 | G202: 计算过程 | J202: SRC-RAW | K202: 已审查 | O202: SRC-RAW 20步步骤表模块分段 | P202: D-A2＋WPI边界（用户2026-09-28确认）

Sheet 模型参数
A1: 模型参数
A2: 分布忠实来自原始数据；图示代表值与不确定性分布分开记录。
A4: 参数ID | B4: 过程ID | C4: 原始参数名 | D4: 中文名称 | E4: 物理意义 | F4: 单位 | G4: 分布类型 | H4: 最小值 | I4: 最大值 | J4: 中位数 | K4: 均值 | L4: 众数 | M4: 固定值 | N4: 图示代表值 | O4: 代表值规则 | P4: 来源ID | Q4: 使用公式/流ID | R4: 状态 | S4: 备注 | T4: 采用候选ID
A5: PA-EN-01A | B5: PR01 | C5: Ice water production and cooling of milk | D5: 分项电力实测 | E5: 电力消耗 | F5: kWh/d | G5: FIXED | M5: 1068 | N5: =IF(A138="","",IF(G138="FIXED",M138,IF(G138="UNIFORM",IF(AND(ISNUMBER(H138),ISNUMBER(I138)),(H138+I138)/2,""),IF(G138="TRIANGLE",IF(ISNUMBER(L138),L138,IF(ISNUMBER(J138),J138,"")),IF(ISNUMBER(J138),J138,IF(ISNUMBER(K138),K138,"")))))) | O5: =IF(A138="","",IF(G138="FIXED","fixed",IF(G138="UNIFORM","midpoint_median",IF(G138="TRIANGLE",IF(ISNUMBER(L138),"mode",IF(ISNUMBER(J138),"source_median","missing")),IF(ISNUMBER(J138),"source_median",IF(ISNUMBER(K138),"source_mean","missing")))))) | P5: SRC-RAW | Q5: FL-EL-01 | R5: 采用 | T5: CT-EN-01A
A6: PA-EN-01B | B6: PR01 | C6: Work of transfert pumps | D6: 分项电力实测 | E6: 电力消耗 | F6: kWh/d | G6: FIXED | M6: 70 | N6: =IF(A139="","",IF(G139="FIXED",M139,IF(G139="UNIFORM",IF(AND(ISNUMBER(H139),ISNUMBER(I139)),(H139+I139)/2,""),IF(G139="TRIANGLE",IF(ISNUMBER(L139),L139,IF(ISNUMBER(J139),J139,"")),IF(ISNUMBER(J139),J139,IF(ISNUMBER(K139),K139,"")))))) | O6: =IF(A139="","",IF(G139="FIXED","fixed",IF(G139="UNIFORM","midpoint_median",IF(G139="TRIANGLE",IF(ISNUMBER(L139),"mode",IF(ISNUMBER(J139),"source_median","missing")),IF(ISNUMBER(J139),"source_median",IF(ISNUMBER(K139),"source_mean","missing")))))) | P6: SRC-RAW | Q6: FL-EL-01 | R6: 采用 | T6: CT-EN-01B
A7: PA-EN-02A | B7: PR02 | C7: Work of transfert pumps | D7: 分项电力实测 | E7: 电力消耗 | F7: kWh/d | G7: FIXED | M7: 1035 | N7: =IF(A140="","",IF(G140="FIXED",M140,IF(G140="UNIFORM",IF(AND(ISNUMBER(H140),ISNUMBER(I140)),(H140+I140)/2,""),IF(G140="TRIANGLE",IF(ISNUMBER(L140),L140,IF(ISNUMBER(J140),J140,"")),IF(ISNUMBER(J140),J140,IF(ISNUMBER(K140),K140,"")))))) | O7: =IF(A140="","",IF(G140="FIXED","fixed",IF(G140="UNIFORM","midpoint_median",IF(G140="TRIANGLE",IF(ISNUMBER(L140),"mode",IF(ISNUMBER(J140),"source_median","missing")),IF(ISNUMBER(J140),"source_median",IF(ISNUMBER(K140),"source_mean","missing")))))) | P7: SRC-RAW | Q7: FL-EL-02 | R7: 采用 | T7: CT-EN-02A
A8: PA-EN-04A | B8: PR04 | C8: pumping + ice water production + coolin | D8: 分项电力实测 | E8: 电力消耗 | F8: kWh/d | G8: FIXED | M8: 1440 | N8: =IF(A141="","",IF(G141="FIXED",M141,IF(G141="UNIFORM",IF(AND(ISNUMBER(H141),ISNUMBER(I141)),(H141+I141)/2,""),IF(G141="TRIANGLE",IF(ISNUMBER(L141),L141,IF(ISNUMBER(J141),J141,"")),IF(ISNUMBER(J141),J141,IF(ISNUMBER(K141),K141,"")))))) | O8: =IF(A141="","",IF(G141="FIXED","fixed",IF(G141="UNIFORM","midpoint_median",IF(G141="TRIANGLE",IF(ISNUMBER(L141),"mode",IF(ISNUMBER(J141),"source_median","missing")),IF(ISNUMBER(J141),"source_median",IF(ISNUMBER(K141),"source_mean","missing")))))) | P8: SRC-RAW | Q8: FL-EL-04 | R8: 采用 | T8: CT-EN-04A
A9: PA-EN-05A | B9: PR05 | C9: Work of MF pumps | D9: 分项电力实测 | E9: 电力消耗 | F9: kWh/d | G9: FIXED | M9: 7996 | N9: =IF(A142="","",IF(G142="FIXED",M142,IF(G142="UNIFORM",IF(AND(ISNUMBER(H142),ISNUMBER(I142)),(H142+I142)/2,""),IF(G142="TRIANGLE",IF(ISNUMBER(L142),L142,IF(ISNUMBER(J142),J142,"")),IF(ISNUMBER(J142),J142,IF(ISNUMBER(K142),K142,"")))))) | O9: =IF(A142="","",IF(G142="FIXED","fixed",IF(G142="UNIFORM","midpoint_median",IF(G142="TRIANGLE",IF(ISNUMBER(L142),"mode",IF(ISNUMBER(J142),"source_median","missing")),IF(ISNUMBER(J142),"source_median",IF(ISNUMBER(K142),"source_mean","missing")))))) | P9: SRC-RAW | Q9: FL-EL-05 | R9: 采用 | T9: CT-EN-05A
A10: PA-EN-05B | B10: PR05 | C10: Work of transfert pumps | D10: 分项电力实测 | E10: 电力消耗 | F10: kWh/d | G10: FIXED | M10: 157 | N10: =IF(A143="","",IF(G143="FIXED",M143,IF(G143="UNIFORM",IF(AND(ISNUMBER(H143),ISNUMBER(I143)),(H143+I143)/2,""),IF(G143="TRIANGLE",IF(ISNUMBER(L143),L143,IF(ISNUMBER(J143),J143,"")),IF(ISNUMBER(J143),J143,IF(ISNUMBER(K143),K143,"")))))) | O10: =IF(A143="","",IF(G143="FIXED","fixed",IF(G143="UNIFORM","midpoint_median",IF(G143="TRIANGLE",IF(ISNUMBER(L143),"mode",IF(ISNUMBER(J143),"source_median","missing")),IF(ISNUMBER(J143),"source_median",IF(ISNUMBER(K143),"source_mean","missing")))))) | P10: SRC-RAW | Q10: FL-EL-05 | R10: 采用 | T10: CT-EN-05B
A11: PA-EN-06A | B11: PR06 | C11: Ice water production and cooling of rete | D11: 分项电力实测 | E11: 电力消耗 | F11: kWh/d | G11: FIXED | M11: 3685 | N11: =IF(A144="","",IF(G144="FIXED",M144,IF(G144="UNIFORM",IF(AND(ISNUMBER(H144),ISNUMBER(I144)),(H144+I144)/2,""),IF(G144="TRIANGLE",IF(ISNUMBER(L144),L144,IF(ISNUMBER(J144),J144,"")),IF(ISNUMBER(J144),J144,IF(ISNUMBER(K144),K144,"")))))) | O11: =IF(A144="","",IF(G144="FIXED","fixed",IF(G144="UNIFORM","midpoint_median",IF(G144="TRIANGLE",IF(ISNUMBER(L144),"mode",IF(ISNUMBER(J144),"source_median","missing")),IF(ISNUMBER(J144),"source_median",IF(ISNUMBER(K144),"source_mean","missing")))))) | P11: SRC-RAW | Q11: FL-EL-06 | R11: 采用 | T11: CT-EN-06A
A12: PA-EN-07A | B12: PR07 | C12: Work of transfert pumps | D12: 分项电力实测 | E12: 电力消耗 | F12: kWh/d | G12: FIXED | M12: 38 | N12: =IF(A145="","",IF(G145="FIXED",M145,IF(G145="UNIFORM",IF(AND(ISNUMBER(H145),ISNUMBER(I145)),(H145+I145)/2,""),IF(G145="TRIANGLE",IF(ISNUMBER(L145),L145,IF(ISNUMBER(J145),J145,"")),IF(ISNUMBER(J145),J145,IF(ISNUMBER(K145),K145,"")))))) | O12: =IF(A145="","",IF(G145="FIXED","fixed",IF(G145="UNIFORM","midpoint_median",IF(G145="TRIANGLE",IF(ISNUMBER(L145),"mode",IF(ISNUMBER(J145),"source_median","missing")),IF(ISNUMBER(J145),"source_median",IF(ISNUMBER(K145),"source_mean","missing")))))) | P12: SRC-RAW | Q12: FL-EL-07 | R12: 采用 | T12: CT-EN-07A
A13: PA-EN-07B | B13: PR07 | C13: Ice water production and cooling of crea | D13: 分项电力实测 | E13: 电力消耗 | F13: kWh/d | G13: FIXED | M13: 0 | N13: =IF(A146="","",IF(G146="FIXED",M146,IF(G146="UNIFORM",IF(AND(ISNUMBER(H146),ISNUMBER(I146)),(H146+I146)/2,""),IF(G146="TRIANGLE",IF(ISNUMBER(L146),L146,IF(ISNUMBER(J146),J146,"")),IF(ISNUMBER(J146),J146,IF(ISNUMBER(K146),K146,"")))))) | O13: =IF(A146="","",IF(G146="FIXED","fixed",IF(G146="UNIFORM","midpoint_median",IF(G146="TRIANGLE",IF(ISNUMBER(L146),"mode",IF(ISNUMBER(J146),"source_median","missing")),IF(ISNUMBER(J146),"source_median",IF(ISNUMBER(K146),"source_mean","missing")))))) | P13: SRC-RAW | Q13: FL-EL-07 | R13: 采用 | T13: CT-EN-07B
A14: PA-EN-08A | B14: PR08 | C14: Work of UF pumps | D14: 分项电力实测 | E14: 电力消耗 | F14: kWh/d | G14: FIXED | M14: 2200 | N14: =IF(A147="","",IF(G147="FIXED",M147,IF(G147="UNIFORM",IF(AND(ISNUMBER(H147),ISNUMBER(I147)),(H147+I147)/2,""),IF(G147="TRIANGLE",IF(ISNUMBER(L147),L147,IF(ISNUMBER(J147),J147,"")),IF(ISNUMBER(J147),J147,IF(ISNUMBER(K147),K147,"")))))) | O14: =IF(A147="","",IF(G147="FIXED","fixed",IF(G147="UNIFORM","midpoint_median",IF(G147="TRIANGLE",IF(ISNUMBER(L147),"mode",IF(ISNUMBER(J147),"source_median","missing")),IF(ISNUMBER(J147),"source_median",IF(ISNUMBER(K147),"source_mean","missing")))))) | P14: SRC-RAW | Q14: FL-EL-08 | R14: 采用 | T14: CT-EN-08A
A15: PA-EN-08B | B15: PR08 | C15: Ice water production and cooling of perm | D15: 分项电力实测 | E15: 电力消耗 | F15: kWh/d | G15: FIXED | M15: 13 | N15: =IF(A148="","",IF(G148="FIXED",M148,IF(G148="UNIFORM",IF(AND(ISNUMBER(H148),ISNUMBER(I148)),(H148+I148)/2,""),IF(G148="TRIANGLE",IF(ISNUMBER(L148),L148,IF(ISNUMBER(J148),J148,"")),IF(ISNUMBER(J148),J148,IF(ISNUMBER(K148),K148,"")))))) | O15: =IF(A148="","",IF(G148="FIXED","fixed",IF(G148="UNIFORM","midpoint_median",IF(G148="TRIANGLE",IF(ISNUMBER(L148),"mode",IF(ISNUMBER(J148),"source_median","missing")),IF(ISNUMBER(J148),"source_median",IF(ISNUMBER(K148),"source_mean","missing")))))) | P15: SRC-RAW | Q15: FL-EL-08 | R15: 采用 | T15: CT-EN-08B
A16: PA-EN-09A | B16: PR09 | C16: Ice water production and cooling of perm | D16: 分项电力实测 | E16: 电力消耗 | F16: kWh/d | G16: FIXED | M16: 129 | N16: =IF(A149="","",IF(G149="FIXED",M149,IF(G149="UNIFORM",IF(AND(ISNUMBER(H149),ISNUMBER(I149)),(H149+I149)/2,""),IF(G149="TRIANGLE",IF(ISNUMBER(L149),L149,IF(ISNUMBER(J149),J149,"")),IF(ISNUMBER(J149),J149,IF(ISNUMBER(K149),K149,"")))))) | O16: =IF(A149="","",IF(G149="FIXED","fixed",IF(G149="UNIFORM","midpoint_median",IF(G149="TRIANGLE",IF(ISNUMBER(L149),"mode",IF(ISNUMBER(J149),"source_median","missing")),IF(ISNUMBER(J149),"source_median",IF(ISNUMBER(K149),"source_mean","missing")))))) | P16: SRC-RAW | Q16: FL-EL-09 | R16: 采用 | T16: CT-EN-09A
... A24: PA-EN-20D | B24: PR20 | C24: extracting pump | D24: 分项电力实测 | E24: 电力消耗 | F24: kWh/d | G24: FIXED | M24: 0.7 | N24: =IF(A157="","",IF(G157="FIXED",M157,IF(G157="UNIFORM",IF(AND(ISNUMBER(H157),ISNUMBER(I157)),(H157+I157)/2,""),IF(G157="TRIANGLE",IF(ISNUMBER(L157),L157,IF(ISNUMBER(J157),J157,"")),IF(ISNUMBER(J157),J157,IF(ISNUMBER(K157),K157,"")))))) | O24: =IF(A157="","",IF(G157="FIXED","fixed",IF(G157="UNIFORM","midpoint_median",IF(G157="TRIANGLE",IF(ISNUMBER(L157),"mode",IF(ISNUMBER(J157),"source_median","missing")),IF(ISNUMBER(J157),"source_median",IF(ISNUMBER(K157),"source_mean","missing")))))) | P24: SRC-RAW | Q24: FL-EL-20 | R24: 采用 | T24: CT-EN-20D
N25: =IF(A158="","",IF(G158="FIXED",M158,IF(G158="UNIFORM",IF(AND(ISNUMBER(H158),ISNUMBER(I158)),(H158+I158)/2,""),IF(G158="TRIANGLE",IF(ISNUMBER(L158),L158,IF(ISNUMBER(J158),J158,"")),IF(ISNUMBER(J158),J158,IF(ISNUMBER(K158),K158,"")))))) | O25: =IF(A158="","",IF(G158="FIXED","fixed",IF(G158="UNIFORM","midpoint_median",IF(G158="TRIANGLE",IF(ISNUMBER(L158),"mode",IF(ISNUMBER(J158),"source_median","missing")),IF(ISNUMBER(J158),"source_median",IF(ISNUMBER(K158),"source_mean","missing"))))))
N26: =IF(A159="","",IF(G159="FIXED",M159,IF(G159="UNIFORM",IF(AND(ISNUMBER(H159),ISNUMBER(I159)),(H159+I159)/2,""),IF(G159="TRIANGLE",IF(ISNUMBER(L159),L159,IF(ISNUMBER(J159),J159,"")),IF(ISNUMBER(J159),J159,IF(ISNUMBER(K159),K159,"")))))) | O26: =IF(A159="","",IF(G159="FIXED","fixed",IF(G159="UNIFORM","midpoint_median",IF(G159="TRIANGLE",IF(ISNUMBER(L159),"mode",IF(ISNUMBER(J159),"source_median","missing")),IF(ISNUMBER(J159),"source_median",IF(ISNUMBER(K159),"source_mean","missing"))))))
N27: =IF(A160="","",IF(G160="FIXED",M160,IF(G160="UNIFORM",IF(AND(ISNUMBER(H160),ISNUMBER(I160)),(H160+I160)/2,""),IF(G160="TRIANGLE",IF(ISNUMBER(L160),L160,IF(ISNUMBER(J160),J160,"")),IF(ISNUMBER(J160),J160,IF(ISNUMBER(K160),K160,"")))))) | O27: =IF(A160="","",IF(G160="FIXED","fixed",IF(G160="UNIFORM","midpoint_median",IF(G160="TRIANGLE",IF(ISNUMBER(L160),"mode",IF(ISNUMBER(J160),"source_median","missing")),IF(ISNUMBER(J160),"source_median",IF(ISNUMBER(K160),"source_mean","missing"))))))
N28: =IF(A161="","",IF(G161="FIXED",M161,IF(G161="UNIFORM",IF(AND(ISNUMBER(H161),ISNUMBER(I161)),(H161+I161)/2,""),IF(G161="TRIANGLE",IF(ISNUMBER(L161),L161,IF(ISNUMBER(J161),J161,"")),IF(ISNUMBER(J161),J161,IF(ISNUMBER(K161),K161,"")))))) | O28: =IF(A161="","",IF(G161="FIXED","fixed",IF(G161="UNIFORM","midpoint_median",IF(G161="TRIANGLE",IF(ISNUMBER(L161),"mode",IF(ISNUMBER(J161),"source_median","missing")),IF(ISNUMBER(J161),"source_median",IF(ISNUMBER(K161),"source_mean","missing"))))))
N29: =IF(A162="","",IF(G162="FIXED",M162,IF(G162="UNIFORM",IF(AND(ISNUMBER(H162),ISNUMBER(I162)),(H162+I162)/2,""),IF(G162="TRIANGLE",IF(ISNUMBER(L162),L162,IF(ISNUMBER(J162),J162,"")),IF(ISNUMBER(J162),J162,IF(ISNUMBER(K162),K162,"")))))) | O29: =IF(A162="","",IF(G162="FIXED","fixed",IF(G162="UNIFORM","midpoint_median",IF(G162="TRIANGLE",IF(ISNUMBER(L162),"mode",IF(ISNUMBER(J162),"source_median","missing")),IF(ISNUMBER(J162),"source_median",IF(ISNUMBER(K162),"source_mean","missing"))))))
N30: =IF(A163="","",IF(G163="FIXED",M163,IF(G163="UNIFORM",IF(AND(ISNUMBER(H163),ISNUMBER(I163)),(H163+I163)/2,""),IF(G163="TRIANGLE",IF(ISNUMBER(L163),L163,IF(ISNUMBER(J163),J163,"")),IF(ISNUMBER(J163),J163,IF(ISNUMBER(K163),K163,"")))))) | O30: =IF(A163="","",IF(G163="FIXED","fixed",IF(G163="UNIFORM","midpoint_median",IF(G163="TRIANGLE",IF(ISNUMBER(L163),"mode",IF(ISNUMBER(J163),"source_median","missing")),IF(ISNUMBER(J163),"source_median",IF(ISNUMBER(K163),"source_mean","missing"))))))
N31: =IF(A164="","",IF(G164="FIXED",M164,IF(G164="UNIFORM",IF(AND(ISNUMBER(H164),ISNUMBER(I164)),(H164+I164)/2,""),IF(G164="TRIANGLE",IF(ISNUMBER(L164),L164,IF(ISNUMBER(J164),J164,"")),IF(ISNUMBER(J164),J164,IF(ISNUMBER(K164),K164,"")))))) | O31: =IF(A164="","",IF(G164="FIXED","fixed",IF(G164="UNIFORM","midpoint_median",IF(G164="TRIANGLE",IF(ISNUMBER(L164),"mode",IF(ISNUMBER(J164),"source_median","missing")),IF(ISNUMBER(J164),"source_median",IF(ISNUMBER(K164),"source_mean","missing"))))))
N32: =IF(A165="","",IF(G165="FIXED",M165,IF(G165="UNIFORM",IF(AND(ISNUMBER(H165),ISNUMBER(I165)),(H165+I165)/2,""),IF(G165="TRIANGLE",IF(ISNUMBER(L165),L165,IF(ISNUMBER(J165),J165,"")),IF(ISNUMBER(J165),J165,IF(ISNUMBER(K165),K165,"")))))) | O32: =IF(A165="","",IF(G165="FIXED","fixed",IF(G165="UNIFORM","midpoint_median",IF(G165="TRIANGLE",IF(ISNUMBER(L165),"mode",IF(ISNUMBER(J165),"source_median","missing")),IF(ISNUMBER(J165),"source_median",IF(ISNUMBER(K165),"source_mean","missing"))))))
N33: =IF(A166="","",IF(G166="FIXED",M166,IF(G166="UNIFORM",IF(AND(ISNUMBER(H166),ISNUMBER(I166)),(H166+I166)/2,""),IF(G166="TRIANGLE",IF(ISNUMBER(L166),L166,IF(ISNUMBER(J166),J166,"")),IF(ISNUMBER(J166),J166,IF(ISNUMBER(K166),K166,"")))))) | O33: =IF(A166="","",IF(G166="FIXED","fixed",IF(G166="UNIFORM","midpoint_median",IF(G166="TRIANGLE",IF(ISNUMBER(L166),"mode",IF(ISNUMBER(J166),"source_median","missing")),IF(ISNUMBER(J166),"source_median",IF(ISNUMBER(K166),"source_mean","missing"))))))
N34: =IF(A167="","",IF(G167="FIXED",M167,IF(G167="UNIFORM",IF(AND(ISNUMBER(H167),ISNUMBER(I167)),(H167+I167)/2,""),IF(G167="TRIANGLE",IF(ISNUMBER(L167),L167,IF(ISNUMBER(J167),J167,"")),IF(ISNUMBER(J167),J167,IF(ISNUMBER(K167),K167,"")))))) | O34: =IF(A167="","",IF(G167="FIXED","fixed",IF(G167="UNIFORM","midpoint_median",IF(G167="TRIANGLE",IF(ISNUMBER(L167),"mode",IF(ISNUMBER(J167),"source_median","missing")),IF(ISNUMBER(J167),"source_median",IF(ISNUMBER(K167),"source_mean","missing"))))))
N35: =IF(A168="","",IF(G168="FIXED",M168,IF(G168="UNIFORM",IF(AND(ISNUMBER(H168),ISNUMBER(I168)),(H168+I168)/2,""),IF(G168="TRIANGLE",IF(ISNUMBER(L168),L168,IF(ISNUMBER(J168),J168,"")),IF(ISNUMBER(J168),J168,IF(ISNUMBER(K168),K168,"")))))) | O35: =IF(A168="","",IF(G168="FIXED","fixed",IF(G168="UNIFORM","midpoint_median",IF(G168="TRIANGLE",IF(ISNUMBER(L168),"mode",IF(ISNUMBER(J168),"source_median","missing")),IF(ISNUMBER(J168),"source_median",IF(ISNUMBER(K168),"source_mean","missing"))))))
N36: =IF(A169="","",IF(G169="FIXED",M169,IF(G169="UNIFORM",IF(AND(ISNUMBER(H169),ISNUMBER(I169)),(H169+I169)/2,""),IF(G169="TRIANGLE",IF(ISNUMBER(L169),L169,IF(ISNUMBER(J169),J169,"")),IF(ISNUMBER(J169),J169,IF(ISNUMBER(K169),K169,"")))))) | O36: =IF(A169="","",IF(G169="FIXED","fixed",IF(G169="UNIFORM","midpoint_median",IF(G169="TRIANGLE",IF(ISNUMBER(L169),"mode",IF(ISNUMBER(J169),"source_median","missing")),IF(ISNUMBER(J169),"source_median",IF(ISNUMBER(K169),"source_mean","missing"))))))
... N71: =IF(A204="","",IF(G204="FIXED",M204,IF(G204="UNIFORM",IF(AND(ISNUMBER(H204),ISNUMBER(I204)),(H204+I204)/2,""),IF(G204="TRIANGLE",IF(ISNUMBER(L204),L204,IF(ISNUMBER(J204),J204,"")),IF(ISNUMBER(J204),J204,IF(ISNUMBER(K204),K204,"")))))) | O71: =IF(A204="","",IF(G204="FIXED","fixed",IF(G204="UNIFORM","midpoint_median",IF(G204="TRIANGLE",IF(ISNUMBER(L204),"mode",IF(ISNUMBER(J204),"source_median","missing")),IF(ISNUMBER(J204),"source_median",IF(ISNUMBER(K204),"source_mean","missing"))))))

Sheet 模型流与公式
A1: 模型流与公式
A2: 一行一个模型流；物理流、环境交换、分配负担和替代候选必须区分。
A4: 流ID | B4: 过程ID | C4: 流名称 | D4: 流类别 | E4: 方向 | F4: 来源过程ID | G4: 目标过程ID | H4: 值类型 | I4: 原始登记值 | J4: 原始单位 | K4: 参考基准 | L4: 公式ID | M4: 来源公式 | N4: 采用公式 | O4: 输入参数ID | P4: 图示代表值 | Q4: 采用单位 | R4: 符号约定 | S4: 是否内部流 | T4: 方法采用状态 | U4: 来源ID | V4: 审查状态 | W4: 是否显示 | X4: 显示标签 | Y4: 备注 | Z4: 采用候选ID | AA4: 数值生成方式 | AB4: 原始计量基准 | AC4: 采用计量基准
A5: FL-RM | B5: PR01 | C5: 原料奶（收奶） | D5: 物理流 | E5: 输入 | G5: PR01 | H5: physical_material | I5: 583 | J5: m3/d | K5: 1天 | P5: 583 | Q5: m3/d | R5: + | S5: 否 | T5: 来源ALCA原始物理流（未分配） | U5: SRC-PDF | V5: 已审查 | W5: 是 | X5: 原料奶 600,490 kg/j | Y5: 原料奶；SRC-RAW原始体积基准 583 m³/d（衍生版质量值仅参考不作基准） | Z5: CT-VOL-RM | AA5: 直接报告 | AB5: 体积 m3/d（SRC-RAW） | AC5: 1天生产
A6: FL-SKIM | B6: PR02 | C6: 脱脂奶 | D6: 物理流 | E6: 输出 | F6: PR02 | G6: PR04 | H6: physical_material | I6: 525 | J6: m3/d | K6: 1天 | P6: 525 | Q6: m3/d | R6: + | S6: 是 | T6: 来源ALCA原始物理流（未分配） | U6: SRC-PDF | V6: 已审查 | W6: 是 | X6: 脱脂奶 537,075 | Y6: 脱脂奶；SRC-RAW原始体积基准 525 m³/d（衍生版质量值仅参考不作基准） | Z6: CT-VOL-SKIM | AA6: 直接报告 | AB6: 体积 m3/d（SRC-RAW） | AC6: 1天生产
A7: FL-CREAM | B7: PR02 | C7: 稀奶油 | D7: 物理流 | E7: 输出 | F7: PR02 | G7: PR03 | H7: physical_material | I7: 58 | J7: m3/d | K7: 1天 | P7: 58 | Q7: m3/d | R7: + | S7: 是 | T7: 来源ALCA原始物理流（未分配） | U7: SRC-PDF | V7: 已审查 | W7: 是 | X7: 稀奶油 56,883 | Y7: 稀奶油；SRC-RAW原始体积基准 58 m³/d（衍生版质量值仅参考不作基准） | Z7: CT-VOL-CREAM | AA7: 直接报告 | AB7: 体积 m3/d（SRC-RAW） | AC7: 1天生产
A8: FL-CAS | B8: PR05 | C8: 胶束酪蛋白 | D8: 物理流 | E8: 输出 | F8: PR05 | G8: PR06 | H8: physical_material | I8: 175 | J8: m3/d | K8: 1天 | P8: 175 | Q8: m3/d | R8: + | S8: 是 | T8: 来源ALCA原始物理流（未分配） | U8: SRC-PDF | V8: 已审查 | W8: 是 | X8: 胶束酪蛋白 182,875 | Y8: 胶束酪蛋白；SRC-RAW原始体积基准 175 m³/d（衍生版质量值仅参考不作基准） | Z8: CT-VOL-CAS | AA8: 直接报告 | AB8: 体积 m3/d（SRC-RAW） | AC8: 1天生产
A9: FL-WHEY | B9: PR05 | C9: 乳清（MF1渗透液） | D9: 物理流 | E9: 输出 | F9: PR05 | G9: PR07 | H9: physical_material | I9: 350 | J9: m3/d | K9: 1天 | P9: 350 | Q9: m3/d | R9: + | S9: 是 | T9: 来源ALCA原始物理流（未分配） | U9: SRC-PDF | V9: 已审查 | W9: 是 | X9: 乳清 354,900 | Y9: 乳清；SRC-RAW原始体积基准 350 m³/d（衍生版质量值仅参考不作基准） | Z9: CT-VOL-WHEY | AA9: 直接报告 | AB9: 体积 m3/d（SRC-RAW） | AC9: 1天生产
A10: FL-W08 | B10: PR08 | C10: UF10透析加水 | D10: 物理流 | E10: 输入 | G10: PR08 | H10: physical_material | I10: 63 | J10: m3/d | K10: 1天 | P10: 63 | Q10: m3/d | R10: + | S10: 否 | T10: 来源ALCA原始物理流（未分配） | U10: SRC-PDF | V10: 已审查 | W10: 是 | X10: 加水 63,000 | Y10: UF10透析加水；SRC-RAW原始体积 63 m³/d（衍生版质量值仅参考） | Z10: CT-VOL-W08 | AA10: 直接报告 | AB10: 体积 m3/d（SRC-RAW） | AC10: 1天生产
A11: FL-WPI | B11: PR08 | C11: WPI浓缩液 | D11: 物理流 | E11: 输出 | F11: PR08 | G11: PR09 | H11: physical_material | I11: 11.7 | J11: m3/d | K11: 1天 | P11: 11.7 | Q11: m3/d | R11: + | S11: 是 | T11: 来源ALCA原始物理流（未分配） | U11: SRC-PDF | V11: 已审查 | W11: 是 | X11: WPI 12,004.2 | Y11: WPI浓缩液；SRC-RAW原始体积基准 11.7 m³/d（衍生版质量值仅参考不作基准） | Z11: CT-VOL-WPI | AA11: 直接报告 | AB11: 体积 m3/d（SRC-RAW） | AC11: 1天生产
A12: FL-LACP | B12: PR08 | C12: 乳糖渗透液 | D12: 物理流 | E12: 输出 | F12: PR08 | G12: PR11 | H12: physical_material | I12: 401.3 | J12: m3/d | K12: 1天 | P12: 401.3 | Q12: m3/d | R12: + | S12: 是 | T12: 来源ALCA原始物理流（未分配） | U12: SRC-PDF | V12: 已审查 | W12: 是 | X12: 乳糖渗透液 406,115.6 | Y12: 乳糖渗透液；SRC-RAW原始体积基准 401.3 m³/d（衍生版质量值仅参考不作基准） | Z12: CT-VOL-LACP | AA12: 直接报告 | AB12: 体积 m3/d（SRC-RAW） | AC12: 1天生产
A13: FL-OSM | B13: PR11 | C13: 渗透水（osmosate） | D13: 物理流 | E13: 输出 | F13: PR11 | H13: physical_material | I13: 316 | J13: m3/d | K13: 1天 | P13: 316 | Q13: m3/d | R13: + | S13: 否 | T13: 来源ALCA原始物理流（未分配） | U13: SRC-PDF | V13: 已审查 | W13: 是 | X13: 渗透水 316,000 | Y13: 渗透水；SRC-RAW原始体积基准 316 m³/d（衍生版质量值仅参考不作基准） | Z13: CT-VOL-OSM | AA13: 直接报告 | AB13: 体积 m3/d（SRC-RAW） | AC13: 1天生产
A14: FL-LAC | B14: PR11 | C14: 浓缩乳糖 | D14: 物理流 | E14: 输出 | F14: PR11 | G14: PR12 | H14: physical_material | I14: 85.3 | J14: m3/d | K14: 1天 | P14: 85.3 | Q14: m3/d | R14: + | S14: 是 | T14: 来源ALCA原始物理流（未分配） | U14: SRC-PDF | V14: 已审查 | W14: 是 | X14: 浓缩乳糖 90,115.6 | Y14: 浓缩乳糖；SRC-RAW原始体积基准 85.3 m³/d（衍生版质量值仅参考不作基准） | Z14: CT-VOL-LAC | AA14: 直接报告 | AB14: 体积 m3/d（SRC-RAW） | AC14: 1天生产
A15: FL-EL-01 | B15: PR01 | C15: 电力（生产） | D15: 能源 | E15: 输入 | G15: PR01 | H15: physical_energy | J15: kWh/d | K15: 1天 | N15: ＝SUM(分项电力参数) | O15: PA-EN-01A;PA-EN-01B | P15: 1138 | Q15: kWh/d | R15: + | S15: 否 | T15: 来源原始清单（未分配） | U15: SRC-RAW | V15: 已审查 | W15: 是 | X15: PR01 生产电力 1138.0 | Y15: 分项实测加总；TOTALs未给出 | AA15: 公式派生 | AB15: 1天生产 | AC15: 1天生产
A16: FL-EL-02 | B16: PR02 | C16: 电力（生产） | D16: 能源 | E16: 输入 | G16: PR02 | H16: physical_energy | J16: kWh/d | K16: 1天 | N16: ＝SUM(分项电力参数) | O16: PA-EN-02A | P16: 1035 | Q16: kWh/d | R16: + | S16: 否 | T16: 来源原始清单（未分配） | U16: SRC-RAW | V16: 已审查 | W16: 是 | X16: PR02 生产电力 1035.0 | Y16: 分项实测加总；TOTALs未给出 | AA16: 公式派生 | AB16: 1天生产 | AC16: 1天生产
A17: FL-EL-03 | B17: PR03 | C17: 电力（生产） | D17: 能源 | E17: 输入 | G17: PR03 | H17: physical_energy | I17: 1216.4 | J17: kWh/d | K17: 1天 | P17: 1216.4 | Q17: kWh/d | R17: + | S17: 否 | T17: 来源原始清单（未分配） | U17: SRC-RAW | V17: 已审查 | W17: 是 | X17: PR03 生产电力 1216.4 | Y17: 步骤电力合计（TOTALs） | Z17: CT-ELT-03 | AA17: 直接报告 | AB17: 1天生产 | AC17: 1天生产
A18: FL-EL-04 | B18: PR04 | C18: 电力（生产） | D18: 能源 | E18: 输入 | G18: PR04 | H18: physical_energy | J18: kWh/d | K18: 1天 | N18: ＝SUM(分项电力参数) | O18: PA-EN-04A | P18: 1440 | Q18: kWh/d | R18: + | S18: 否 | T18: 来源原始清单（未分配） | U18: SRC-RAW | V18: 已审查 | W18: 是 | X18: PR04 生产电力 1440.0 | Y18: 分项实测加总；TOTALs未给出 | AA18: 公式派生 | AB18: 1天生产 | AC18: 1天生产
A19: FL-EL-05 | B19: PR05 | C19: 电力（生产） | D19: 能源 | E19: 输入 | G19: PR05 | H19: physical_energy | J19: kWh/d | K19: 1天 | N19: ＝SUM(分项电力参数) | O19: PA-EN-05A;PA-EN-05B | P19: 8153 | Q19: kWh/d | R19: + | S19: 否 | T19: 来源原始清单（未分配） | U19: SRC-RAW | V19: 已审查 | W19: 是 | X19: PR05 生产电力 8153.0 | Y19: 分项实测加总；TOTALs未给出 | AA19: 公式派生 | AB19: 1天生产 | AC19: 1天生产
A20: FL-EL-06 | B20: PR06 | C20: 电力（生产） | D20: 能源 | E20: 输入 | G20: PR06 | H20: physical_energy | J20: kWh/d | K20: 1天 | N20: ＝SUM(分项电力参数) | O20: PA-EN-06A | P20: 3685 | Q20: kWh/d | R20: + | S20: 否 | T20: 来源原始清单（未分配） | U20: SRC-RAW | V20: 已审查 | W20: 是 | X20: PR06 生产电力 3685.0 | Y20: 分项实测加总；TOTALs未给出 | AA20: 公式派生 | AB20: 1天生产 | AC20: 1天生产
A21: FL-EL-07 | B21: PR07 | C21: 电力（生产） | D21: 能源 | E21: 输入 | G21: PR07 | H21: physical_energy | J21: kWh/d | K21: 1天 | N21: ＝SUM(分项电力参数) | O21: PA-EN-07A;PA-EN-07B | P21: 38 | Q21: kWh/d | R21: + | S21: 否 | T21: 来源原始清单（未分配） | U21: SRC-RAW | V21: 已审查 | W21: 是 | X21: PR07 生产电力 38.0 | Y21: 分项实测加总；TOTALs未给出 | AA21: 公式派生 | AB21: 1天生产 | AC21: 1天生产
A22: FL-EL-08 | B22: PR08 | C22: 电力（生产） | D22: 能源 | E22: 输入 | G22: PR08 | H22: physical_energy | J22: kWh/d | K22: 1天 | N22: ＝SUM(分项电力参数) | O22: PA-EN-08A;PA-EN-08B | P22: 2213 | Q22: kWh/d | R22: + | S22: 否 | T22: 来源原始清单（未分配） | U22: SRC-RAW | V22: 已审查 | W22: 是 | X22: PR08 生产电力 2213.0 | Y22: 分项实测加总；TOTALs未给出 | AA22: 公式派生 | AB22: 1天生产 | AC22: 1天生产
A23: FL-EL-09 | B23: PR09 | C23: 电力（生产） | D23: 能源 | E23: 输入 | G23: PR09 | H23: physical_energy | J23: kWh/d | K23: 1天 | N23: ＝SUM(分项电力参数) | O23: PA-EN-09A | P23: 129 | Q23: kWh/d | R23: + | S23: 否 | T23: 来源原始清单（未分配） | U23: SRC-RAW | V23: 已审查 | W23: 是 | X23: PR09 生产电力 129.0 | Y23: 分项实测加总；TOTALs未给出 | AA23: 公式派生 | AB23: 1天生产 | AC23: 1天生产
A24: FL-EL-10 | B24: PR10 | C24: 电力（生产） | D24: 能源 | E24: 输入 | G24: PR10 | H24: physical_energy | J24: kWh/d | K24: 1天 | N24: ＝SUM(分项电力参数) | O24: PA-EN-10A;PA-EN-10B | P24: 1.2 | Q24: kWh/d | R24: + | S24: 否 | T24: 来源原始清单（未分配） | U24: SRC-RAW | V24: 已审查 | W24: 是 | X24: PR10 生产电力 1.2 | Y24: 分项实测加总；TOTALs未给出 | AA24: 公式派生 | AB24: 1天生产 | AC24: 1天生产
A25: FL-EL-11 | B25: PR11 | C25: 电力（生产） | D25: 能源 | E25: 输入 | G25: PR11 | H25: physical_energy | J25: kWh/d | K25: 1天 | N25: ＝SUM(分项电力参数) | O25: PA-EN-11A | P25: 1535 | Q25: kWh/d | R25: + | S25: 否 | T25: 来源原始清单（未分配） | U25: SRC-RAW | V25: 已审查 | W25: 是 | X25: PR11 生产电力 1535.0 | Y25: 分项实测加总；TOTALs未给出 | AA25: 公式派生 | AB25: 1天生产 | AC25: 1天生产
A26: FL-EL-12 | B26: PR12 | C26: 电力（生产） | D26: 能源 | E26: 输入 | G26: PR12 | H26: physical_energy | J26: kWh/d | K26: 1天 | N26: ＝SUM(分项电力参数) | O26: PA-EN-12A | P26: 172 | Q26: kWh/d | R26: + | S26: 否 | T26: 来源原始清单（未分配） | U26: SRC-RAW | V26: 已审查 | W26: 是 | X26: PR12 生产电力 172.0 | Y26: 分项实测加总；TOTALs未给出 | AA26: 公式派生 | AB26: 1天生产 | AC26: 1天生产
A27: FL-EL-20 | B27: PR20 | C27: 电力（生产） | D27: 能源 | E27: 输入 | G27: PR20 | H27: physical_energy | J27: kWh/d | K27: 1天 | N27: ＝SUM(分项电力参数) | O27: PA-EN-20A;PA-EN-20B;PA-EN-20C;PA-EN-20D | P27: 5050.7 | Q27: kWh/d | R27: + | S27: 否 | T27: 来源原始清单（未分配） | U27: SRC-RAW | V27: 已审查 | W27: 是 | X27: PR20 生产电力 5050.7 | Y27: 分项实测加总；TOTALs未给出 | AA27: 公式派生 | AB27: 1天生产 | AC27: 1天生产
A28: FL-GAS-04 | B28: PR04 | C28: 燃气热（生产） | D28: 能源 | E28: 输入 | G28: PR04 | H28: physical_energy | I28: 19465 | J28: MJ/d | K28: 1天 | P28: 19465 | Q28: MJ/d | R28: + | S28: 否 | T28: 来源原始清单（未分配） | U28: SRC-RAW | V28: 已审查 | W28: 是 | X28: PR04 燃气热（生产） 19465 | Y28: 燃气锅炉 | Z28: CT-GAST-04 | AA28: 直接报告 | AB28: 1天生产 | AC28: 1天生产
A29: FL-GAS-05 | B29: PR05 | C29: 燃气热（生产） | D29: 能源 | E29: 输入 | G29: PR05 | H29: physical_energy | I29: 54075 | J29: MJ/d | K29: 1天 | P29: 54075 | Q29: MJ/d | R29: + | S29: 否 | T29: 来源原始清单（未分配） | U29: SRC-RAW | V29: 已审查 | W29: 是 | X29: PR05 燃气热（生产） 54075 | Y29: 燃气锅炉 | Z29: CT-GAST-05 | AA29: 直接报告 | AB29: 1天生产 | AC29: 1天生产
A30: FL-TKM-10 | B30: PR10 | C30: 运输（t·km） | D30: 能源 | E30: 输入 | G30: PR10 | H30: physical_energy | I30: 1370 | J30: t.km | K30: 1天 | P30: 1370 | Q30: t.km | R30: + | S30: 否 | T30: 来源原始清单（未分配） | U30: SRC-RAW | V30: 已审查 | W30: 是 | X30: WPI冷藏运输 1370 | Y30: insulated truck，4°C 100km（原文Mass·distance实测） | Z30: CT-TKM-10 | AA30: 直接报告 | AB30: 1天生产 | AC30: 1天生产
A31: FL-SLURRY-20 | B31: PR20 | C31: 运输（t·km） | D31: 能源 | E31: 输入 | G31: PR20 | H31: physical_energy | I31: 45.6 | J31: t.km | K31: 1天 | P31: 45.6 | Q31: t.km | R31: + | S31: 否 | T31: 来源原始清单（未分配） | U31: SRC-RAW | V31: 已审查 | W31: 是 | X31: 污泥运输 45.6 | Y31: slurry spreading | Z31: CT-SLURRY-20 | AA31: 直接报告 | AB31: 1天生产 | AC31: 1天生产
A32: FL-O-CREAM | B32: PR03 | C32: 奶油出厂（联产品） | D32: 物理流 | E32: 输出 | F32: PR03 | H32: physical_material | I32: 58 | J32: m3/d | K32: 1天 | P32: 58 | Q32: m3/d | R32: + | S32: 否 | T32: 来源原始清单（未分配） | U32: SRC-RAW | V32: 已审查 | W32: 是 | X32: 奶油出厂（联产品） 58 | Y32: 3_CS输出段Cream 58 m³/d（Losses are neglected） | Z32: CT-O-CREAM | AA32: 直接报告 | AB32: 体积 m3/d（SRC-RAW） | AC32: 1天生产
A33: FL-O-CAS | B33: PR06 | C33: 胶束酪蛋白出厂（联产品） | D33: 物理流 | E33: 输出 | F33: PR06 | H33: physical_material | I33: 175 | J33: m3/d | K33: 1天 | P33: 175 | Q33: m3/d | R33: + | S33: 否 | T33: 来源原始清单（未分配） | U33: SRC-RAW | V33: 已审查 | W33: 是 | X33: 胶束酪蛋白出厂（联产品） 175 | Y33: 6_CS输出段Casein micelle retentate 175 m³/d（Losses are neglected） | Z33: CT-O-CAS | AA33: 直接报告 | AB33: 体积 m3/d（SRC-RAW） | AC33: 1天生产
A34: FL-O-LAC | B34: PR12 | C34: 浓缩乳糖出厂（联产品） | D34: 物理流 | E34: 输出 | F34: PR12 | H34: physical_material | I34: 85.3 | J34: m3/d | K34: 1天 | P34: 85.3 | Q34: m3/d | R34: + | S34: 否 | T34: 来源原始清单（未分配） | U34: SRC-RAW | V34: 已审查 | W34: 是 | X34: 浓缩乳糖出厂（联产品） 85.3 | Y34: 12_CS输出段Cooled lactose concentrate 85.3 m³/d（Losses are neglected） | Z34: CT-O-LAC | AA34: 直接报告 | AB34: 体积 m3/d（SRC-RAW） | AC34: 1天生产
A35: FL-O-WPI | B35: PR10 | C35: WPI浓缩液出厂（主产品） | D35: 物理流 | E35: 输出 | F35: PR10 | H35: physical_material | I35: 11.7 | J35: m3/d | K35: 1天 | P35: 11.7 | Q35: m3/d | R35: + | S35: 否 | T35: 来源原始清单（未分配） | U35: SRC-RAW | V35: 已审查 | W35: 是 | X35: WPI浓缩液出厂（主产品） 11.7 | Y35: 系统边界=WPI浓缩液出厂；11.7 m³/d 与 8_UF1→9_DI 主流 FL-WPI 一致（无损失报告） | Z35: CT-O-WPI | AA35: 直接报告 | AB35: 体积 m3/d（SRC-RAW） | AC35: 1天生产
A36: FL-NH3-03 | B36: PR03 | C36: PR03 制冷剂NH3 | D36: 物理流 | E36: 输入 | G36: PR03 | H36: physical_material | I36: 0.0084 | J36: m3/d | K36: 1天 | P36: 0.0084 | Q36: m3/d | R36: + | S36: 否 | T36: 来源原始清单（未分配） | U36: SRC-RAW | V36: 已审查 | W36: 否 | X36: PR03 制冷剂NH3 0.0084 | Y36: 单位按原文；NH3 1_RCS为m3/d | Z36: CT-NH3-03 | AA36: 直接报告 | AB36: 1天生产 | AC36: 1天生产
A37: FL-NH3-05 | B37: PR05 | C37: PR05 制冷剂NH3 | D37: 物理流 | E37: 输入 | G37: PR05 | H37: physical_material | I37: 0.0127 | J37: kg/d | K37: 1天 | P37: 0.0127 | Q37: kg/d | R37: + | S37: 否 | T37: 来源原始清单（未分配） | U37: SRC-RAW | V37: 已审查 | W37: 否 | X37: PR05 制冷剂NH3 0.0127 | Y37: 单位按原文；NH3 1_RCS为m3/d | Z37: CT-NH3-05 | AA37: 直接报告 | AB37: 1天生产 | AC37: 1天生产
A38: FL-NH3-06 | B38: PR06 | C38: PR06 制冷剂NH3 | D38: 物理流 | E38: 输入 | G38: PR06 | H38: physical_material | I38: 0.0257 | J38: kg/d | K38: 1天 | P38: 0.0257 | Q38: kg/d | R38: + | S38: 否 | T38: 来源原始清单（未分配） | U38: SRC-RAW | V38: 已审查 | W38: 否 | X38: PR06 制冷剂NH3 0.0257 | Y38: 单位按原文；NH3 1_RCS为m3/d | Z38: CT-NH3-06 | AA38: 直接报告 | AB38: 1天生产 | AC38: 1天生产
A39: FL-NH3-08 | B39: PR08 | C39: PR08 制冷剂NH3 | D39: 物理流 | E39: 输入 | G39: PR08 | H39: physical_material | I39: 0.0001 | J39: m3/d | K39: 1天 | P39: 0.0001 | Q39: m3/d | R39: + | S39: 否 | T39: 来源原始清单（未分配） | U39: SRC-RAW | V39: 已审查 | W39: 否 | X39: PR08 制冷剂NH3 0.0001 | Y39: 单位按原文；NH3 1_RCS为m3/d | Z39: CT-NH3-08 | AA39: 直接报告 | AB39: 1天生产 | AC39: 1天生产
A40: FL-NH3-09 | B40: PR09 | C40: PR09 制冷剂NH3 | D40: 物理流 | E40: 输入 | G40: PR09 | H40: physical_material | I40: 0.00116 | J40: m3/d | K40: 1天 | P40: 0.00116 | Q40: m3/d | R40: + | S40: 否 | T40: 来源原始清单（未分配） | U40: SRC-RAW | V40: 已审查 | W40: 否 | X40: PR09 制冷剂NH3 0.00116 | Y40: 单位按原文；NH3 1_RCS为m3/d | Z40: CT-NH3-09 | AA40: 直接报告 | AB40: 1天生产 | AC40: 1天生产
A41: FL-NH3-12 | B41: PR12 | C41: PR12 制冷剂NH3 | D41: 物理流 | E41: 输入 | G41: PR12 | H41: physical_material | I41: 0.0032 | J41: m3/d | K41: 1天 | P41: 0.0032 | Q41: m3/d | R41: + | S41: 否 | T41: 来源原始清单（未分配） | U41: SRC-RAW | V41: 已审查 | W41: 否 | X41: PR12 制冷剂NH3 0.0032 | Y41: 单位按原文；NH3 1_RCS为m3/d | Z41: CT-NH3-12 | AA41: 直接报告 | AB41: 1天生产 | AC41: 1天生产
...

Sheet 核算检查
A1: 核算检查
A2: 检查表只记录诊断，不作为模型输入。BLOCKED 未解决前不得冻结。
A4: 检查ID | B4: 检查类型 | C4: 对象类型 | D4: 对象ID | E4: 检查方法/公式 | F4: 期望值 | G4: 实际值 | H4: 单位 | I4: 容差 | J4: 差值 | K4: 结果 | L4: 问题ID | M4: 说明 | N4: 审查路线 | O4: 实际验证结论 | P4: 影响对象ID
A5: CH-01 | B5: 质量平衡 | C5: 过程 | D5: PR02 | E5: 出-入：537075+56883-600490 | F5: -6532 | G5: -6532 | H5: kg/j | I5: 0（登记偏差） | J5: =IF(OR(F5="",G5=""),"",G5-F5) | K5: PASS | L5: Q-01 | M5: 原始版体积平衡闭合：583=525+58；v1质量差-6,532 kg/j为衍生版密度换算口径差 | N5: 按框值逐项复算 | O5: SRC-RAW体积基准复核闭合（2026-09-27） | P5: FL-RM;FL-SKIM;FL-CREAM
A6: CH-02 | B6: 质量平衡 | C6: 过程 | D6: PR05 | E6: 出-入：354900+182875-537075 | F6: 0 | G6: 700 | H6: kg/j | I6: 0（登记偏差） | J6: =IF(OR(F6="",G6=""),"",G6-F6) | K6: PASS | L6: Q-03 | M6: 原始版体积闭合：175+350=525；v1质量差+700 kg/j为衍生版口径差 | N6: 按框值逐项复算 | O6: SRC-RAW体积基准复核闭合 | P6: FL-SKIM;FL-WHEY;FL-CAS
A7: CH-03 | B7: 质量平衡 | C7: 过程 | D7: PR08 | E7: 出-入：12004.2+406115.6-(354900+63000) | F7: 0 | G7: 219.8 | H7: kg/j | I7: ±1000 | J7: =IF(OR(F7="",G7=""),"",G7-F7) | K7: PASS | M7: 出入差0.05%，容差内 | N7: 按框值逐项复算 | O7: 偏差+219.8 kg/j在容差内 | P7: FL-WHEY;FL-W08;FL-WPI;FL-LACP
A8: CH-04 | B8: 质量平衡 | C8: 过程 | D8: PR11 | E8: 出-入：316000+90115.6-406115.6 | F8: 0 | G8: 0 | H8: kg/j | I8: ±1000 | J8: =IF(OR(F8="",G8=""),"",G8-F8) | K8: PASS | M8: RO质量平衡闭合 | N8: 按框值逐项复算 | O8: 闭合 | P8: FL-LACP;FL-OSM;FL-LAC
A9: CH-07 | B9: 干物质平衡 | C9: 过程 | D9: PR11 | E9: 出-入：90115.6×0.24-406115.6×0.044 | F9: 0 | G9: 3758.65 | H9: kg DM/j | I9: 0（登记偏差） | J9: =IF(OR(F11="",G11=""),"",G11-F11) | K9: 偏差登记 | L9: Q-09 | M9: RO进料DM 17,869.09 kg/j，出料DM 21,627.74 kg/j；DM不守恒，源数据内部矛盾 | N9: 按框值逐项复算 | O9: 偏差+3,758.65 kg DM/j已复算确认 | P9: FL-LACP;FL-LAC
A10: CH-08 | B10: 蛋白平衡 | C10: 过程 | D10: PR08 | E10: 蛋白出-入：12004.2×0.114-354900×0.0059 | F10: 0 | G10: -725.42 | H10: kg蛋白/j | I10: 0（登记偏差） | J10: =IF(OR(F12="",G12=""),"",G12-F12) | K10: 偏差登记 | L10: Q-06 | M10: 进乳清蛋白2,093.9 kg/j，WPI带出1,368.5 kg/j；34.6%蛋白去向未报告（渗透液蛋白标0） | N10: 按框值逐项复算 | O10: 偏差-725.42 kg/j已复算确认 | P10: FL-WHEY;FL-WPI
A11: CH-10 | B11: 收入复算 | C11: 参数 | D11: PA-PRICE-LAC | E11: 90115.6×1.5 vs 报告revenue 128 | F11: 135173.4 | G11: 128 | H11: €/j | I11: 0（登记偏差） | J11: =IF(OR(F14="",G14=""),"",G14-F14) | K11: 偏差登记 | L11: Q-02 | M11: 浓缩乳糖revenue报告128 €/j，价×量=135,173 €/j，无法复现（不影响AF，AF直接给出） | N11: 价×量复算 | O11: 偏差已复算确认 | P11: PA-PRICE-LAC;FL-LAC
A12: CH-15 | B12: 能源合计 | C12: 产品系统 | D12: ALL | E12: 逐步电力加总（生产段，WPI边界PR01-12+20） | G12: 25806.3 | H12: kWh/d | I12: ±1 | J12: =IF(OR(F16="",G16=""),"",G16-F16) | K12: PASS | M12: WPI边界生产电力合计25806.3 kWh/d（分项加总，含污水站5,050.7）；清洗电另计约2084.0 kWh/d | N12: 逐步加总 | O12: WPI边界生产电力合计25806.3 kWh/d已复算 | P12: FL-EL-01~FL-EL-12;FL-EL-20
A13: CH-16 | B13: 水平衡 | C13: 过程 | D13: PR20 | E13: 污水站进水191.7 vs 出水proxy 450 | G13: 258.3 | H13: m3/d | I13: 0（登记偏差） | J13: =IF(OR(F17="",G17=""),"",G17-F17) | K13: 偏差登记 | L13: Q-15 | M13: 出水450 m³/d为proxy项目参考流，与实际进水191.7 m³/d不对应；使用出水数据时须按proxy口径 | N13: 框值比对 | O13: proxy口径差异已登记 | P13: FL-WW-20;FL-TEW-20
A14: CH-17 | B14: 资本品合计 | C14: 产品系统 | D14: ALL | E14: Machines段128条设备/部件级材料加总（8条无数据未计入） | G14: 26.59 | H14: kg/d | I14: ±0.1 | J14: =IF(OR(F18="",G18=""),"",G18-F18) | K14: PASS | M14: 20步Machines段128条资本品材料合计约26.6 kg/d（不锈钢/铜/铝/橡胶/膜材料等，按天摊销）；8条无数据行未计入（登记GB-01） | N14: 逐步加总 | O14: 资本品合计26.6 kg/d已复算 | P14: FL-MCH-*
J15: =IF(OR(F19="",G19=""),"",G19-F19)
J16: =IF(OR(F20="",G20=""),"",G20-F20)
J17: =IF(OR(F21="",G21=""),"",G21-F21)
J18: =IF(OR(F22="",G22=""),"",G22-F22)
J19: =IF(OR(F23="",G23=""),"",G23-F23)
J20: =IF(OR(F24="",G24=""),"",G24-F24)
J21: =IF(OR(F25="",G25=""),"",G25-F25)
J22: =IF(OR(F26="",G26=""),"",G26-F26)
J23: =IF(OR(F27="",G27=""),"",G27-F27)
J24: =IF(OR(F28="",G28=""),"",G28-F28)
J25: =IF(OR(F29="",G29=""),"",G29-F29)
J26: =IF(OR(F30="",G30=""),"",G30-F30)
... J200: =IF(OR(F204="",G204=""),"",G204-F204)

Sheet 问题与决策
A1: 问题与决策
A2: 保留来源差异、影响、候选处理和用户决定；实际改变要写回事实表。
A4: 问题ID | B4: 对象类型 | C4: 对象ID | D4: 问题描述 | E4: 证据/来源 | F4: 影响 | G4: 候选处理 | H4: 用户决定 | I4: 状态 | J4: 执行位置 | K4: 更新日期 | L4: 备注 | M4: 是否阻断冻结 | N4: 确认日期 | O4: 归属操作ID
A5: Q-01 | B5: 过程 | C5: PR02 | D5: 奶脂分离步骤质量不平衡：出料593,958 kg/j < 入料600,490 kg/j（-6,532 kg/j，-1.09%），源数据未报告损失 | E5: SRC-PDF p1 步骤2框；CH-01 | F5: 链级质量平衡基准偏差1.09% | G5: 保留原文值，登记不平衡，不自行补差 | H5: 原始版体积平衡闭合（583=525+58）；质量差为衍生版密度口径差，不再作为源数据缺陷；v2以SRC-RAW体积为权威基准 | I5: 已解决 | J5: 核算检查CH-01 | K5: 2026-09-27 | M5: 否 | O5: PR02
A6: Q-02 | B6: 参数 | C6: PA-PRICE-LAC | D6: 两处revenue无法复现：浓缩乳糖128 €/j vs 价×量135,173 €/j；产品1 22,186 vs 21,298.5 €/j | E6: SRC-PDF p1；CH-10/CH-11 | F6: 不影响分配因子（AF直接给出）；影响经济核算展示 | G6: 保留报告值并标注不可复现 | H6: 用户决定（2026-09-28）：不做经济分配，revenue数字不复算不影响清单；登记关闭 | I6: 已解决 | J6: 核算检查CH-10/CH-11 | K6: 2026-09-27 | M6: 否 | O6: PR11
A7: Q-03 | B7: 过程 | C7: PR05 | D7: MF1出料比入料多700 kg/j（+0.13%） | E7: SRC-PDF p1 步骤5框；CH-02 | F7: 质量平衡基准 | G7: 保留原文值，登记偏差 | H7: 原始版体积闭合（175+350=525）；衍生版质量差登记为口径差 | I7: 已解决 | J7: 核算检查CH-02 | K7: 2026-09-27 | M7: 否 | O7: PR05
A8: Q-06 | B8: 过程 | C8: PR08 | D8: UF10蛋白不平衡：入2,093.9 kg蛋白/j，出1,368.5 kg/j（渗透液蛋白标0），34.6%蛋白去向未报告 | E8: SRC-PDF p1 步骤8框；CH-08 | F8: 蛋白回收率解释；影响产品蛋白纯度来源可信度 | G8: 保留原文值，登记缺口 | H8: 口径已明确（2026-09-28用户指示）：原文基线=体积守恒（8_UF1: 350+63=11.7+401.3 ✓），原文不做组分守恒；所谓蛋白34.6%差系衍生版密度×组成%换算引入，非原文数据问题。衍生版组成参数已全部降级为不采用（仅参考）。关闭 | I8: 已解决 | J8: 核算检查CH-08 | K8: 2026-09-27 | M8: 否 | O8: PR08
A9: Q-07 | B9: 方法 | C9: ALL | D9: 目标研究ALCA分配规则选择：mass / dry matter / protein / economic 四套因子均已入库，采用哪套（或并存敏感性）待用户决定；功能单位换算至每kg产品亦依赖此决定 | E9: SRC-XLSX allocation_tables；项目说明 | F9: 负担分配与每kg产品清单 | G9: 候选全部保留；不替用户选择 | H9: 用户决定（2026-09-27）：不分配、不替代、不做LCIA；交付全产品系统清单（主产品/联产品/废水并列输出）；建模模式attributional；四套ALCA分配因子（mass/dry matter/protein/economic）保留在候选数据但不采用【2026-09-29 由 Q-19 取代：课题更正为 CLCA，四套 AF 仅作对照留档】 | I9: 已解决 | J9: 项目说明/模型参数PA-AF-* | K9: 2026-09-27 | M9: 否 | O9: ALL
A10: Q-08 | B10: 背景接口 | C10: ALL | D10: 背景数据缺失：各操作电力/蒸汽消耗、酸化剂（pH3.8）与复溶碱（pH7）用量、清洗剂、运输燃料均未报告，未连接背景数据库 | E10: SRC-PDF 全图无能源流 | F10: 无法计算能耗图与任何LCIA结果 | G10: 登记待补参数清单GB-01~GB-05 | H10: 能源/化学品/CIP数据已在v2从SRC-RAW补入（逐步电力/燃气热/柠檬酸/CaCl2/NaOH/清洗段全项）；背景数据库按用户要求不连接 | I10: 已解决 | J10: 待补参数清单 | K10: 2026-09-27 | M10: 否 | O10: ALL
A11: Q-09 | B11: 过程 | C11: PR11 | D11: RO步骤干物质不守恒：进17,869.09 kg DM/j，出21,627.74 kg DM/j（+3,758.65） | E11: SRC-XLSX? no；SRC-PDF p1 步骤8渗透液DM4.40%、步骤11乳糖DM24%；CH-07 | F11: 乳糖联产品DM基准内部矛盾 | G11: 保留原文值，登记矛盾，建议回查原始文献 | H11: 口径已明确（2026-09-28用户指示）：原文基线=体积守恒（11_OI: 401.3=85.3+316 ✓，原文注'losses are neglected'），不做组分守恒；DM+21%系衍生版组成%换算引入，非原文数据问题。衍生版组成参数已全部降级为不采用（仅参考）。关闭 | I11: 已解决 | J11: 核算检查CH-07 | K11: 2026-09-27 | M11: 否 | O11: PR11
A12: Q-10 | B12: 来源 | C12: SYS-WHEY-2023 | D12: 单来源体系；图内部分参数二手引用Gesan-Guiziou et al (2019)，原文未提供未核对（secondary_evidence）；框架文献主文未提供 | E12: SRC-PDF 图例；S1.3 | F12: 闸门C判定：若无用户自有决策/多源采用，则不输出建模接口 | G12: 登记来源局限；请用户补充主文或确认接受 | H12: 登记保留：单来源体系+二手引用标注作为数据可信度备注，不回查（2026-09-28） | I12: 未解决 | J12: 数据来源 | K12: 2026-09-27 | M12: 否 | O12: ALL
A13: Q-12 | B13: 来源 | C13: SYS-GUY-2024-DIB | D13: 多版本核验结论：同一DIB数据集包（已发表，recherche.data.gouv.fr DOI 10.57745/7D0ROH）内含两层文件——原始记录层（SRC-RAW 20步全项）与示意图/分配数据层（v231127 PDF/XLSX，数据集自带）；示意图层将体积×密度换算为质量、AF修约2位小数、不含能源/清洗/化学品/污水，并存在具体换算差错：UFbeta透析水误记66.93 m³/d（原始4.6）、干燥蒸发水5.7/1.0 m³误读为入料水、复溶液3.96 m³混入稀释水、产品量1703.88/318.34与原始1703.97/318.28微差 | E13: SRC-RAW vs SRC-PDF 指纹比对（2026-09-27） | F13: v1.0清单可信度；v2已全部改取SRC-RAW | G13: 撤回衍生版数值（组成%/价格/干燥参数保留为衍生版标注候选）；权威版=SRC-RAW | H13: 用户指示采用DIB数据集（2026-09-27），权威版SRC-RAW | I13: 已解决 | J13: 数据来源/候选数据 | K13: 2026-09-27 | L13: 示意图层独有内容：组成%、虚构价格、干燥专家参数、Figure n°X | M13: 否 | N13: 2026-09-27 | O13: ALL
A14: Q-15 | B14: 过程 | C14: PR20 | D14: 污水站出水450 m³/d为proxy项目参考流，与进水191.7 m³/d不对应 | E14: SRC-RAW 20_STEP；CH-16 | F14: 出水污染物数据的使用口径 | G14: 按proxy口径登记，使用时注明 | H14: 登记：出水按proxy口径使用并注明（GB-04） | I14: 未解决 | J14: 核算检查CH-16 | K14: 2026-09-27 | M14: 否 | O14: PR20
A17: Q-17 | B17: 边界 | C17: ALL-OPS | D17: 机器设备材料（资本品）：SRC-RAW各表Machines段精确到设备/部件级（如Installation d'ultrafiltration→organic membrane→Polyethersulfone 0.38 kg/d） | E17: SRC-RAW Machines段 | F17: 清单边界完整性 | G17: 用户2026-09-28决定纳入：128条设备/部件级材料流入库（FL-MCH-*，8条无数据登记缺口）；8条无数据行（Glycerin×4、pipes×3、Support et tuyauteries）登记为源数据缺口 | H17: 纳入资本品（2026-09-28） | I17: 已解决 | J17: 待补参数清单GB-01 | K17: 2026-09-27 | M17: 否 | O17: ALL
A18: Q-18 | B18: 流 | C18: FL-TEW-20 | D18: 污水站出水450 m3/d（proxy）复审：复审其与5个出水负荷指标（TSS/TN/TP/COD/TKN）的绑定关系，以及m3口径对清单输出的敏感性（关联Q-15） | E18: SRC-RAW 20_STEP treated water (proxy project)；CH-16 | F18: 出水污染物数据的使用口径 | G18: 保留proxy口径登记（GB-04），复审时再定是否维持 | H18: 2026-09-28 用户指示：之后要复审 | I18: 待复审 | J18: 核算检查CH-16
A202: Q-19 | B202: 方法 | C202: ALL | D202: 范式口径更正：课题为 CLCA（边际预测），框架文献 Guyomarc'h 2024 为 ALCA——按范式三分类情况③（不同），放弃文献分配因子，课题走边际供应商＋副产品替代 | E202: 用户 2026-09-29 指示；原 Q-07 决定 | F202: 分配因子不进入课题模型；功能三需建替代接口与边际供应商 | G202: 四套 AF（PA-AF-*）保留候选作对照留档 | H202: 用户决定（2026-09-29）：课题 CLCA，放弃文献分配因子；边际供应商＋副产品替代待功能三确定 | I202: 已解决 | J202: 项目说明.建模模式／分配政策／副产品替代状态 | K202: 2026-09-29 | L202: 取代 Q-07 的 attributional 口径

Sheet 绘图确认
A1: 绘图确认
A2: 科学字段由模型过程和模型流派生；用户只确认展开、显示、标签和样式。
A3: 只确认展开、显示和标签；L/M列自动引用模型流，不能手填科学数值。
A4: 对象ID | B4: 对象类型 | C4: 来源ID | D4: 所属车间 | E4: 来源过程ID | F4: 目标过程ID | G4: 主支线ID | H4: 展开方式 | I4: 是否显示 | J4: 显示标签 | K4: 是否显示数值 | L4: 代表值 | M4: 单位 | N4: 标签模式 | O4: 样式角色 | P4: 数据功能确认 | Q4: 绘图功能确认 | R4: Draw.io对象ID | S4: QA状态 | T4: 关联问题ID | U4: 备注
A5: FL-RM | B5: Edge | F5: PR01-OP1 | G5: 主线 | I5: 是 | J5: 原料奶 583 | L5: =IF(A5="","",IF(B5="Edge",IFERROR(IF(INDEX('模型流与公式'!$P$5:$P$204,MATCH(A5,'模型流与公式'!$A$5:$A$204,0))="","",INDEX('模型流与公式'!$P$5:$P$204,MATCH(A5,'模型流与公式'!$A$5:$A$204,0))),""),"")) | M5: =IF(A5="","",IF(B5="Edge",IFERROR(IF(INDEX('模型流与公式'!$Q$5:$Q$204,MATCH(A5,'模型流与公式'!$A$5:$A$204,0))="","",INDEX('模型流与公式'!$Q$5:$Q$204,MATCH(A5,'模型流与公式'!$A$5:$A$204,0))),""),""))
A6: FL-SKIM | B6: Edge | E6: PR02-OP1 | F6: PR04-OP1 | G6: 主线 | I6: 是 | J6: 脱脂奶 525 | L6: =IF(A6="","",IF(B6="Edge",IFERROR(IF(INDEX('模型流与公式'!$P$5:$P$204,MATCH(A6,'模型流与公式'!$A$5:$A$204,0))="","",INDEX('模型流与公式'!$P$5:$P$204,MATCH(A6,'模型流与公式'!$A$5:$A$204,0))),""),"")) | M6: =IF(A6="","",IF(B6="Edge",IFERROR(IF(INDEX('模型流与公式'!$Q$5:$Q$204,MATCH(A6,'模型流与公式'!$A$5:$A$204,0))="","",INDEX('模型流与公式'!$Q$5:$Q$204,MATCH(A6,'模型流与公式'!$A$5:$A$204,0))),""),""))
A7: FL-CREAM | B7: Edge | E7: PR02-OP1 | F7: PR03-OP1 | G7: 支线（奶油） | I7: 是 | J7: 稀奶油 58 | L7: =IF(A7="","",IF(B7="Edge",IFERROR(IF(INDEX('模型流与公式'!$P$5:$P$204,MATCH(A7,'模型流与公式'!$A$5:$A$204,0))="","",INDEX('模型流与公式'!$P$5:$P$204,MATCH(A7,'模型流与公式'!$A$5:$A$204,0))),""),"")) | M7: =IF(A7="","",IF(B7="Edge",IFERROR(IF(INDEX('模型流与公式'!$Q$5:$Q$204,MATCH(A7,'模型流与公式'!$A$5:$A$204,0))="","",INDEX('模型流与公式'!$Q$5:$Q$204,MATCH(A7,'模型流与公式'!$A$5:$A$204,0))),""),""))
A8: FL-CAS | B8: Edge | E8: PR05-OP1 | F8: PR06-OP1 | G8: 支线（胶束酪蛋白） | I8: 是 | J8: 胶束酪蛋白 175 | L8: =IF(A8="","",IF(B8="Edge",IFERROR(IF(INDEX('模型流与公式'!$P$5:$P$204,MATCH(A8,'模型流与公式'!$A$5:$A$204,0))="","",INDEX('模型流与公式'!$P$5:$P$204,MATCH(A8,'模型流与公式'!$A$5:$A$204,0))),""),"")) | M8: =IF(A8="","",IF(B8="Edge",IFERROR(IF(INDEX('模型流与公式'!$Q$5:$Q$204,MATCH(A8,'模型流与公式'!$A$5:$A$204,0))="","",INDEX('模型流与公式'!$Q$5:$Q$204,MATCH(A8,'模型流与公式'!$A$5:$A$204,0))),""),""))
A9: FL-WHEY | B9: Edge | E9: PR05-OP1 | F9: PR07-OP1 | G9: 主线 | I9: 是 | J9: 乳清 350 | L9: =IF(A9="","",IF(B9="Edge",IFERROR(IF(INDEX('模型流与公式'!$P$5:$P$204,MATCH(A9,'模型流与公式'!$A$5:$A$204,0))="","",INDEX('模型流与公式'!$P$5:$P$204,MATCH(A9,'模型流与公式'!$A$5:$A$204,0))),""),"")) | M9: =IF(A9="","",IF(B9="Edge",IFERROR(IF(INDEX('模型流与公式'!$Q$5:$Q$204,MATCH(A9,'模型流与公式'!$A$5:$A$204,0))="","",INDEX('模型流与公式'!$Q$5:$Q$204,MATCH(A9,'模型流与公式'!$A$5:$A$204,0))),""),""))
A10: FL-W08 | B10: Edge | F10: PR08-OP1 | G10: 主线 | I10: 是 | J10: UF10透析水 63 | L10: =IF(A10="","",IF(B10="Edge",IFERROR(IF(INDEX('模型流与公式'!$P$5:$P$204,MATCH(A10,'模型流与公式'!$A$5:$A$204,0))="","",INDEX('模型流与公式'!$P$5:$P$204,MATCH(A10,'模型流与公式'!$A$5:$A$204,0))),""),"")) | M10: =IF(A10="","",IF(B10="Edge",IFERROR(IF(INDEX('模型流与公式'!$Q$5:$Q$204,MATCH(A10,'模型流与公式'!$A$5:$A$204,0))="","",INDEX('模型流与公式'!$Q$5:$Q$204,MATCH(A10,'模型流与公式'!$A$5:$A$204,0))),""),""))
A11: FL-WPI | B11: Edge | E11: PR08-OP1 | F11: PR09-OP1 | G11: 主线 | I11: 是 | J11: WPI浓缩液 11.7 | L11: =IF(A11="","",IF(B11="Edge",IFERROR(IF(INDEX('模型流与公式'!$P$5:$P$204,MATCH(A11,'模型流与公式'!$A$5:$A$204,0))="","",INDEX('模型流与公式'!$P$5:$P$204,MATCH(A11,'模型流与公式'!$A$5:$A$204,0))),""),"")) | M11: =IF(A11="","",IF(B11="Edge",IFERROR(IF(INDEX('模型流与公式'!$Q$5:$Q$204,MATCH(A11,'模型流与公式'!$A$5:$A$204,0))="","",INDEX('模型流与公式'!$Q$5:$Q$204,MATCH(A11,'模型流与公式'!$A$5:$A$204,0))),""),""))
A12: FL-LACP | B12: Edge | E12: PR08-OP1 | F12: PR11-OP1 | G12: 支线（乳糖） | I12: 是 | J12: 乳糖渗透液 401.3 | L12: =IF(A12="","",IF(B12="Edge",IFERROR(IF(INDEX('模型流与公式'!$P$5:$P$204,MATCH(A12,'模型流与公式'!$A$5:$A$204,0))="","",INDEX('模型流与公式'!$P$5:$P$204,MATCH(A12,'模型流与公式'!$A$5:$A$204,0))),""),"")) | M12: =IF(A12="","",IF(B12="Edge",IFERROR(IF(INDEX('模型流与公式'!$Q$5:$Q$204,MATCH(A12,'模型流与公式'!$A$5:$A$204,0))="","",INDEX('模型流与公式'!$Q$5:$Q$204,MATCH(A12,'模型流与公式'!$A$5:$A$204,0))),""),""))
A13: FL-OSM | B13: Edge | E13: PR11-OP1 | G13: 支线（乳糖） | I13: 是 | J13: 渗透水 316 | L13: =IF(A13="","",IF(B13="Edge",IFERROR(IF(INDEX('模型流与公式'!$P$5:$P$204,MATCH(A13,'模型流与公式'!$A$5:$A$204,0))="","",INDEX('模型流与公式'!$P$5:$P$204,MATCH(A13,'模型流与公式'!$A$5:$A$204,0))),""),"")) | M13: =IF(A13="","",IF(B13="Edge",IFERROR(IF(INDEX('模型流与公式'!$Q$5:$Q$204,MATCH(A13,'模型流与公式'!$A$5:$A$204,0))="","",INDEX('模型流与公式'!$Q$5:$Q$204,MATCH(A13,'模型流与公式'!$A$5:$A$204,0))),""),""))
A14: FL-LAC | B14: Edge | E14: PR11-OP1 | F14: PR12-OP1 | G14: 支线（乳糖） | I14: 是 | J14: 浓缩乳糖 85.3 | L14: =IF(A14="","",IF(B14="Edge",IFERROR(IF(INDEX('模型流与公式'!$P$5:$P$204,MATCH(A14,'模型流与公式'!$A$5:$A$204,0))="","",INDEX('模型流与公式'!$P$5:$P$204,MATCH(A14,'模型流与公式'!$A$5:$A$204,0))),""),"")) | M14: =IF(A14="","",IF(B14="Edge",IFERROR(IF(INDEX('模型流与公式'!$Q$5:$Q$204,MATCH(A14,'模型流与公式'!$A$5:$A$204,0))="","",INDEX('模型流与公式'!$Q$5:$Q$204,MATCH(A14,'模型流与公式'!$A$5:$A$204,0))),""),""))
A15: FL-TKM-10 | B15: Edge | F15: PR10-OP1 | G15: 主线 | I15: 是 | J15: WPI冷藏运输 1,370 t·km | L15: =IF(A15="","",IF(B15="Edge",IFERROR(IF(INDEX('模型流与公式'!$P$5:$P$204,MATCH(A15,'模型流与公式'!$A$5:$A$204,0))="","",INDEX('模型流与公式'!$P$5:$P$204,MATCH(A15,'模型流与公式'!$A$5:$A$204,0))),""),"")) | M15: =IF(A15="","",IF(B15="Edge",IFERROR(IF(INDEX('模型流与公式'!$Q$5:$Q$204,MATCH(A15,'模型流与公式'!$A$5:$A$204,0))="","",INDEX('模型流与公式'!$Q$5:$Q$204,MATCH(A15,'模型流与公式'!$A$5:$A$204,0))),""),""))
A16: FL-SLURRY-20 | B16: Edge | F16: PR20-OP1 | G16: 支线（三废处理） | I16: 是 | J16: 污泥运输 45.6 t·km | L16: =IF(A16="","",IF(B16="Edge",IFERROR(IF(INDEX('模型流与公式'!$P$5:$P$204,MATCH(A16,'模型流与公式'!$A$5:$A$204,0))="","",INDEX('模型流与公式'!$P$5:$P$204,MATCH(A16,'模型流与公式'!$A$5:$A$204,0))),""),"")) | M16: =IF(A16="","",IF(B16="Edge",IFERROR(IF(INDEX('模型流与公式'!$Q$5:$Q$204,MATCH(A16,'模型流与公式'!$A$5:$A$204,0))="","",INDEX('模型流与公式'!$Q$5:$Q$204,MATCH(A16,'模型流与公式'!$A$5:$A$204,0))),""),""))
A17: FL-O-CREAM | B17: Edge | E17: PR03-OP1 | G17: 支线（奶油） | I17: 是 | J17: 奶油（联产品）58 | L17: =IF(A17="","",IF(B17="Edge",IFERROR(IF(INDEX('模型流与公式'!$P$5:$P$204,MATCH(A17,'模型流与公式'!$A$5:$A$204,0))="","",INDEX('模型流与公式'!$P$5:$P$204,MATCH(A17,'模型流与公式'!$A$5:$A$204,0))),""),"")) | M17: =IF(A17="","",IF(B17="Edge",IFERROR(IF(INDEX('模型流与公式'!$Q$5:$Q$204,MATCH(A17,'模型流与公式'!$A$5:$A$204,0))="","",INDEX('模型流与公式'!$Q$5:$Q$204,MATCH(A17,'模型流与公式'!$A$5:$A$204,0))),""),""))
A18: FL-O-CAS | B18: Edge | E18: PR06-OP1 | G18: 支线（胶束酪蛋白） | I18: 是 | J18: 酪蛋白（联产品）175 | L18: =IF(A18="","",IF(B18="Edge",IFERROR(IF(INDEX('模型流与公式'!$P$5:$P$204,MATCH(A18,'模型流与公式'!$A$5:$A$204,0))="","",INDEX('模型流与公式'!$P$5:$P$204,MATCH(A18,'模型流与公式'!$A$5:$A$204,0))),""),"")) | M18: =IF(A18="","",IF(B18="Edge",IFERROR(IF(INDEX('模型流与公式'!$Q$5:$Q$204,MATCH(A18,'模型流与公式'!$A$5:$A$204,0))="","",INDEX('模型流与公式'!$Q$5:$Q$204,MATCH(A18,'模型流与公式'!$A$5:$A$204,0))),""),""))
A19: FL-O-LAC | B19: Edge | E19: PR12-OP1 | G19: 支线（乳糖） | I19: 是 | J19: 乳糖（联产品）85.3 | L19: =IF(A19="","",IF(B19="Edge",IFERROR(IF(INDEX('模型流与公式'!$P$5:$P$204,MATCH(A19,'模型流与公式'!$A$5:$A$204,0))="","",INDEX('模型流与公式'!$P$5:$P$204,MATCH(A19,'模型流与公式'!$A$5:$A$204,0))),""),"")) | M19: =IF(A19="","",IF(B19="Edge",IFERROR(IF(INDEX('模型流与公式'!$Q$5:$Q$204,MATCH(A19,'模型流与公式'!$A$5:$A$204,0))="","",INDEX('模型流与公式'!$Q$5:$Q$204,MATCH(A19,'模型流与公式'!$A$5:$A$204,0))),""),""))
A20: FL-O-WPI | B20: Edge | E20: PR10-OP1 | G20: 主线 | I20: 是 | J20: WPI浓缩液（出厂）11.7 | L20: =IF(A20="","",IF(B20="Edge",IFERROR(IF(INDEX('模型流与公式'!$P$5:$P$204,MATCH(A20,'模型流与公式'!$A$5:$A$204,0))="","",INDEX('模型流与公式'!$P$5:$P$204,MATCH(A20,'模型流与公式'!$A$5:$A$204,0))),""),"")) | M20: =IF(A20="","",IF(B20="Edge",IFERROR(IF(INDEX('模型流与公式'!$Q$5:$Q$204,MATCH(A20,'模型流与公式'!$A$5:$A$204,0))="","",INDEX('模型流与公式'!$Q$5:$Q$204,MATCH(A20,'模型流与公式'!$A$5:$A$204,0))),""),""))
A21: FL-NH3-03 | B21: Edge | I21: 否 | L21: =IF(A21="","",IF(B21="Edge",IFERROR(IF(INDEX('模型流与公式'!$P$5:$P$204,MATCH(A21,'模型流与公式'!$A$5:$A$204,0))="","",INDEX('模型流与公式'!$P$5:$P$204,MATCH(A21,'模型流与公式'!$A$5:$A$204,0))),""),"")) | M21: =IF(A21="","",IF(B21="Edge",IFERROR(IF(INDEX('模型流与公式'!$Q$5:$Q$204,MATCH(A21,'模型流与公式'!$A$5:$A$204,0))="","",INDEX('模型流与公式'!$Q$5:$Q$204,MATCH(A21,'模型流与公式'!$A$5:$A$204,0))),""),"")) | U21: 制冷剂NH3补加逐条见冻结清单（1_RCS为m³/d）
A22: FL-NH3-05 | B22: Edge | I22: 否 | L22: =IF(A22="","",IF(B22="Edge",IFERROR(IF(INDEX('模型流与公式'!$P$5:$P$204,MATCH(A22,'模型流与公式'!$A$5:$A$204,0))="","",INDEX('模型流与公式'!$P$5:$P$204,MATCH(A22,'模型流与公式'!$A$5:$A$204,0))),""),"")) | M22: =IF(A22="","",IF(B22="Edge",IFERROR(IF(INDEX('模型流与公式'!$Q$5:$Q$204,MATCH(A22,'模型流与公式'!$A$5:$A$204,0))="","",INDEX('模型流与公式'!$Q$5:$Q$204,MATCH(A22,'模型流与公式'!$A$5:$A$204,0))),""),"")) | U22: 制冷剂NH3补加逐条见冻结清单（1_RCS为m³/d）
A23: FL-NH3-06 | B23: Edge | I23: 否 | L23: =IF(A23="","",IF(B23="Edge",IFERROR(IF(INDEX('模型流与公式'!$P$5:$P$204,MATCH(A23,'模型流与公式'!$A$5:$A$204,0))="","",INDEX('模型流与公式'!$P$5:$P$204,MATCH(A23,'模型流与公式'!$A$5:$A$204,0))),""),"")) | M23: =IF(A23="","",IF(B23="Edge",IFERROR(IF(INDEX('模型流与公式'!$Q$5:$Q$204,MATCH(A23,'模型流与公式'!$A$5:$A$204,0))="","",INDEX('模型流与公式'!$Q$5:$Q$204,MATCH(A23,'模型流与公式'!$A$5:$A$204,0))),""),"")) | U23: 制冷剂NH3补加逐条见冻结清单（1_RCS为m³/d）
A24: FL-NH3-08 | B24: Edge | I24: 否 | L24: =IF(A24="","",IF(B24="Edge",IFERROR(IF(INDEX('模型流与公式'!$P$5:$P$204,MATCH(A24,'模型流与公式'!$A$5:$A$204,0))="","",INDEX('模型流与公式'!$P$5:$P$204,MATCH(A24,'模型流与公式'!$A$5:$A$204,0))),""),"")) | M24: =IF(A24="","",IF(B24="Edge",IFERROR(IF(INDEX('模型流与公式'!$Q$5:$Q$204,MATCH(A24,'模型流与公式'!$A$5:$A$204,0))="","",INDEX('模型流与公式'!$Q$5:$Q$204,MATCH(A24,'模型流与公式'!$A$5:$A$204,0))),""),"")) | U24: 制冷剂NH3补加逐条见冻结清单（1_RCS为m³/d）
A25: FL-NH3-09 | B25: Edge | I25: 否 | L25: =IF(A25="","",IF(B25="Edge",IFERROR(IF(INDEX('模型流与公式'!$P$5:$P$204,MATCH(A25,'模型流与公式'!$A$5:$A$204,0))="","",INDEX('模型流与公式'!$P$5:$P$204,MATCH(A25,'模型流与公式'!$A$5:$A$204,0))),""),"")) | M25: =IF(A25="","",IF(B25="Edge",IFERROR(IF(INDEX('模型流与公式'!$Q$5:$Q$204,MATCH(A25,'模型流与公式'!$A$5:$A$204,0))="","",INDEX('模型流与公式'!$Q$5:$Q$204,MATCH(A25,'模型流与公式'!$A$5:$A$204,0))),""),"")) | U25: 制冷剂NH3补加逐条见冻结清单（1_RCS为m³/d）
