Workbook

Sheet 00_工作流总控
A1: 前景清单与绘图工作流 | K1: 实时检查 | L1: 结果
A2: 数据功能按用户确认的文献清单工作流推进；闸门 B 确认冻结范围后，绘图功能另行启动。 | K2: 未解决问题 | L2: =COUNTIF('问题与决策'!$I$5:$I$204,"未解决")
K3: BLOCKED 检查 | L3: =COUNTIF('核算检查'!$K$5:$K$204,"BLOCKED")
A4: 阶段 | B4: 任务 | C4: 输入 | D4: 输出 | E4: 完成条件 | F4: 状态 | G4: 负责人/确认人 | H4: 版本/日期 | I4: 备注 | K4: 数据功能确认 | L4: =COUNTIF('绘图确认'!$P$5:$P$204,"已确认")
A5: S01 | B5: S1.1–S1.3 课题、文献与原始清单 | C5: 研究课题与候选来源 | D5: 课题摘要和原始清单核验 | E5: C1 的完整指完整生命周期清单；缺文件已报告 | F5: 完成 | G5: 用户2026-09-26闸门B确认 | H5: 2026-09-26 | I5: S1.1–S1.3 完成；本轮附件缺 (1) 版工作簿与 runtime 文件，已登记 Q10 | K5: 绘图功能入口 | L5: =IF(AND(L2=0,L3=0,L4>0),"可进入","暂不可进入")
A6: S02 | B6: S1.4 双文献池分类 | C6: 来源文件及依赖 | D6: 完整清单池、参数选取池 | E6: C2 完整清单池非空；一篇来源可兼任两池 | F6: 完成 | G6: 用户2026-09-26闸门B确认 | H6: 2026-09-26 | I6: 完整清单池=SYS-Siegrist2026；参数池含其内部引用来源（二级引用）
A7: S03 | B7: S2.1 分文献整理方案 | C7: 候选来源与课题 | D7: 方法、边界与取数方案 | E7: 目标口径及前景/背景接口已说明 | F7: 完成 | G7: 用户2026-09-26闸门B确认 | H7: 2026-09-26 | I7: 目标 CLCA；FU=1 kg SPI；边界与背景接口已记录于项目说明
A8: S04 | B8: S2.2–S2.3 框架选择与闸门A | C8: 完整清单文献池 | D8: 框架文献及单元操作结构 | E8: 用户确认框架；否决理由及候选处理留痕 | F8: 完成 | G8: 用户2026-09-26闸门B确认 | H8: 2026-09-26 | I8: 框架=SYS-Siegrist2026（池内唯一）；骨架沿用上一轮并经本轮复核；否决理由不适用
A9: S05 | B9: S3.1–S3.3 基准、最小黑箱与覆盖度 | C9: 框架文献与附件 | D9: 模块划分和参数覆盖度矩阵 | E9: 功能单位、边界、操作粒度及缺口已登记 | F9: 完成 | G9: 用户2026-09-26闸门B确认 | H9: 2026-09-26 | I9: 五级覆盖度矩阵已建；M1–M3 全部操作登记
A10: S06 | B10: S3.4 全部流识别 | C10: 模块与操作结构 | D10: 输入、输出、内部转移和循环流 | E10: 逐流端点、方向与边界已登记 | F10: 完成 | G10: 用户2026-09-26闸门B确认 | H10: 2026-09-26 | I10: 24 条采用流＋3 条替代接口；端点/方向/边界已登记
A11: S07 | B11: D1、S3.5–S3.7 公式溯源与逐流卡 | C11: 来源参数、公式和流 | D11: 采用参数、流及公式依赖 | E11: 公式递归到输入参数；流卡有证据和稳定ID | F11: 完成 | G11: 用户2026-09-26闸门B确认 | H11: 2026-09-26 | I11: 逐流卡：来源、公式链、参数 ID、证据、采用状态齐备
A12: S08 | B12: QC 清单复核 | C12: 参数、公式、流与覆盖矩阵 | D12: 核算检查与问题标记 | E12: 复查仍有问题已及时向用户报告并记录决定 | F12: 完成 | G12: 用户2026-09-26闸门B确认 | H12: 2026-09-26 | I12: 14 项核算检查已执行；QC 后问题已登记并汇报（见 S4.1）
A13: S09 | B13: S4.1 汇报与闸门B | C13: 模块化清单、覆盖度、问题 | D13: Excel与待补参数清单 | E13: 用户确认清单、待补项及可冻结范围 | F13: 已确认 | G13: 用户2026-09-26确认 | H13: 2026-09-26 | I13: 闸门B已确认：冻结范围=模块骨架＋已采用流卡＋方法口径；Q03–Q05受影响exchange已标阻断不进冻结集
A14: S10 | B14: 绘图功能内容蓝图 | C14: 冻结 Excel | D14: 绘图确认 | E14: 显示决定经用户另行确认 | F14: 未开始
A15: S11 | B15: Draw.io 绘制复检 | C15: 已确认规格 | D15: 原生 .drawio | E15: 结构、内容与渲染检查通过 | F15: 未开始

Sheet 项目说明
A1: 项目说明
A3: 字段 | B3: 填写值 | C3: 说明
A4: 项目编号 | B4: SPI-CLCA-2026-001 | C4: 稳定工作编号
A5: 目标来源范围 | B5: 完整清单文献池仅 SYS-Siegrist2026（一篇框架）；参数候选来自其数据表内部引用来源（二级引用，未独立核对原文）及上一轮用户审计母表 | C5: 从完整清单文献池选择框架；没有候选则补充审查，不自动纯建模
A6: 目标产品系统 | B6: 大豆分离蛋白（SPI）价值链（Soy_protein_isolation）
A7: 产品名称 | B7: Soy Protein Isolate (SPI)
A8: 功能单位 | B8: 1 kg SPI（湿基，95% 干物质）
A9: 系统边界 | B9: cradle-to-gate 前景系统：破碎与脱皮→脱脂（调质/压片/溶剂萃取）→SPI 提取（碱提/离心/等电点沉淀/洗涤/干燥）；种植与干燥阶段为背景（Agrifootprint v6.3），运输为背景接口；资本品 excluded；SPI 路径不含 milling（value_chains.xlsx 已确认）
A10: 建模模式 | B10: consequential | C10: 用户确认目标 ALCA 或 CLCA；不得由来源自动代填
A11: 背景数据库类型 | B11: 作者平台：ecoinvent v3.10 (cut-off) + Agrifootprint v6.3；本研究 CLCA 背景映射待建模阶段确认 | C11: 按目标研究记录背景数据库及版本
A12: 分配政策 | B12: 本研究 CLCA 不分配；豆皮/豆油/spent flakes 显式物理共产品；替代/系统扩展在 CLCA 层单独定义（来源的 economic allocation 仅作方法证据，不采用） | C12: 物理流与 ALCA 分配或 CLCA 替代处理分开
A13: 副产品替代状态 | B13: 替代接口未定义；仅登记 substitution_candidate 接口行（F25–F27），待补清单 G06 跟踪 | C13: 副产品替代接口及供应商待目标研究确认
A14: 数值情景 | B14: representative | C14: 经确认的图示代表情景；不把全部代表值称为中位数
A15: 工作簿版本 | B15: 4.2
A16: 数据功能状态 | B16: frozen
A17: 冻结版本 | B17: v4.3-frozen-2026-09-27（补记绘图确认：27流显示决定＋13拓扑；科学数值未变） | C17: 数据功能确认后填写
A18: 工艺路线 | B18: 主文献锚定 | C18: 当前工作流只允许经闸门A确认的主文献锚定路线
A19: 整链主来源体系ID | B19: SYS-Siegrist2026 | C19: 闸门A确认的框架来源体系ID
A20: 产品质量规格 | B20: SPI 95% DM；蛋白 92.9%（干基）；white flakes 88% DM、59% 蛋白（干基） | C20: 纯度、湿干基或其他可比性条件
A21: 来源路线确认记录 | B21: Q02 / 用户 2026-09-19 锁定（交接文档§1），本轮沿用 | C21: 关联问题与决策 ID 或确认日期
A22: 数据功能用户确认 | B22: 用户2026-09-26确认闸门B；冻结范围=模块骨架＋已采用流卡＋方法口径 | C22: 未明确确认不得将工作簿标为冻结

Sheet 数据来源
A1: 数据来源
A2: 一行一个文件；候选值的页码/单元格见“候选数据”。同一研究的正文、附件和代码共用来源体系ID。
A4: 来源ID | B4: 文件名 | C4: 来源类型 | D4: 页码/章节/工作表 | E4: 单元格/公式位置 | F4: 原始内容摘要 | G4: 适用对象ID | H4: 证据状态 | I4: 备注 | J4: 来源体系ID | K4: 文件角色 | L4: 来源独立性 | M4: 上游依赖 | N4: 原研究方法 | O4: 工艺覆盖 | P4: 原功能单位 | Q4: 详细提取状态 | R4: 文献池角色 | S4: 完整清单证据
A5: SRC-PDF | B5: Siegrist_2026_A parametric LCA platform...pdf | C5: 期刊主文 | D5: Methods §2.1–2.8 | E5: Eq.1–3, Table 1 | F5: 参数化 LCA 平台；ALCA+经济分配；19 条价值链；SPI/SPC/PPI/PPC/WG 五配料 | G5: PS-SPI | H5: 已提取 | I5: DOI 10.1016/j.spc.2025.12.010 | J5: SYS-Siegrist2026 | K5: 主文 | L5: 独立 | M5: 无 | N5: ALCA（attributional），economic allocation | O5: 五配料整链（cultivation→gate） | P5: 1 kg product 与 1 kg protein 双功能单位 | Q5: 已详读 | R5: 完整清单文献池;参数选取文献池 | S5: 完整参数化前景清单见 SRC-XLS-OLD 的 General_parameters/Formulas_* 与 ppplca 代码；主文§2.3 声明 complete data inventory in SI2
A6: SRC-SI | B6: 1-s2.0-S2352550925002313-mmc1.docx | C6: 补充材料 | D6: Table S.1–S.6 | E6: 19 个表格 | F6: 价值链概览、Sobol 指数、结果 min/max/median（1 kg 产品与 1 kg 蛋白） | G6: PS-SPI | H6: 已提取 | I6: 结果层证据；不含过程清单 | J6: SYS-Siegrist2026 | K6: 补充材料 | L6: 独立 | M6: 无 | N6: 同主文 | O6: 结果汇总 | P6: 同主文 | Q6: 已提取 | R6: 参数选取文献池
A7: SRC-XLS-OLD | B7: SPI-Siegrist2026.xlsx | C7: 参数化清单工作簿（附件版=旧版本） | D7: General_parameters/Formulas_SPI/SPI/Defatting/Cleaning/Energy 等 18 表 | E7: SPI!I48=0.0463879（L6 硬编码 3） | F7: 作者详细推导工作簿：参数分布、质量流、能耗公式；旧版 L6=3 导致 SPI 电耗 0.0464（已弃用） | G7: 全部参数与流 | H7: 已提取-版本弃用 | I7: 本轮附件所附为旧版；当前版 SPI-Siegrist2026(1).xlsx 未随附件提供（Q01/Q10） | J7: SYS-Siegrist2026 | K7: 附件数据表 | L7: 共享来源体系 | M7: ppplca runtime | N7: ALCA 参数化清单 | O7: 五配料 | P7: 各过程 per kg 中间产品 | Q7: 已详读 | R7: 参数选取文献池 | S7: General_parameters＋Formulas_SPI 为完整参数化清单池证据（体系级）
A8: SRC-SI2 | B8: 1-s2.0-S2352550925002313-mmc2.xlsx | C8: 期刊官方补充材料 SI2（ScienceDirect 2026-09-26 重新下载） | D8: SPI/General_parameters/Formulas_SPI 等 17 表 | E8: SPI!L6==J6/K6；I48=0.0629995 | F8: 即上一轮所称当前版 (1)：与 GitHub runtime 全部 39 个 SPI 参数逐一比对一致；与旧版仅 2 处实质差异（L6、G18），其余为浮点显示精度 | G8: 全部采用值 | H8: 已提取-复核 | I8: 官方发布版本，证据等级最高；本地副本：Siegrist2026\1-s2.0-S2352550925002313-mmc2.xlsx | J8: SYS-Siegrist2026 | K8: 附件数据表（官方 SI2，当前权威版） | L8: 共享来源体系 | M8: ppplca runtime | N8: ALCA 参数化清单 | O8: 五配料 | P8: 各过程 per kg 中间产品 | Q8: 已详读 | R8: 参数选取文献池 | S8: General_parameters＋Formulas_SPI（官方发布口径）
A9: SRC-VC | B9: value_chains.xlsx | C9: 价值链情景配置 | D9: Value_chains 表 | E9: A2:L5（SPI 四情景） | F9: SPI 含 cultivation→dehulling→defatting→extraction→pointofuse；milling 字段为空 | G9: PS-SPI | H9: 已提取 | I9: 只决定阶段/地点/运输，不提供过程参数 | J9: SYS-Siegrist2026 | K9: 情景配置 | L9: 共享来源体系 | M9: 无 | N9: — | O9: 价值链阶段与地点 | P9: — | Q9: 已核查 | R9: 参数选取文献池
A10: SRC-NB | B10: main.ipynb | C10: 模型代码入口 | D10: 全部单元格 | E10: import ppplca / install / setup / run | F10: 仅调用 ppplca 包，无 SPI 参数覆盖 | G10: PS-SPI | H10: 已提取 | I10: 证明 notebook 无隐藏修正（上一轮代码审计结论） | J10: SYS-Siegrist2026 | K10: 代码 | L10: 共享来源体系 | M10: ppplca, ecoinvent 3.10, Agrifootprint 6.3 | N10: — | O10: — | P10: — | Q10: 已核查 | R10: 参数选取文献池
A11: SRC-README | B11: README.md | C11: 版本说明 | D11: 全文 | E11: — | F11: 模型依赖 ecoinvent v3.10 与 Agrifootprint v6.3 | G11: PS-SPI | H11: 已提取 | I11: README 链接 SPC 2026 论文；数据表 README 声明链接另一篇论文（Q07） | J11: SYS-Siegrist2026 | K11: 说明文件 | L11: 共享来源体系 | M11: 无 | N11: — | O11: — | P11: — | Q11: 已提取
A12: SRC-CLCA-AUDIT | B12: SPI_CLCA_阶段归档_参数审计与代码核查(1).xlsx | C12: 本研究上一轮审计母表 v0 | D12: Selected_Foreground_LCI/Model_Basis/Audit_Log/Energy_Breakdown 等 13 表 | E12: L01–L24、B01–B27、A01–A26 | F12: 上一轮（2026-09-19）审计与采用值母表；本工作簿的采用值基准 | G12: 全部采用值 | H12: 已提取-继承 | I12: 本研究数据母表；后续取舍先更新此处再同步本工作簿 | J12: SYS-UserPrior | K12: 用户审计工作簿 | L12: 本研究自有 | M12: SPI-Siegrist2026(1).xlsx | N12: CLCA（本研究） | O12: SPI 三模块 | P12: 1 kg SPI | Q12: 已详读
A13: SRC-CLCA-HANDOVER | B13: SPI_CLCA_阶段归档与下轮对话交接.docx | C13: 上一轮交接文档 | D13: §1–§12 | E13: — | F13: 方法锁定（CLCA/FU/三模块）、文件权威性顺序、未决三问题、制图规则 | G13: PS-SPI | H13: 已提取-继承 | I13: 用户决策来源（闸门C条件②③证据） | J13: SYS-UserPrior | K13: 用户交接文档 | L13: 本研究自有 | M13: SRC-CLCA-AUDIT | N13: CLCA | O13: SPI 三模块 | P13: 1 kg SPI | Q13: 已提取
A14: SRC-DRAFT-STRUCT | B14: SPI生产流程与前景LCI结构化描述_草案.docx | C14: 流程结构草案 | D14: §1–§11 | E14: — | F14: 三模块结构、M3 主线/豆渣支线/废水节点、星号规则 | G14: M1/M2/M3 骨架 | H14: 已提取-继承 | I14: 绘图功能输入；不拥有科学数值 | J14: SYS-UserPrior | K14: 用户结构草案 | L14: 本研究自有 | M14: SRC-CLCA-AUDIT | N14: CLCA | O14: SPI 三模块 | P14: 1 kg SPI | Q14: 已提取
A15: SRC-MB | B15: SPI前景清单质量平衡1.xlsx | C15: 上一轮候选质量平衡核算 | D15: 平衡核算/流程清单/核对与缺口 | E15: C4–C54 | F15: 0.88 干基候选核算；结论是原模型全流程质量平衡未通过 | G15: 水系统/质量平衡证据 | H15: 已提取-参考 | I15: 保守候选值来源；与本工作簿采用值分开 | J15: SYS-UserPrior | K15: 用户核算工作簿 | L15: 本研究自有 | M15: SRC-XLS-OLD | N15: CLCA 候选核算 | O15: SPI 三模块 | P15: 1 kg SPI | Q15: 已提取
A16: SRC-LCA-AUDIT-OLD | B16: SPI_LCA前景数据建模_参数审计与选择.xlsx | C16: 更早版本审计母表 | D16: Overview–LCI_Ready_View 8 表 | E16: — | F16: CLCA 审计母表更早版本；被 SRC-CLCA-AUDIT 取代 | G16: — | H16: 参考 | I16: 历史版本 | J16: SYS-UserPrior | K16: 用户审计工作簿（旧） | L16: 本研究自有 | M16: — | N16: — | O16: — | P16: — | Q16: 参考
A18: SRC-RUNTIME | B18: Processing_data.xlsx（ppplca/stubs，GitHub 下载） | C18: 作者代码 runtime 参数/公式文件 | D18: General_parameters/Formulas_SPI | E18: SPI 参数组（33 行） | F18: 作者代码实际读取的参数与公式重构版；本轮已从 github.com/siegarmi/ppplca 下载并复核 | G18: 全部 SPI 参数与公式 | H18: 已提取-复核 | I18: 与上一轮审计结论一致：参数代表值相同；electricity_mix 复算=0.0629995 kWh/kg SPI | J18: SYS-Siegrist2026 | K18: 代码 runtime | L18: 共享来源体系 | M18: ppplca, ecoinvent 3.10, Agrifootprint 6.3 | N18: ALCA 参数化清单 | O18: 五配料 | P18: 各过程 per kg 中间产品 | Q18: 已复核 | R18: 参数选取文献池 | S18: General_parameters＋Formulas_SPI（runtime 口径）

Sheet 模型过程
A1: 模型过程
A2: 以作者实际计算过程为主骨架；设备操作默认写入内部操作说明。
A4: 过程ID | B4: 产品系统 | C4: 功能车间 | D4: 模型过程原名 | E4: 中文名称 | F4: 流程顺序 | G4: 模型粒度 | H4: 内部操作说明 | I4: 主支线角色 | J4: 来源ID | K4: 模型采用状态 | L4: 图中展开方式 | M4: 确认状态 | N4: 备注 | O4: 工艺骨架依据 | P4: 骨架确认决策ID
A5: PS-SPI | B5: SPI 价值链 | C5: - | D5: Soy protein isolation value chain | E5: 大豆分离蛋白价值链 | F5: 1 | G5: 产品系统 | H5: SPI 生产全链；含背景接口（cultivation、运输） | I5: 主线 | J5: SRC-PDF;SRC-VC | K5: 采用 | L5: 顶层总览 | M5: 已确认(2026-09-19) | N5: value_chains 四情景：BR-GB/CN-CN/US-NL/US-US | O5: Siegrist 2026 §2.2 Table 1（SPI 列：cultivation, dehulling, defatting, isoelectric precipitation）+ value_chains.xlsx（SPI 无 milling） | P5: D02
A6: M1 | B6: SPI 价值链 | C6: 预处理 | D6: Cracking and dehulling | E6: 清理、破碎与脱壳 | F6: 1 | G6: 计算过程 | H6: 破碎+脱皮组合操作；不新增独立 cleaning loss/电耗（Q-A01 已裁决） | I6: 主线 | J6: SRC-XLS-OLD | K6: 采用 | L6: 模块框 | M6: 已确认(2026-09-19) | N6: 输出脱皮大豆 2.5212 kg/kg SPI；豆皮共产品 | O6: 同骨架依据 | P6: D02
A7: M2 | B7: SPI 价值链 | C7: 预处理 | D7: Conditioning, flaking and defatting | E7: 大豆脱脂 | F7: 2 | G7: 计算过程 | H7: 调质→压片→溶剂萃取；己烷循环内部化，fresh hexane 为净补充；不并入 degumming | I7: 主线 | J7: SRC-XLS-OLD | K7: 采用 | L7: 模块框（内部工序在覆盖矩阵登记） | M7: 已确认(2026-09-19) | N7: 输出 white flakes 1.9852、豆油 0.4764、废水 0.6251、己烷排放 0.0027 | O7: 同骨架依据；M2 质量差额 0.03 kg/kg 不硬补（Q09） | P7: D02
A8: M3 | B8: SPI 价值链 | C8: 蛋白分离 | D8: Soy protein isolation (isoelectric precipitation) | E8: SPI 蛋白提取 | F8: 3 | G8: 计算过程 | H8: 碱提→一离(豆渣支线:压榨→闪蒸)→等电点沉淀→二离(乳清)→洗涤/三离→喷雾干燥 | I8: 主线 | J8: SRC-XLS-OLD;SRC-CLCA-AUDIT | K8: 采用 | L8: 模块框+一条主线+豆渣支线+水相节点 | M8: 已确认(2026-09-19) | N8: 主产品 SPI 1 kg；spent flakes 0.5449 共产品；水系统审计中（Q03/Q04） | O8: 同骨架依据 | P8: D02

Sheet 模型参数
A1: 模型参数
A2: 分布忠实来自原始数据；图示代表值与不确定性分布分开记录。
A4: 参数ID | B4: 过程ID | C4: 原始参数名 | D4: 中文名称 | E4: 物理意义 | F4: 单位 | G4: 分布类型 | H4: 最小值 | I4: 最大值 | J4: 中位数 | K4: 均值 | L4: 众数 | M4: 固定值 | N4: 图示代表值 | O4: 代表值规则 | P4: 来源ID | Q4: 使用公式/流ID | R4: 状态 | S4: 备注 | T4: 采用候选ID
A5: P01 | B5: M3 | C5: SPI_dm_output | D5: SPI 干物质含量 | E5: 产品规格 | F5: kg/kg | G5: FIXED | M5: 0.95 | N5: =IF(A5="","",IF(G5="FIXED",M5,IF(G5="UNIFORM",IF(AND(ISNUMBER(H5),ISNUMBER(I5)),(H5+I5)/2,""),IF(G5="TRIANGLE",IF(ISNUMBER(L5),L5,IF(ISNUMBER(J5),J5,"")),IF(ISNUMBER(J5),J5,IF(ISNUMBER(K5),K5,"")))))) | O5: =IF(A5="","",IF(G5="FIXED","fixed",IF(G5="UNIFORM","midpoint_median",IF(G5="TRIANGLE",IF(ISNUMBER(L5),"mode",IF(ISNUMBER(J5),"source_median","missing")),IF(ISNUMBER(J5),"source_median",IF(ISNUMBER(K5),"source_mean","missing")))))) | P5: SRC-XLS-OLD | Q5: F19 | R5: 采用 | S5: Deak 2008 | T5: CAD-01
A6: P02 | B6: M3 | C6: SPI_protein_out | D6: SPI 蛋白含量（干基） | E6: 产品规格 | F6: kg/kg DM | G6: TRIANGLE | H6: 0.508 | I6: 0.951 | L6: 0.929 | N6: =IF(A6="","",IF(G6="FIXED",M6,IF(G6="UNIFORM",IF(AND(ISNUMBER(H6),ISNUMBER(I6)),(H6+I6)/2,""),IF(G6="TRIANGLE",IF(ISNUMBER(L6),L6,IF(ISNUMBER(J6),J6,"")),IF(ISNUMBER(J6),J6,IF(ISNUMBER(K6),K6,"")))))) | O6: =IF(A6="","",IF(G6="FIXED","fixed",IF(G6="UNIFORM","midpoint_median",IF(G6="TRIANGLE",IF(ISNUMBER(L6),"mode",IF(ISNUMBER(J6),"source_median","missing")),IF(ISNUMBER(J6),"source_median",IF(ISNUMBER(K6),"source_mean","missing")))))) | P6: SRC-XLS-OLD | Q6: F01;F09 | R6: 采用 | S6: Verfaillie 2023 | T6: CAD-02
A7: P03 | B7: M3 | C7: SPI_protein_recovery | D7: 蛋白回收率 | E7: 提取收率 | F7: kg/kg | G7: TRIANGLE | H7: 0.649 | I7: 0.858 | L7: 0.7535 | N7: =IF(A7="","",IF(G7="FIXED",M7,IF(G7="UNIFORM",IF(AND(ISNUMBER(H7),ISNUMBER(I7)),(H7+I7)/2,""),IF(G7="TRIANGLE",IF(ISNUMBER(L7),L7,IF(ISNUMBER(J7),J7,"")),IF(ISNUMBER(J7),J7,IF(ISNUMBER(K7),K7,"")))))) | O7: =IF(A7="","",IF(G7="FIXED","fixed",IF(G7="UNIFORM","midpoint_median",IF(G7="TRIANGLE",IF(ISNUMBER(L7),"mode",IF(ISNUMBER(J7),"source_median","missing")),IF(ISNUMBER(J7),"source_median",IF(ISNUMBER(K7),"source_mean","missing")))))) | P7: SRC-XLS-OLD | Q7: F01;F09 | R7: 采用 | S7: Brasil 2016（40 个工业值） | T7: CAD-03
A8: P04 | B8: M3 | C8: SPI_protein_in | D8: 白豆片蛋白含量（干基） | E8: 原料规格 | F8: kg/kg DM | G8: TRIANGLE | H8: 0.51 | I8: 0.625 | L8: 0.59 | N8: =IF(A8="","",IF(G8="FIXED",M8,IF(G8="UNIFORM",IF(AND(ISNUMBER(H8),ISNUMBER(I8)),(H8+I8)/2,""),IF(G8="TRIANGLE",IF(ISNUMBER(L8),L8,IF(ISNUMBER(J8),J8,"")),IF(ISNUMBER(J8),J8,IF(ISNUMBER(K8),K8,"")))))) | O8: =IF(A8="","",IF(G8="FIXED","fixed",IF(G8="UNIFORM","midpoint_median",IF(G8="TRIANGLE",IF(ISNUMBER(L8),"mode",IF(ISNUMBER(J8),"source_median","missing")),IF(ISNUMBER(J8),"source_median",IF(ISNUMBER(K8),"source_mean","missing")))))) | P8: SRC-XLS-OLD | Q8: F01;F09 | R8: 采用 | T8: CAD-04
A9: P05 | B9: M3 | C9: SPI_dm_input | D9: 白豆片干物质含量 | E9: 原料规格 | F9: kg/kg | G9: FIXED | M9: 0.88 | N9: =IF(A9="","",IF(G9="FIXED",M9,IF(G9="UNIFORM",IF(AND(ISNUMBER(H9),ISNUMBER(I9)),(H9+I9)/2,""),IF(G9="TRIANGLE",IF(ISNUMBER(L9),L9,IF(ISNUMBER(J9),J9,"")),IF(ISNUMBER(J9),J9,IF(ISNUMBER(K9),K9,"")))))) | O9: =IF(A9="","",IF(G9="FIXED","fixed",IF(G9="UNIFORM","midpoint_median",IF(G9="TRIANGLE",IF(ISNUMBER(L9),"mode",IF(ISNUMBER(J9),"source_median","missing")),IF(ISNUMBER(J9),"source_median",IF(ISNUMBER(K9),"source_mean","missing")))))) | P9: SRC-XLS-OLD | Q9: F01;F21 | R9: 采用 | S9: 与硬编码 0.93 冲突（Q03） | T9: CAD-05
A10: P06 | B10: M3 | C10: SPI_temperature | D10: 浸提升温 | E10: 工艺条件 | F10: °C | G10: TRIANGLE | H10: 28 | I10: 61 | L10: 33 | N10: =IF(A10="","",IF(G10="FIXED",M10,IF(G10="UNIFORM",IF(AND(ISNUMBER(H10),ISNUMBER(I10)),(H10+I10)/2,""),IF(G10="TRIANGLE",IF(ISNUMBER(L10),L10,IF(ISNUMBER(J10),J10,"")),IF(ISNUMBER(J10),J10,IF(ISNUMBER(K10),K10,"")))))) | O10: =IF(A10="","",IF(G10="FIXED","fixed",IF(G10="UNIFORM","midpoint_median",IF(G10="TRIANGLE",IF(ISNUMBER(L10),"mode",IF(ISNUMBER(J10),"source_median","missing")),IF(ISNUMBER(J10),"source_median",IF(ISNUMBER(K10),"source_mean","missing")))))) | P10: SRC-XLS-OLD | Q10: F18 | R10: 采用 | T10: CAD-06
A11: P07 | B11: M3 | C11: SPI_solvent_ratio | D11: 浸提溶剂比 | E11: 工艺条件 | F11: kg/kg | G11: TRIANGLE | H11: 10 | I11: 20 | L11: 10 | N11: =IF(A11="","",IF(G11="FIXED",M11,IF(G11="UNIFORM",IF(AND(ISNUMBER(H11),ISNUMBER(I11)),(H11+I11)/2,""),IF(G11="TRIANGLE",IF(ISNUMBER(L11),L11,IF(ISNUMBER(J11),J11,"")),IF(ISNUMBER(J11),J11,IF(ISNUMBER(K11),K11,"")))))) | O11: =IF(A11="","",IF(G11="FIXED","fixed",IF(G11="UNIFORM","midpoint_median",IF(G11="TRIANGLE",IF(ISNUMBER(L11),"mode",IF(ISNUMBER(J11),"source_median","missing")),IF(ISNUMBER(J11),"source_median",IF(ISNUMBER(K11),"source_mean","missing")))))) | P11: SRC-XLS-OLD | Q11: F13;F21 | R11: 采用 | T11: CAD-07
A12: P08 | B12: M2 | C12: Soy_defatting_input | D12: 脱皮豆/白豆片比 | E12: 上游换算 | F12: kg/kg | G12: TRIANGLE | H12: 1.21 | I12: 1.29 | L12: 1.27 | N12: =IF(A12="","",IF(G12="FIXED",M12,IF(G12="UNIFORM",IF(AND(ISNUMBER(H12),ISNUMBER(I12)),(H12+I12)/2,""),IF(G12="TRIANGLE",IF(ISNUMBER(L12),L12,IF(ISNUMBER(J12),J12,"")),IF(ISNUMBER(J12),J12,IF(ISNUMBER(K12),K12,"")))))) | O12: =IF(A12="","",IF(G12="FIXED","fixed",IF(G12="UNIFORM","midpoint_median",IF(G12="TRIANGLE",IF(ISNUMBER(L12),"mode",IF(ISNUMBER(J12),"source_median","missing")),IF(ISNUMBER(J12),"source_median",IF(ISNUMBER(K12),"source_mean","missing")))))) | P12: SRC-XLS-OLD | Q12: F01;F02 | R12: 采用 | T12: CAD-08
A13: P09 | B13: M2 | C13: Soy_defatting_water | D13: 脱脂工艺水 | E13: 外部输入 | F13: l/kg | G13: TRIANGLE | L13: 0.31486524 | N13: =IF(A13="","",IF(G13="FIXED",M13,IF(G13="UNIFORM",IF(AND(ISNUMBER(H13),ISNUMBER(I13)),(H13+I13)/2,""),IF(G13="TRIANGLE",IF(ISNUMBER(L13),L13,IF(ISNUMBER(J13),J13,"")),IF(ISNUMBER(J13),J13,IF(ISNUMBER(K13),K13,"")))))) | O13: =IF(A13="","",IF(G13="FIXED","fixed",IF(G13="UNIFORM","midpoint_median",IF(G13="TRIANGLE",IF(ISNUMBER(L13),"mode",IF(ISNUMBER(J13),"source_median","missing")),IF(ISNUMBER(J13),"source_median",IF(ISNUMBER(K13),"source_mean","missing")))))) | P13: SRC-XLS-OLD | Q13: F05 | R13: 采用 | S13: min/max 见源表 | T13: CAD-09
A14: P10 | B14: M2 | C14: Soy_defatting_wastewater | D14: 脱脂废水 | E14: 模块输出 | F14: l/kg | G14: TRIANGLE | L14: 0.31486524 | N14: =IF(A14="","",IF(G14="FIXED",M14,IF(G14="UNIFORM",IF(AND(ISNUMBER(H14),ISNUMBER(I14)),(H14+I14)/2,""),IF(G14="TRIANGLE",IF(ISNUMBER(L14),L14,IF(ISNUMBER(J14),J14,"")),IF(ISNUMBER(J14),J14,IF(ISNUMBER(K14),K14,"")))))) | O14: =IF(A14="","",IF(G14="FIXED","fixed",IF(G14="UNIFORM","midpoint_median",IF(G14="TRIANGLE",IF(ISNUMBER(L14),"mode",IF(ISNUMBER(J14),"source_median","missing")),IF(ISNUMBER(J14),"source_median",IF(ISNUMBER(K14),"source_mean","missing")))))) | P14: SRC-XLS-OLD | Q14: F11 | R14: 采用 | T14: CAD-10
A15: P11 | B15: M2 | C15: Soy_defatting_hexane | D15: fresh hexane | E15: 溶剂净补充 | F15: kg/kg | G15: TRIANGLE | L15: 0.0013741007 | N15: =IF(A15="","",IF(G15="FIXED",M15,IF(G15="UNIFORM",IF(AND(ISNUMBER(H15),ISNUMBER(I15)),(H15+I15)/2,""),IF(G15="TRIANGLE",IF(ISNUMBER(L15),L15,IF(ISNUMBER(J15),J15,"")),IF(ISNUMBER(J15),J15,IF(ISNUMBER(K15),K15,"")))))) | O15: =IF(A15="","",IF(G15="FIXED","fixed",IF(G15="UNIFORM","midpoint_median",IF(G15="TRIANGLE",IF(ISNUMBER(L15),"mode",IF(ISNUMBER(J15),"source_median","missing")),IF(ISNUMBER(J15),"source_median",IF(ISNUMBER(K15),"source_mean","missing")))))) | P15: SRC-XLS-OLD | Q15: F06;F12 | R15: 采用 | T15: CAD-11
A16: P12 | B16: M2 | C16: Soy_defatting_electricity | D16: 脱脂电耗 | E16: 模块能耗 | F16: kJ/kg | G16: TRIANGLE | L16: 142.98296 | N16: =IF(A16="","",IF(G16="FIXED",M16,IF(G16="UNIFORM",IF(AND(ISNUMBER(H16),ISNUMBER(I16)),(H16+I16)/2,""),IF(G16="TRIANGLE",IF(ISNUMBER(L16),L16,IF(ISNUMBER(J16),J16,"")),IF(ISNUMBER(J16),J16,IF(ISNUMBER(K16),K16,"")))))) | O16: =IF(A16="","",IF(G16="FIXED","fixed",IF(G16="UNIFORM","midpoint_median",IF(G16="TRIANGLE",IF(ISNUMBER(L16),"mode",IF(ISNUMBER(J16),"source_median","missing")),IF(ISNUMBER(J16),"source_median",IF(ISNUMBER(K16),"source_mean","missing")))))) | P16: SRC-XLS-OLD | Q16: F07 | R16: 采用 | T16: CAD-12
A17: P13 | B17: M2 | C17: Soy_defatting_heat | D17: 脱脂热耗 | E17: 模块能耗 | F17: kJ/kg | G17: TRIANGLE | L17: 951.91796 | N17: =IF(A17="","",IF(G17="FIXED",M17,IF(G17="UNIFORM",IF(AND(ISNUMBER(H17),ISNUMBER(I17)),(H17+I17)/2,""),IF(G17="TRIANGLE",IF(ISNUMBER(L17),L17,IF(ISNUMBER(J17),J17,"")),IF(ISNUMBER(J17),J17,IF(ISNUMBER(K17),K17,"")))))) | O17: =IF(A17="","",IF(G17="FIXED","fixed",IF(G17="UNIFORM","midpoint_median",IF(G17="TRIANGLE",IF(ISNUMBER(L17),"mode",IF(ISNUMBER(J17),"source_median","missing")),IF(ISNUMBER(J17),"source_median",IF(ISNUMBER(K17),"source_mean","missing")))))) | P17: SRC-XLS-OLD | Q17: F08 | R17: 采用 | T17: CAD-13
A18: P14 | B18: M2 | C18: Soy_defatting_oil_production | D18: 豆油产率 | E18: 共产品 | F18: kg/kg | G18: TRIANGLE | H18: 0.191 | I18: 0.26 | L18: 0.24 | N18: =IF(A18="","",IF(G18="FIXED",M18,IF(G18="UNIFORM",IF(AND(ISNUMBER(H18),ISNUMBER(I18)),(H18+I18)/2,""),IF(G18="TRIANGLE",IF(ISNUMBER(L18),L18,IF(ISNUMBER(J18),J18,"")),IF(ISNUMBER(J18),J18,IF(ISNUMBER(K18),K18,"")))))) | O18: =IF(A18="","",IF(G18="FIXED","fixed",IF(G18="UNIFORM","midpoint_median",IF(G18="TRIANGLE",IF(ISNUMBER(L18),"mode",IF(ISNUMBER(J18),"source_median","missing")),IF(ISNUMBER(J18),"source_median",IF(ISNUMBER(K18),"source_mean","missing")))))) | P18: SRC-XLS-OLD | Q18: F10 | R18: 采用 | T18: CAD-14
A19: P15 | B19: M1 | C19: Soy_dehulling_hulls | D19: 豆皮系数 | E19: 共产品 | F19: kg/kg | G19: FIXED | M19: 0.08 | N19: =IF(A19="","",IF(G19="FIXED",M19,IF(G19="UNIFORM",IF(AND(ISNUMBER(H19),ISNUMBER(I19)),(H19+I19)/2,""),IF(G19="TRIANGLE",IF(ISNUMBER(L19),L19,IF(ISNUMBER(J19),J19,"")),IF(ISNUMBER(J19),J19,IF(ISNUMBER(K19),K19,"")))))) | O19: =IF(A19="","",IF(G19="FIXED","fixed",IF(G19="UNIFORM","midpoint_median",IF(G19="TRIANGLE",IF(ISNUMBER(L19),"mode",IF(ISNUMBER(J19),"source_median","missing")),IF(ISNUMBER(J19),"source_median",IF(ISNUMBER(K19),"source_mean","missing")))))) | P19: SRC-XLS-OLD | Q19: F03 | R19: 采用 | T19: CAD-15
A20: P16 | B20: M1 | C20: Soy_dehulling_electricity | D20: 脱皮电耗 | E20: 模块能耗 | F20: kJ/kg | G20: TRIANGLE | H20: 5 | I20: 30 | L20: 23.4 | N20: =IF(A20="","",IF(G20="FIXED",M20,IF(G20="UNIFORM",IF(AND(ISNUMBER(H20),ISNUMBER(I20)),(H20+I20)/2,""),IF(G20="TRIANGLE",IF(ISNUMBER(L20),L20,IF(ISNUMBER(J20),J20,"")),IF(ISNUMBER(J20),J20,IF(ISNUMBER(K20),K20,"")))))) | O20: =IF(A20="","",IF(G20="FIXED","fixed",IF(G20="UNIFORM","midpoint_median",IF(G20="TRIANGLE",IF(ISNUMBER(L20),"mode",IF(ISNUMBER(J20),"source_median","missing")),IF(ISNUMBER(J20),"source_median",IF(ISNUMBER(K20),"source_mean","missing")))))) | P20: SRC-XLS-OLD | Q20: F04 | R20: 采用 | T20: CAD-16
A21: P17 | B21: M3 | C21: Electricity_centrifugal_decanter | D21: 离心单位电耗 | E21: 设备参数 | F21: MJ/m3 | G21: TRIANGLE | H21: 1.08 | I21: 3.744 | L21: 3.42 | N21: =IF(A21="","",IF(G21="FIXED",M21,IF(G21="UNIFORM",IF(AND(ISNUMBER(H21),ISNUMBER(I21)),(H21+I21)/2,""),IF(G21="TRIANGLE",IF(ISNUMBER(L21),L21,IF(ISNUMBER(J21),J21,"")),IF(ISNUMBER(J21),J21,IF(ISNUMBER(K21),K21,"")))))) | O21: =IF(A21="","",IF(G21="FIXED","fixed",IF(G21="UNIFORM","midpoint_median",IF(G21="TRIANGLE",IF(ISNUMBER(L21),"mode",IF(ISNUMBER(J21),"source_median","missing")),IF(ISNUMBER(J21),"source_median",IF(ISNUMBER(K21),"source_mean","missing")))))) | P21: SRC-XLS-OLD | Q21: F17 | R21: 采用 | T21: CAD-17
A22: P18 | B22: M3 | C22: Electricity_pressing | D22: 压榨单位电耗 | E22: 设备参数 | F22: kJ/kg | G22: UNIFORM | H22: 0.39 | I22: 1.89 | N22: =IF(A22="","",IF(G22="FIXED",M22,IF(G22="UNIFORM",IF(AND(ISNUMBER(H22),ISNUMBER(I22)),(H22+I22)/2,""),IF(G22="TRIANGLE",IF(ISNUMBER(L22),L22,IF(ISNUMBER(J22),J22,"")),IF(ISNUMBER(J22),J22,IF(ISNUMBER(K22),K22,"")))))) | O22: =IF(A22="","",IF(G22="FIXED","fixed",IF(G22="UNIFORM","midpoint_median",IF(G22="TRIANGLE",IF(ISNUMBER(L22),"mode",IF(ISNUMBER(J22),"source_median","missing")),IF(ISNUMBER(J22),"source_median",IF(ISNUMBER(K22),"source_mean","missing")))))) | P22: SRC-XLS-OLD | Q22: F17 | R22: 采用 | T22: CAD-18
A23: P19 | B23: M3 | C23: Electricity_pumping | D23: 泵送附加比例 | E23: 设备参数 | F23: fraction | G23: TRIANGLE | H23: 0.09 | I23: 0.164 | L23: 0.15 | N23: =IF(A23="","",IF(G23="FIXED",M23,IF(G23="UNIFORM",IF(AND(ISNUMBER(H23),ISNUMBER(I23)),(H23+I23)/2,""),IF(G23="TRIANGLE",IF(ISNUMBER(L23),L23,IF(ISNUMBER(J23),J23,"")),IF(ISNUMBER(J23),J23,IF(ISNUMBER(K23),K23,"")))))) | O23: =IF(A23="","",IF(G23="FIXED","fixed",IF(G23="UNIFORM","midpoint_median",IF(G23="TRIANGLE",IF(ISNUMBER(L23),"mode",IF(ISNUMBER(J23),"source_median","missing")),IF(ISNUMBER(J23),"source_median",IF(ISNUMBER(K23),"source_mean","missing")))))) | P23: SRC-XLS-OLD | Q23: F17 | R23: 采用 | S23: 按 15% 使用 | T23: CAD-19
A24: P20 | B24: M3 | C24: Heat_flash_drier | D24: 闪蒸单位热耗 | E24: 设备参数 | F24: kJ/kg 蒸发水 | G24: TRIANGLE | H24: 3600 | I24: 5040 | L24: 3600 | N24: =IF(A24="","",IF(G24="FIXED",M24,IF(G24="UNIFORM",IF(AND(ISNUMBER(H24),ISNUMBER(I24)),(H24+I24)/2,""),IF(G24="TRIANGLE",IF(ISNUMBER(L24),L24,IF(ISNUMBER(J24),J24,"")),IF(ISNUMBER(J24),J24,IF(ISNUMBER(K24),K24,"")))))) | O24: =IF(A24="","",IF(G24="FIXED","fixed",IF(G24="UNIFORM","midpoint_median",IF(G24="TRIANGLE",IF(ISNUMBER(L24),"mode",IF(ISNUMBER(J24),"source_median","missing")),IF(ISNUMBER(J24),"source_median",IF(ISNUMBER(K24),"source_mean","missing")))))) | P24: SRC-XLS-OLD | Q24: F18 | R24: 采用 | T24: CAD-20
A25: P21 | B25: M3 | C25: Heat_spray_drier | D25: 喷雾单位热耗 | E25: 设备参数 | F25: kJ/kg 蒸发水 | G25: UNIFORM | H25: 3268 | I25: 6333 | N25: =IF(A25="","",IF(G25="FIXED",M25,IF(G25="UNIFORM",IF(AND(ISNUMBER(H25),ISNUMBER(I25)),(H25+I25)/2,""),IF(G25="TRIANGLE",IF(ISNUMBER(L25),L25,IF(ISNUMBER(J25),J25,"")),IF(ISNUMBER(J25),J25,IF(ISNUMBER(K25),K25,"")))))) | O25: =IF(A25="","",IF(G25="FIXED","fixed",IF(G25="UNIFORM","midpoint_median",IF(G25="TRIANGLE",IF(ISNUMBER(L25),"mode",IF(ISNUMBER(J25),"source_median","missing")),IF(ISNUMBER(J25),"source_median",IF(ISNUMBER(K25),"source_mean","missing")))))) | P25: SRC-XLS-OLD | Q25: F18 | R25: 采用 | T25: CAD-21
A26: P22 | B26: M3 | C26: dm_content_spray_drier | D26: 喷雾进料干物质 | E26: 工艺条件 | F26: kg/kg | G26: TRIANGLE | H26: 0.12 | I26: 0.2 | L26: 0.16 | N26: =IF(A26="","",IF(G26="FIXED",M26,IF(G26="UNIFORM",IF(AND(ISNUMBER(H26),ISNUMBER(I26)),(H26+I26)/2,""),IF(G26="TRIANGLE",IF(ISNUMBER(L26),L26,IF(ISNUMBER(J26),J26,"")),IF(ISNUMBER(J26),J26,IF(ISNUMBER(K26),K26,"")))))) | O26: =IF(A26="","",IF(G26="FIXED","fixed",IF(G26="UNIFORM","midpoint_median",IF(G26="TRIANGLE",IF(ISNUMBER(L26),"mode",IF(ISNUMBER(J26),"source_median","missing")),IF(ISNUMBER(J26),"source_median",IF(ISNUMBER(K26),"source_mean","missing")))))) | P26: SRC-XLS-OLD | Q26: F18;F22 | R26: 采用 | T26: CAD-22
A27: P23 | B27: M3 | C27: SPI_mass_flow_factors | D27: 质量流因子组 | E27: 公式输入 | F27: kg/kg | G27: FIXED | M27: 1.0625 | N27: =IF(A27="","",IF(G27="FIXED",M27,IF(G27="UNIFORM",IF(AND(ISNUMBER(H27),ISNUMBER(I27)),(H27+I27)/2,""),IF(G27="TRIANGLE",IF(ISNUMBER(L27),L27,IF(ISNUMBER(J27),J27,"")),IF(ISNUMBER(J27),J27,IF(ISNUMBER(K27),K27,"")))))) | O27: =IF(A27="","",IF(G27="FIXED","fixed",IF(G27="UNIFORM","midpoint_median",IF(G27="TRIANGLE",IF(ISNUMBER(L27),"mode",IF(ISNUMBER(J27),"source_median","missing")),IF(ISNUMBER(J27),"source_median",IF(ISNUMBER(K27),"source_mean","missing")))))) | P27: SRC-XLS-OLD | Q27: F17;F18;F21 | R27: 采用 | S27: 多值组，见 CAD-27；含 0.93 链（Q03） | T27: CAD-27
A28: P24 | B28: M3 | C28: SPI_spent_flakes | D28: 豆渣系数 | E28: 共产品 | F28: kg/kg 白豆片 | G28: FIXED | M28: 0.27450158 | N28: =IF(A28="","",IF(G28="FIXED",M28,IF(G28="UNIFORM",IF(AND(ISNUMBER(H28),ISNUMBER(I28)),(H28+I28)/2,""),IF(G28="TRIANGLE",IF(ISNUMBER(L28),L28,IF(ISNUMBER(J28),J28,"")),IF(ISNUMBER(J28),J28,IF(ISNUMBER(K28),K28,"")))))) | O28: =IF(A28="","",IF(G28="FIXED","fixed",IF(G28="UNIFORM","midpoint_median",IF(G28="TRIANGLE",IF(ISNUMBER(L28),"mode",IF(ISNUMBER(J28),"source_median","missing")),IF(ISNUMBER(J28),"source_median",IF(ISNUMBER(K28),"source_mean","missing")))))) | P28: SRC-XLS-OLD | Q28: F20 | R28: 采用 | T28: CAD-23
A29: P25 | B29: M3 | C29: SPI_whey | D29: whey 系数 | E29: 水相输出 | F29: kg/kg 白豆片 | G29: FIXED | M29: 0.57879302 | N29: =IF(A29="","",IF(G29="FIXED",M29,IF(G29="UNIFORM",IF(AND(ISNUMBER(H29),ISNUMBER(I29)),(H29+I29)/2,""),IF(G29="TRIANGLE",IF(ISNUMBER(L29),L29,IF(ISNUMBER(J29),J29,"")),IF(ISNUMBER(J29),J29,IF(ISNUMBER(K29),K29,"")))))) | O29: =IF(A29="","",IF(G29="FIXED","fixed",IF(G29="UNIFORM","midpoint_median",IF(G29="TRIANGLE",IF(ISNUMBER(L29),"mode",IF(ISNUMBER(J29),"source_median","missing")),IF(ISNUMBER(J29),"source_median",IF(ISNUMBER(K29),"source_mean","missing")))))) | P29: SRC-XLS-OLD | Q29: F21 | R29: 采用 | S29: 含 0.93 链（Q03） | T29: CAD-24
A30: P26 | B30: M3 | C30: SPI_NaOH_input | D30: NaOH(50%) 体积系数 | E30: 化学品 | F30: l/kg 溶剂 | G30: FIXED | M30: 0.00125 | N30: =IF(A30="","",IF(G30="FIXED",M30,IF(G30="UNIFORM",IF(AND(ISNUMBER(H30),ISNUMBER(I30)),(H30+I30)/2,""),IF(G30="TRIANGLE",IF(ISNUMBER(L30),L30,IF(ISNUMBER(J30),J30,"")),IF(ISNUMBER(J30),J30,IF(ISNUMBER(K30),K30,"")))))) | O30: =IF(A30="","",IF(G30="FIXED","fixed",IF(G30="UNIFORM","midpoint_median",IF(G30="TRIANGLE",IF(ISNUMBER(L30),"mode",IF(ISNUMBER(J30),"source_median","missing")),IF(ISNUMBER(J30),"source_median",IF(ISNUMBER(K30),"source_mean","missing")))))) | P30: SRC-XLS-OLD | Q30: F15 | R30: 采用 | S30: 最终 kg 映射待核（Q05） | T30: CAD-25
A31: P27 | B31: M3 | C31: SPI_HCl_input | D31: HCl(30%) 体积系数 | E31: 化学品 | F31: l/kg 溶剂 | G31: FIXED | M31: 0.0029166667 | N31: =IF(A31="","",IF(G31="FIXED",M31,IF(G31="UNIFORM",IF(AND(ISNUMBER(H31),ISNUMBER(I31)),(H31+I31)/2,""),IF(G31="TRIANGLE",IF(ISNUMBER(L31),L31,IF(ISNUMBER(J31),J31,"")),IF(ISNUMBER(J31),J31,IF(ISNUMBER(K31),K31,"")))))) | O31: =IF(A31="","",IF(G31="FIXED","fixed",IF(G31="UNIFORM","midpoint_median",IF(G31="TRIANGLE",IF(ISNUMBER(L31),"mode",IF(ISNUMBER(J31),"source_median","missing")),IF(ISNUMBER(J31),"source_median",IF(ISNUMBER(K31),"source_mean","missing")))))) | P31: SRC-XLS-OLD | Q31: F16 | R31: 采用 | S31: 最终 kg 映射待核（Q05） | T31: CAD-26
A32: P28 | B32: M3 | C32: SPI_density_factors | D32: 密度因子组 | E32: 公式输入 | F32: kg/L | G32: FIXED | M32: 1.0378 | N32: =IF(A32="","",IF(G32="FIXED",M32,IF(G32="UNIFORM",IF(AND(ISNUMBER(H32),ISNUMBER(I32)),(H32+I32)/2,""),IF(G32="TRIANGLE",IF(ISNUMBER(L32),L32,IF(ISNUMBER(J32),J32,"")),IF(ISNUMBER(J32),J32,IF(ISNUMBER(K32),K32,"")))))) | O32: =IF(A32="","",IF(G32="FIXED","fixed",IF(G32="UNIFORM","midpoint_median",IF(G32="TRIANGLE",IF(ISNUMBER(L32),"mode",IF(ISNUMBER(J32),"source_median","missing")),IF(ISNUMBER(J32),"source_median",IF(ISNUMBER(K32),"source_mean","missing")))))) | P32: SRC-XLS-OLD | Q32: F17 | R32: 采用 | S32: 多值组，见 CAD-28；含 0.93 链（Q03） | T32: CAD-28
A33: P29 | B33: M3 | C33: SPI_module_electricity | D33: SPI 模块总电力 | E33: 模块能耗 | F33: kWh/kg SPI | G33: FIXED | M33: 0.062999518 | N33: =IF(A33="","",IF(G33="FIXED",M33,IF(G33="UNIFORM",IF(AND(ISNUMBER(H33),ISNUMBER(I33)),(H33+I33)/2,""),IF(G33="TRIANGLE",IF(ISNUMBER(L33),L33,IF(ISNUMBER(J33),J33,"")),IF(ISNUMBER(J33),J33,IF(ISNUMBER(K33),K33,"")))))) | O33: =IF(A33="","",IF(G33="FIXED","fixed",IF(G33="UNIFORM","midpoint_median",IF(G33="TRIANGLE",IF(ISNUMBER(L33),"mode",IF(ISNUMBER(J33),"source_median","missing")),IF(ISNUMBER(J33),"source_median",IF(ISNUMBER(K33),"source_mean","missing")))))) | P33: SRC-CLCA-AUDIT | Q33: F17 | R33: 采用 | S33: 当前版/runtime 值（Q01） | T33: CAD-29
A34: P30 | B34: M3 | C34: SPI_module_heat | D34: SPI 模块总热量 | E34: 模块能耗 | F34: MJ/kg SPI | G34: FIXED | M34: 27.500833 | N34: =IF(A34="","",IF(G34="FIXED",M34,IF(G34="UNIFORM",IF(AND(ISNUMBER(H34),ISNUMBER(I34)),(H34+I34)/2,""),IF(G34="TRIANGLE",IF(ISNUMBER(L34),L34,IF(ISNUMBER(J34),J34,"")),IF(ISNUMBER(J34),J34,IF(ISNUMBER(K34),K34,"")))))) | O34: =IF(A34="","",IF(G34="FIXED","fixed",IF(G34="UNIFORM","midpoint_median",IF(G34="TRIANGLE",IF(ISNUMBER(L34),"mode",IF(ISNUMBER(J34),"source_median","missing")),IF(ISNUMBER(J34),"source_median",IF(ISNUMBER(K34),"source_mean","missing")))))) | P34: SRC-XLS-OLD | Q34: F18 | R34: 采用 | T34: CAD-31
N35: =IF(A35="","",IF(G35="FIXED",M35,IF(G35="UNIFORM",IF(AND(ISNUMBER(H35),ISNUMBER(I35)),(H35+I35)/2,""),IF(G35="TRIANGLE",IF(ISNUMBER(L35),L35,IF(ISNUMBER(J35),J35,"")),IF(ISNUMBER(J35),J35,IF(ISNUMBER(K35),K35,"")))))) | O35: =IF(A35="","",IF(G35="FIXED","fixed",IF(G35="UNIFORM","midpoint_median",IF(G35="TRIANGLE",IF(ISNUMBER(L35),"mode",IF(ISNUMBER(J35),"source_median","missing")),IF(ISNUMBER(J35),"source_median",IF(ISNUMBER(K35),"source_mean","missing"))))))
N36: =IF(A36="","",IF(G36="FIXED",M36,IF(G36="UNIFORM",IF(AND(ISNUMBER(H36),ISNUMBER(I36)),(H36+I36)/2,""),IF(G36="TRIANGLE",IF(ISNUMBER(L36),L36,IF(ISNUMBER(J36),J36,"")),IF(ISNUMBER(J36),J36,IF(ISNUMBER(K36),K36,"")))))) | O36: =IF(A36="","",IF(G36="FIXED","fixed",IF(G36="UNIFORM","midpoint_median",IF(G36="TRIANGLE",IF(ISNUMBER(L36),"mode",IF(ISNUMBER(J36),"source_median","missing")),IF(ISNUMBER(J36),"source_median",IF(ISNUMBER(K36),"source_mean","missing"))))))
N37: =IF(A37="","",IF(G37="FIXED",M37,IF(G37="UNIFORM",IF(AND(ISNUMBER(H37),ISNUMBER(I37)),(H37+I37)/2,""),IF(G37="TRIANGLE",IF(ISNUMBER(L37),L37,IF(ISNUMBER(J37),J37,"")),IF(ISNUMBER(J37),J37,IF(ISNUMBER(K37),K37,"")))))) | O37: =IF(A37="","",IF(G37="FIXED","fixed",IF(G37="UNIFORM","midpoint_median",IF(G37="TRIANGLE",IF(ISNUMBER(L37),"mode",IF(ISNUMBER(J37),"source_median","missing")),IF(ISNUMBER(J37),"source_median",IF(ISNUMBER(K37),"source_mean","missing"))))))
N38: =IF(A38="","",IF(G38="FIXED",M38,IF(G38="UNIFORM",IF(AND(ISNUMBER(H38),ISNUMBER(I38)),(H38+I38)/2,""),IF(G38="TRIANGLE",IF(ISNUMBER(L38),L38,IF(ISNUMBER(J38),J38,"")),IF(ISNUMBER(J38),J38,IF(ISNUMBER(K38),K38,"")))))) | O38: =IF(A38="","",IF(G38="FIXED","fixed",IF(G38="UNIFORM","midpoint_median",IF(G38="TRIANGLE",IF(ISNUMBER(L38),"mode",IF(ISNUMBER(J38),"source_median","missing")),IF(ISNUMBER(J38),"source_median",IF(ISNUMBER(K38),"source_mean","missing"))))))
N39: =IF(A39="","",IF(G39="FIXED",M39,IF(G39="UNIFORM",IF(AND(ISNUMBER(H39),ISNUMBER(I39)),(H39+I39)/2,""),IF(G39="TRIANGLE",IF(ISNUMBER(L39),L39,IF(ISNUMBER(J39),J39,"")),IF(ISNUMBER(J39),J39,IF(ISNUMBER(K39),K39,"")))))) | O39: =IF(A39="","",IF(G39="FIXED","fixed",IF(G39="UNIFORM","midpoint_median",IF(G39="TRIANGLE",IF(ISNUMBER(L39),"mode",IF(ISNUMBER(J39),"source_median","missing")),IF(ISNUMBER(J39),"source_median",IF(ISNUMBER(K39),"source_mean","missing"))))))
N40: =IF(A40="","",IF(G40="FIXED",M40,IF(G40="UNIFORM",IF(AND(ISNUMBER(H40),ISNUMBER(I40)),(H40+I40)/2,""),IF(G40="TRIANGLE",IF(ISNUMBER(L40),L40,IF(ISNUMBER(J40),J40,"")),IF(ISNUMBER(J40),J40,IF(ISNUMBER(K40),K40,"")))))) | O40: =IF(A40="","",IF(G40="FIXED","fixed",IF(G40="UNIFORM","midpoint_median",IF(G40="TRIANGLE",IF(ISNUMBER(L40),"mode",IF(ISNUMBER(J40),"source_median","missing")),IF(ISNUMBER(J40),"source_median",IF(ISNUMBER(K40),"source_mean","missing"))))))
N41: =IF(A41="","",IF(G41="FIXED",M41,IF(G41="UNIFORM",IF(AND(ISNUMBER(H41),ISNUMBER(I41)),(H41+I41)/2,""),IF(G41="TRIANGLE",IF(ISNUMBER(L41),L41,IF(ISNUMBER(J41),J41,"")),IF(ISNUMBER(J41),J41,IF(ISNUMBER(K41),K41,"")))))) | O41: =IF(A41="","",IF(G41="FIXED","fixed",IF(G41="UNIFORM","midpoint_median",IF(G41="TRIANGLE",IF(ISNUMBER(L41),"mode",IF(ISNUMBER(J41),"source_median","missing")),IF(ISNUMBER(J41),"source_median",IF(ISNUMBER(K41),"source_mean","missing"))))))
...

Sheet 模型流与公式
A1: 模型流与公式
A2: 一行一个模型流；物理流、环境交换、分配负担和替代候选必须区分。
A4: 流ID | B4: 过程ID | C4: 流名称 | D4: 流类别 | E4: 方向 | F4: 来源过程ID | G4: 目标过程ID | H4: 值类型 | I4: 原始登记值 | J4: 原始单位 | K4: 参考基准 | L4: 公式ID | M4: 来源公式 | N4: 采用公式 | O4: 输入参数ID | P4: 图示代表值 | Q4: 采用单位 | R4: 符号约定 | S4: 是否内部流 | T4: 方法采用状态 | U4: 来源ID | V4: 审查状态 | W4: 是否显示 | X4: 显示标签 | Y4: 备注 | Z4: 采用候选ID | AA4: 数值生成方式 | AB4: 原始计量基准 | AC4: 采用计量基准
A5: F01 | B5: M1 | C5: 大豆原料/干燥大豆 | D5: 物理流 | E5: 输入 | G5: M1 | H5: physical_material | I5: 2.722899 | J5: kg | K5: 1 kg SPI | L5: EQ-WF | M5: white flakes×1.27×1.08 | N5: WF=(P01×P02/P03/P04)×P08×(1+P15) | O5: P01;P02;P03;P04;P08;P15 | P5: 2.722899 | Q5: kg | R5: + | S5: 否 | T5: CLCA不分配-上游物理输入 | U5: SRC-CLCA-AUDIT | V5: PASS | W5: 是 | X5: 原始大豆 2.7229 kg | Y5: 逐级反推（(1)版/runtime 口径） | AA5: 公式派生 | AB5: kg/kg 白豆片 | AC5: kg/kg SPI
A6: F02 | B6: M1 | C6: 脱皮大豆 | D6: 物理流 | E6: 输出 | F6: M1 | G6: M2 | H6: physical_material | I6: 2.521203 | J6: kg | K6: 1 kg SPI | L6: EQ-WF | M6: WF×P08 | N6: WF=(P01×P02/P03/P04)×P08 | O6: P01;P02;P03;P04;P08 | P6: 2.521203 | Q6: kg | R6: + | S6: 是 | T6: CLCA不分配-内部主物流 | U6: SRC-CLCA-AUDIT | V6: PASS | W6: 是 | X6: 去壳大豆 2.5212 kg | Y6: 跨模块只出现一次 | AA6: 公式派生 | AB6: kg/kg SPI | AC6: kg/kg SPI
A7: F03 | B7: M1 | C7: 豆皮 hulls | D7: 物理流 | E7: 输出 | F7: M1 | H7: physical_material | I7: 0.201696 | J7: kg | K7: 1 kg SPI | L7: EQ-HULLS | M7: WF×P08×P15 | N7: hulls=WF×1.27×0.08 | O7: P01;P02;P03;P04;P08;P15 | P7: 0.201696 | Q7: kg | R7: + | S7: 否 | T7: 共产品显式保留-替代接口未定义 | U7: SRC-XLS-OLD | V7: PASS | W7: 是 | X7: 豆壳 0.2017 kg | AA7: 公式派生 | AB7: kg/kg 脱皮大豆 | AC7: kg/kg SPI
A8: F04 | B8: M1 | C8: 电力 | D8: 能源 | E8: 输入 | G8: M1 | H8: physical_energy | I8: 0.016388 | J8: kWh | K8: 1 kg SPI | L8: EQ-E1 | M8: 脱皮豆×23.4/3600 | N8: E1=WF×P08×P16/3600 | O8: P16 | P8: 0.016387818 | Q8: kWh | R8: + | S8: 否 | T8: CLCA不分配-模块总量 | U8: SRC-XLS-OLD | V8: PASS | W8: 是 | X8: 电力 0.01639 kWh | AA8: 公式派生 | AB8: kJ/kg 脱皮大豆 | AC8: kWh/kg SPI
A9: F05 | B9: M2 | C9: 工艺水 | D9: 物理流 | E9: 输入 | G9: M2 | H9: physical_material | I9: 0.62507 | J9: kg≈L | K9: 1 kg SPI | L9: EQ-W2 | M9: WF×P09 | N9: W2=WF×P09 | O9: P09 | P9: 0.62507 | Q9: kg | R9: + | S9: 否 | T9: CLCA不分配-模块代表值 | U9: SRC-XLS-OLD | V9: PASS_WITH_NOTE | W9: 是 | X9: 工艺水 0.6251 kg | Y9: 原模型代表值，不宣称严格水平衡（Q10 水口径） | AA9: 公式派生 | AB9: l/kg 白豆片 | AC9: kg/kg SPI
A10: F06 | B10: M2 | C10: fresh hexane | D10: 物理流 | E10: 输入 | G10: M2 | H10: physical_material | I10: 0.002728 | J10: kg | K10: 1 kg SPI | L10: EQ-HEX | M10: WF×P11 | N10: hex=WF×P11 | O10: P11 | P10: 0.002728 | Q10: kg | R10: + | S10: 否 | T10: CLCA不分配-净补充量 | U10: SRC-XLS-OLD | V10: PASS_WITH_NOTE | W10: 是 | X10: 新鲜正己烷 0.002728 kg | Y10: 内部循环不作为外部输入；compartment 待映射（Q06） | AA10: 公式派生 | AB10: kg/kg 白豆片 | AC10: kg/kg SPI
A11: F07 | B11: M2 | C11: 电力 | D11: 能源 | E11: 输入 | G11: M2 | H11: physical_energy | I11: 0.078847 | J11: kWh | K11: 1 kg SPI | L11: EQ-E2 | M11: WF×P12/3600 | N11: E2=WF×P12/3600 | O11: P12 | P11: 0.078847119 | Q11: kWh | R11: + | S11: 否 | T11: CLCA不分配-模块总量 | U11: SRC-XLS-OLD | V11: PASS | W11: 是 | X11: 电力 0.07885 kWh | Y11: 模块总值，不拆到工序（Sheehan 占比仅解释） | AA11: 公式派生 | AB11: kJ/kg 白豆片 | AC11: kWh/kg SPI
A12: F08 | B12: M2 | C12: 热量 | D12: 能源 | E12: 输入 | G12: M2 | H12: physical_energy | I12: 1.889747 | J12: MJ | K12: 1 kg SPI | L12: EQ-H2 | M12: WF×P13/1000 | N12: H2=WF×P13/1000 | O12: P13 | P12: 1.8897466 | Q12: MJ | R12: + | S12: 否 | T12: CLCA不分配-模块总量 | U12: SRC-XLS-OLD | V12: PASS | W12: 是 | X12: 热 1.88975 MJ | AA12: 公式派生 | AB12: kJ/kg 白豆片 | AC12: MJ/kg SPI
A13: F09 | B13: M2 | C13: white flakes | D13: 物理流 | E13: 输出 | F13: M2 | G13: M3 | H13: physical_material | I13: 1.985199 | J13: kg | K13: 1 kg SPI | L13: EQ-WF | M13: 0.95×0.929/(0.7535×0.59) | N13: WF=P01×P02/P03/P04 | O13: P01;P02;P03;P04 | P13: 1.985199 | Q13: kg | R13: + | S13: 是 | T13: CLCA不分配-内部主物流 | U13: SRC-XLS-OLD | V13: PASS | W13: 是 | X13: 白豆片 1.9852 kg | Y13: 跨模块只出现一次 | AA13: 公式派生 | AB13: kg/kg SPI | AC13: kg/kg SPI
A14: F10 | B14: M2 | C14: 豆油 | D14: 物理流 | E14: 输出 | F14: M2 | H14: physical_material | I14: 0.476448 | J14: kg | K14: 1 kg SPI | L14: EQ-OIL | M14: WF×P14 | N14: oil=WF×P14 | O14: P14 | P14: 0.476448 | Q14: kg | R14: + | S14: 否 | T14: 共产品显式保留-替代接口未定义 | U14: SRC-XLS-OLD | V14: PASS | W14: 是 | X14: 豆油 0.4764 kg | AA14: 公式派生 | AB14: kg/kg 白豆片 | AC14: kg/kg SPI
A15: F11 | B15: M2 | C15: 废水 | D15: 物理流 | E15: 输出 | F15: M2 | H15: physical_material | I15: 0.62507 | J15: kg≈L | K15: 1 kg SPI | L15: EQ-WW2 | M15: WF×P10 | N15: ww=WF×P10 | O15: P10 | P15: 0.62507 | Q15: kg | R15: + | S15: 否 | T15: CLCA不分配-模块代表值 | U15: SRC-XLS-OLD | V15: PASS_WITH_NOTE | W15: 是 | X15: 工艺废水 0.6251 kg | Y15: 与水输入同值，模块代表值 | AA15: 公式派生 | AB15: l/kg 白豆片 | AC15: kg/kg SPI
A16: F12 | B16: M2 | C16: 己烷排放 | D16: 环境排放 | E16: 输出 | F16: M2 | H16: environment_exchange | I16: 0.002728 | J16: kg | K16: 1 kg SPI | L16: EQ-HEM | M16: WF×P11 | N16: hem=WF×P11（输入=损失假设） | O16: P11 | P16: 0.002728 | Q16: kg | R16: +（源公式 wastewater 用 -1 为软件约定） | S16: 否 | T16: CLCA不分配-排放 | U16: SRC-XLS-OLD | V16: PASS_WITH_NOTE | W16: 是 | X16: 正己烷排放 0.002728 kg | Y16: 排放介质待数据库映射（Q06） | AA16: 公式派生 | AB16: kg/kg 白豆片 | AC16: kg/kg SPI
A17: F13 | B17: M3 | C17: 浸提步骤加水 | D17: 物理流 | E17: 输入 | G17: M3 | H17: physical_material | I17: 19.85199 | J17: kg | K17: 1 kg SPI | L17: EQ-W3 | M17: WF×P07 | N17: W3=WF×P07 | O17: P07 | P17: 19.85199 | Q17: kg | R17: + | S17: 是（步骤） | T17: 步骤加水-非最终 external exchange | U17: SRC-XLS-OLD | V17: PASS_WITH_NOTE | W17: 否 | X17: （工艺投水，不进 LCI 图面） | Y17: 步骤需求；不等于外部新鲜水（Q04）；2026-09-27 图面按 LCA 边界口径改为外部取水 16.98 显示，工艺投水撤出图面 | AA17: 直接报告 | AB17: kg/kg 白豆片 | AC17: kg/kg SPI
A18: F14 | B18: M3 | C18: 蛋白洗涤步骤加水 | D18: 物理流 | E18: 输入 | G18: M3 | H18: physical_material | I18: 6 | J18: kg | K18: 1 kg SPI | L18: EQ-W4 | M18: 6 kg/kg SPI | N18: W4=6 | O18: 常量（W4=6 直接报告） | P18: 6 | Q18: kg | R18: + | S18: 是（步骤） | T18: 步骤加水-非最终 external exchange | U18: SRC-XLS-OLD | V18: PASS_WITH_NOTE | W18: 否 | X18: （工艺投水，不进 LCI 图面） | Y18: 6 kg/kg SPI；源参数注释"6 kg water for protein wash"＋蛋白离心进料公式含+6 → 属离心4蛋白洗涤，非离心2豆片洗涤（2026-09-27 修正）；2026-09-27 图面按 LCA 边界口径改为外部取水 16.98 显示，工艺投水撤出图面 | AA18: 直接报告 | AB18: kg/kg SPI | AC18: kg/kg SPI
A19: F15 | B19: M3 | C19: NaOH 10% 溶液 | D19: 物理流 | E19: 输入 | G19: M3 | H19: physical_material | I19: 0.124075 | J19: L | K19: 1 kg SPI | L19: EQ-NAOH | M19: WF×P26×P07×5 | N19: NaOH10%=WF×0.00125×10×5 | O19: P26;P07 | P19: 0.124075 | Q19: L | R19: + | S19: 否 | T19: 化学品-最终 kg 映射待核 | U19: SRC-XLS-OLD | V19: REVIEW | W19: 是 | X19: NaOH 10% 溶液 0.1241 L* | Y19: 由 50% 体积×5 折算 10%；密度/浓度链不完整（Q05） | AA19: 公式派生 | AB19: l/kg 溶剂 | AC19: L/kg SPI
A20: F16 | B20: M3 | C20: HCl 10% 溶液 | D20: 物理流 | E20: 输入 | G20: M3 | H20: physical_material | I20: 0.173705 | J20: L | K20: 1 kg SPI | L20: EQ-HCL | M20: WF×P27×P07×3 | N20: HCl10%=WF×0.0029167×10×3 | O20: P27;P07 | P20: 0.173705 | Q20: L | R20: + | S20: 否 | T20: 化学品-最终 kg 映射待核 | U20: SRC-XLS-OLD | V20: REVIEW | W20: 是 | X20: HCl 10% 溶液 0.1737 L* | Y20: 由 30% 体积×3 折算 10%（Q05） | AA20: 公式派生 | AB20: l/kg 溶剂 | AC20: L/kg SPI
A21: F17 | B21: M3 | C21: 电力 | D21: 能源 | E21: 输入 | G21: M3 | H21: physical_energy | I21: 0.0629995 | J21: kWh | K21: 1 kg SPI | L21: EQ-E3 | M21: Formulas_SPI electricity_mix / SPI!I48(当前版) | N21: 采用值 0.0629995（当前版/runtime） | P21: 0.062999518 | Q21: kWh | R21: + | S21: 否 | T21: CLCA不分配-模块总量 | U21: SRC-CLCA-AUDIT | V21: PASS_WITH_NOTE | W21: 是 | X21: 电力 0.06300 kWh | Y21: 旧版 0.0464 已排除（Q01）；0.93 统一后或小幅变化（Q03） | Z21: CAD-F17 | AA21: 直接报告 | AB21: kWh/kg SPI | AC21: kWh/kg SPI
A22: F18 | B22: M3 | C22: 热量 | D22: 能源 | E22: 输入 | G22: M3 | H22: physical_energy | I22: 27.500833 | J22: MJ | K22: 1 kg SPI | L22: EQ-H3 | M22: Formulas_SPI heat_mix / SPI!I49 | N22: 加热+喷雾+闪蒸（详见 Formulas_SPI） | P22: 27.500833 | Q22: MJ | R22: + | S22: 否 | T22: CLCA不分配-模块总量 | U22: SRC-XLS-OLD | V22: PASS | W22: 是 | X22: 热 27.5008 MJ | Z22: CAD-F18 | AA22: 直接报告 | AB22: MJ/kg SPI | AC22: MJ/kg SPI
A23: F19 | B23: M3 | C23: SPI 主产品 | D23: 物理流 | E23: 输出 | F23: M3 | H23: physical_material | I23: 1 | J23: kg | K23: 1 kg SPI | L23: FU | M23: 功能单位 | N23: 1 | O23: 常量（功能单位直接报告） | P23: 1 | Q23: kg | R23: + | S23: 否 | T23: 主产品 | U23: SRC-PDF | V23: PASS | W23: 是 | X23: 大豆分离蛋白（SPI）1.0000 kg 干物质 95% | AA23: 直接报告 | AB23: kg/kg SPI | AC23: kg/kg SPI
A24: F20 | B24: M3 | C24: spent flakes | D24: 物理流 | E24: 输出 | F24: M3 | H24: physical_material | I24: 0.54494 | J24: kg | K24: 1 kg SPI | L24: EQ-SF | M24: WF×P24×0.9/0.2×... 源公式 | N24: SF=WF×P24（干基 90%） | O24: P24 | P24: 0.54494 | Q24: kg | R24: + | S24: 否 | T24: 共产品显式保留-替代接口未定义 | U24: SRC-XLS-OLD | V24: PASS | W24: 是 | X24: 提取后豆片 0.5449 kg（含水约 10%） | AA24: 公式派生 | AB24: kg/kg 白豆片 | AC24: kg/kg SPI
A25: F21 | B25: M3 | C25: whey-rich 水相 | D25: 物理流 | E25: 输出 | F25: M3 | H25: physical_material | I25: 11.490193 | J25: kg | K25: 1 kg SPI | L25: EQ-WHEY | M25: Formulas_SPI wastewater | N25: whey=WF×P25×P07 | O25: P25;P07 | P25: 11.490193 | Q25: kg | R25: + | S25: 否 | T25: 审计中-不称严格总废水 | U25: SRC-XLS-OLD | V25: REVIEW | W25: 是 | X25: 乳清水相 11.490 kg* | Y25: 作者 runtime wastewater=0.01149019 m³；受 0.93 影响（Q03/Q04） | Z25: CAD-F21 | AA25: 公式派生 | AB25: kg/kg 白豆片 | AC25: kg/kg SPI
A26: F22 | B26: M3 | C26: 喷雾干燥水蒸气 | D26: 物理流 | E26: 输出 | F26: M3 | H26: physical_material | I26: 4.9375 | J26: kg | K26: 1 kg SPI | L26: EQ-V1 | M26: P01/P22-1 | N26: vapor=P01/P22-1 | O26: P01;P22 | P26: 4.9375 | Q26: kg | R26: + | S26: 否 | T26: 物理输出-是否 elementary exchange 另定 | U26: SRC-XLS-OLD | V26: PASS_WITH_NOTE | W26: 是 | X26: 蒸发水 4.9375 kg | Y26: 从喷雾干燥单向输出 | AA26: 公式派生 | AB26: kg/kg SPI | AC26: kg/kg SPI
A27: F23 | B27: M3 | C27: 闪蒸干燥水蒸气 | D27: 物理流 | E27: 输出 | F27: M3 | H27: physical_material | I27: 0.209592 | J27: kg | K27: 1 kg SPI | L27: EQ-V2 | M27: SPI 内部质量/能量公式 | N27: vapor=0.209592 | O27: 常量（EQ-V2 派生，见来源公式） | P27: 0.209592 | Q27: kg | R27: + | S27: 否 | T27: 物理输出-是否 elementary exchange 另定 | U27: SRC-XLS-OLD | V27: PASS_WITH_NOTE | W27: 是 | X27: 水蒸气 0.2096 kg | Y27: 从闪蒸干燥单向输出 | AA27: 公式派生 | AB27: kg/kg SPI | AC27: kg/kg SPI
A28: F24 | B28: M3 | C28: 外部新鲜水 tap_water（Formulas_SPI） | D28: 物理流 | E28: 输入 | G28: M3 | H28: physical_material | I28: 16.98 | J28: kg | K28: 1 kg SPI | L28: EQ-W5 | M28: SPI!I50 | N28: Overview 口径 | O28: 常量（SPI!I50 直接报告） | P28: 16.980004 | Q28: kg | R28: + | S28: 否 | T28: 审计中-暂不锁定最终 exchange | U28: SRC-XLS-OLD | V28: PASS_WITH_NOTE | W28: 是 | X28: 外部取水 16.98 kg | Y28: 官方参数重算=16.980004 与 Formulas_SPI 一致；Overview I50=16.5036 为另一公式（自带水按供给扣减，物理更优）；两者差0.4764为自带水符号处理差异；建模取水exchange采用16.98（忠实平台，用户2026-09-27决定A）；废水exchange=乳清11.490 kg（0.01149 m³） | AA28: 直接报告 | AB28: kg/kg SPI | AC28: kg/kg SPI
A29: F25 | B29: M1 | C29: 豆皮-替代接口 | D29: 方法接口 | E29: 输出 | F29: M1 | H29: substitution_candidate | K29: 1 kg SPI | M29: CLCA 替代接口占位 | N29: 占位接口-无量值公式 | O29: 无（接口占位） | Q29: kg | R29: + | S29: 否 | T29: substitution_candidate-接口未定义 | U29: SRC-CLCA-HANDOVER | V29: NOT_APPLICABLE | W29: 否 | AB29: 接口登记 | AC29: kg/kg SPI（占位）
A30: F26 | B30: M2 | C30: 豆油-替代接口 | D30: 方法接口 | E30: 输出 | F30: M2 | H30: substitution_candidate | K30: 1 kg SPI | M30: 同上 | N30: 占位接口-无量值公式 | O30: 无（接口占位） | Q30: kg | R30: + | S30: 否 | T30: substitution_candidate-接口未定义 | U30: SRC-CLCA-HANDOVER | V30: NOT_APPLICABLE | W30: 否 | AB30: 接口登记 | AC30: kg/kg SPI（占位）
A31: F27 | B31: M3 | C31: spent flakes-替代接口 | D31: 方法接口 | E31: 输出 | F31: M3 | H31: substitution_candidate | K31: 1 kg SPI | M31: 同上 | N31: 占位接口-无量值公式 | O31: 无（接口占位） | Q31: kg | R31: + | S31: 否 | T31: substitution_candidate-接口未定义 | U31: SRC-CLCA-HANDOVER | V31: NOT_APPLICABLE | W31: 否 | AB31: 接口登记 | AC31: kg/kg SPI（占位）

Sheet 核算检查
A1: 核算检查
A2: 检查表只记录诊断，不作为模型输入。BLOCKED 未解决前不得冻结。
A4: 检查ID | B4: 检查类型 | C4: 对象类型 | D4: 对象ID | E4: 检查方法/公式 | F4: 期望值 | G4: 实际值 | H4: 单位 | I4: 容差 | J4: 差值 | K4: 结果 | L4: 问题ID | M4: 说明 | N4: 审查路线 | O4: 实际验证结论 | P4: 影响对象ID
A5: CHK01 | B5: 物质平衡 | C5: 流 | D5: F01;F02;F03 | E5: 大豆原料 = 脱皮大豆+豆皮 | F5: 2.722899 | G5: 2.722899 | H5: kg | I5: 0.001 | J5: =IF(OR(F5="",G5=""),"",G5-F5) | K5: PASS | M5: M1 输入=输出（含共产品） | N5: 来源内部核对（同一工作簿公式复算） | O5: 已执行：2.521203+0.201696=2.722899，一致 | P5: F01
A6: CHK02 | B6: 物质平衡 | C6: 过程 | D6: M2 | E6: 输入(脱皮豆+水+己烷)=输出(白豆片+油+废水+己烷排放) | F6: 3.149007 | G6: 3.089426 | H6: kg | I6: 0.02 | J6: =IF(OR(F6="",G6=""),"",G6-F6) | K6: REVIEW | L6: Q09 | M6: 差 0.0596 kg（1.9%）：1.27 与 1+0.24 差 0.03 kg/kg 未闭合 | N6: 来源内部核对 | O6: 已执行：差额登记，不硬补；作者参数化代表清单 | P6: F09;F10
A7: CHK03 | B7: 物质平衡 | C7: 过程 | D7: M3 | E7: 输入干物质(白豆片×0.88)=输出干物质(SPI+豆渣×0.9+whey×0.03) | F7: 1.747 | G7: 1.7851 | H7: kg DM | I7: 0.01 | J7: =IF(OR(F7="",G7=""),"",G7-F7) | K7: REVIEW | L7: Q03 | M7: 输出超输入约 2.2%；0.93 口径输入 1.8462 亦不闭合 | N7: 来源内部核对 | O7: 已执行：干物质超额登记，受影响流标审计中 | P7: F21;F22
A8: CHK04 | B8: 单位检查 | C8: 流 | D8: F04 | E8: 23.4 kJ/kg×2.521203 kg÷3600 | F8: 0.016388 | G8: 0.016387818 | H8: kWh | I8: 1e-06 | J8: =IF(OR(F8="",G8=""),"",G8-F8) | K8: PASS | M8: kJ→kWh 换算 | N8: 基础审查 | O8: 已执行：一致 | P8: F04
A9: CHK05 | B9: 单位检查 | C9: 流 | D9: F07 | E9: 142.983 kJ/kg×1.985199÷3600 | F9: 0.078847 | G9: 0.078847119 | H9: kWh | I9: 1e-06 | J9: =IF(OR(F9="",G9=""),"",G9-F9) | K9: PASS | M9: kJ→kWh 换算 | N9: 基础审查 | O9: 已执行：一致 | P9: F07
A10: CHK06 | B10: 单位检查 | C10: 流 | D10: F08 | E10: 951.918 kJ/kg×1.985199÷1000 | F10: 1.889747 | G10: 1.8897466 | H10: MJ | I10: 1e-06 | J10: =IF(OR(F10="",G10=""),"",G10-F10) | K10: PASS | M10: kJ→MJ 换算 | N10: 基础审查 | O10: 已执行：一致 | P10: F08
A11: CHK07 | B11: 版本检查 | C11: 流 | D11: F17 | E11: 旧版 I48=0.0463879 vs 当前版/runtime=0.0629995 | F11: 0.0629995 | G11: 0.062999518 | H11: kWh | I11: 1e-07 | J11: =IF(OR(F11="",G11=""),"",G11-F11) | K11: PASS_WITH_NOTE | L11: Q01 | M11: 旧版 L6=3 硬编码；采用当前版值 | N11: 来源内部核对（版本对照） | O11: 已执行：差异原因已查清并决策 | P11: F17
A12: CHK08 | B12: 代表值复算 | C12: 流 | D12: F18 | E12: SPI!I49=27500.8326 kJ=27.5008 MJ | F12: 27.5008 | G12: 27.500833 | H12: MJ | I12: 0.0001 | J12: =IF(OR(F12="",G12=""),"",G12-F12) | K12: PASS | M12: kJ→MJ | N12: 基础审查 | O12: 已执行：一致 | P12: F18
A13: CHK09 | B13: 内部流检查 | C13: 流 | D13: F02;F09 | E13: 内部流不得重复计为外部投入/产出 | F13: 0 | G13: 0 | H13: kg | I13: 0 | J13: =IF(OR(F13="",G13=""),"",G13-F13) | K13: PASS | M13: 跨模块物流各只出现一次 | N13: 结构检查 | O13: 已执行：F02/F09 只作模块间连接 | P13: F02;F09
A14: CHK10 | B14: 重复计入 | C14: 流 | D14: F05;F11 | E14: M2 水输入=废水输出（同参数） | F14: 0.62507 | G14: 0.62507 | H14: kg | I14: 1e-06 | J14: =IF(OR(F14="",G14=""),"",G14-F14) | K14: PASS_WITH_NOTE | M14: 同值但分属输入/输出两侧，不重复计入 | N14: 基础审查 | O14: 已执行：作者模型同值假设已注明 | P14: F05;F11
A15: CHK11 | B15: 方向符号 | C15: 流 | D15: F12;F21 | E15: 源公式 wastewater 带 (-1) 为软件交换约定 | F15: 0 | G15: 0 | H15: - | I15: 0 | J15: =IF(OR(F15="",G15=""),"",G15-F15) | K15: PASS_WITH_NOTE | M15: 负号≠负质量，方向单独记录 | N15: 基础审查 | O15: 已执行：符号与方向分开登记 | P15: F12;F21
A16: CHK12 | B16: 覆盖检查 | C16: 模型 | D16: ALL | E16: 采用流 24+接口 3 均有来源/公式/ID/基准 | F16: 27 | G16: 27 | H16: 条 | I16: 0 | J16: =IF(OR(F16="",G16=""),"",G16-F16) | K16: PASS | M16: 逐流记录完整性 | N16: 结构检查 | O16: 已执行：全部流卡字段齐备 | P16: ALL
A17: CHK13 | B17: 能源汇总 | C17: 过程 | D17: PS-SPI | E17: 全流程电=0.016388+0.078847+0.0629995；热=1.889747+27.500833 | F17: 0.158235 | G17: 0.15823445 | H17: kWh | I17: 1e-06 | J17: =IF(OR(F17="",G17=""),"",G17-F17) | K17: PASS | M17: 电/热分别汇总，不合并载体 | N17: 基础审查 | O17: 已执行：电 0.158234 kWh、热 29.39058 MJ 分别成立 | P17: F04;F07;F17
A18: CHK14 | B18: 方法处理 | C18: 模型 | D18: ALL | E18: price ratio/allocation 全部排除，共产品显式 | F18: 0 | G18: 0 | H18: - | I18: 0 | J18: =IF(OR(F18="",G18=""),"",G18-F18) | K18: PASS | L18: Q02 | M18: 作者 ALCA 经济分配仅作方法证据 | N18: 方法检查 | O18: 已执行：CAD-33/34/35 已排除；F25–F27 接口占位 | P18: ALL
A19: CHK15 | B19: 可比性 | C19: 参数 | D19: P08;P14 | E19: 1.27 vs 1+0.24 的 0.03 差额 | F19: 0.03 | G19: 0.03 | H19: kg/kg | I19: 0 | J19: =IF(OR(F19="",G19=""),"",G19-F19) | K19: REVIEW | L19: Q09 | M19: 多文献参数化非单一工厂闭合平衡 | N19: 来源内部核对 | O19: 已执行：按作者代表值采用，方法中说明 | P19: F09
J20: =IF(OR(F20="",G20=""),"",G20-F20)
J21: =IF(OR(F21="",G21=""),"",G21-F21)
J22: =IF(OR(F22="",G22=""),"",G22-F22)
J23: =IF(OR(F23="",G23=""),"",G23-F23)
J24: =IF(OR(F24="",G24=""),"",G24-F24)
J25: =IF(OR(F25="",G25=""),"",G25-F25)
J26: =IF(OR(F26="",G26=""),"",G26-F26)
J27: =IF(OR(F27="",G27=""),"",G27-F27)
J28: =IF(OR(F28="",G28=""),"",G28-F28)
J29: =IF(OR(F29="",G29=""),"",G29-F29)
J30: =IF(OR(F30="",G30=""),"",G30-F30)
J31: =IF(OR(F31="",G31=""),"",G31-F31)
... J204: =IF(OR(F204="",G204=""),"",G204-F204)

Sheet 问题与决策
A1: 问题与决策
A2: 保留来源差异、影响、候选处理和用户决定；实际改变要写回事实表。
A4: 问题ID | B4: 对象类型 | C4: 对象ID | D4: 问题描述 | E4: 证据/来源 | F4: 影响 | G4: 候选处理 | H4: 用户决定 | I4: 状态 | J4: 执行位置 | K4: 更新日期 | L4: 备注 | M4: 是否阻断冻结 | N4: 确认日期 | O4: 归属操作ID
A5: Q01 | B5: 文件 | C5: SRC-XLS-OLD | D5: 本轮附件 SPI-Siegrist2026.xlsx 为旧版本：SPI!L6=3 硬编码→I48=0.0464 kWh；当前版 (1) 与 ppplca runtime 为 0.0629995；且 (1) 版与 runtime 文件未随附件提供 | E5: 上一轮代码审计（交接文档§2/§4） | F5: F17 模块电耗；版本可信度 | G5: CAD-29 采用（0.0630）；CAD-30 排除（0.0464） | H5: 采用 0.0629995 kWh/kg SPI；旧值仅作版本证据；如需代码复现需用户补充 (1) 版与 Processing_data.xlsx | I5: 已解决 | J5: 候选数据/模型参数 | K5: 2026-09-26 | L5: 2026-09-26 查明：上一轮“(1)版”即期刊官方补充材料 mmc2.xlsx，已重新下载并比对一致 | M5: 否 | N5: 2026-09-19 | O5: M3
A6: Q02 | B6: 方法 | C6: PS-SPI | D6: 来源为 ALCA+economic allocation；本研究采用 CLCA，不做分配 | E6: 交接文档§1；论文§2.1 | F6: 全部 price ratio 参数；共产品处理 | G6: CAD-33/34/35 排除；F25–F27 登记替代接口 | H6: CLCA 不分配；豆皮/豆油/spent flakes 显式物理共产品；替代/系统扩展在 CLCA 层另定（用户 2026-09-19 锁定，本轮沿用） | I6: 已解决 | J6: 项目说明/模型流 | K6: 2026-09-26 | L6: 闸门C条件②③证据 | M6: 否 | N6: 2026-09-19 | O6: PS-SPI
A7: Q03 | B7: 参数 | C7: P05;P23;P24;P25;P28 | D7: white flakes 干物质正式参数 0.88，但 K6/I56 等硬编码 0.93 并传入派生质量流/密度/whey | E7: 上一轮审计 A07/A08 | F7: F21 whey、F17 部分离心电耗、CHK03 干物质平衡 | G7: 保留作者代表值；受影响流标审计中 | H7: 暂不修正、不替换正式清单；下一阶段做完整依赖链重算（统一 0.88 情景对照）后再决定 | I7: 未解决 | J7: 问题表 | K7: 2026-09-26 | L7: 0.88 下输出超输入 2.2% | M7: 是（对受影响水相/电耗的最终冻结） | O7: M3
A8: Q04 | B8: 流 | C8: F13;F14;F21;F24 | D8: SPI 水系统口径不一致：步骤加水 19.852+6、Overview 16.5036、Formulas_SPI 16.98、whey 11.490 | E8: 上一轮审计 A10/A11/A24 | F8: 外部 fresh water 与净废水 exchange 无法锁定 | G8: F24 暂不显示；F13/F14 仅作步骤加水 | H8: 已解决：外部取水=16.98 kg（Formulas_SPI公式按官方参数重算验证）；总进水17.49（含豆片自带0.238与酸碱溶液水0.268）vs 总出水16.74（乳清11.490+蒸发5.148+豆渣0.054+产品0.050），残差0.74源于作者公式未计酸碱溶液水；投水25.852与净取水16.98之差8.87为内部循环，不进LCI；6 kg洗涤水经源注释判决属离心4蛋白洗涤（图已修正）。用户2026-09-27确认。；2026-09-27 图面同步：模块Ⅲ水输入改为外部取水 16.98，工艺投水 25.852 撤出图面（进 17.49 ↔ 出 16.74，残差 0.74 为作者公式未计酸碱溶液水） | I8: 已解决 | J8: 问题表 | K8: 2026-09-26 | M8: 是（对 M3 外部水 exchange 的最终冻结） | O8: M3
A9: Q05 | B9: 流 | C9: F15;F16 | D9: NaOH/HCl 最终 LCI 单位为 kg，但源系数由 10% 溶液体积折算，缺密度/浓度换算链 | E9: 上一轮审计 A12/A13 | F9: 化学品 exchange 质量映射 | G9: 保留 10% 溶液体积并加* | H9: 核对目标背景数据库 reference product（solution vs active substance）后补齐密度/浓度换算 | I9: 未解决 | J9: 问题表 | K9: 2026-09-26 | L9: soy-specific 数据弱，属模型假设 | M9: 是（对酸碱 exchange 的最终冻结） | O9: M3
A10: Q06 | B10: 流 | C10: F12 | D10: hexane 排放数值可用，但环境介质（air/water/unspecified）未定 | E10: 上一轮审计 | F10: 排放 compartment 映射 | G10: 保留数值 | H10: 背景数据库映射时确定 compartment | I10: 未解决 | J10: 问题表 | K10: 2026-09-26 | L10: 不阻断骨架与模块值 | M10: 否 | O10: M2
A11: Q07 | B11: 来源 | C11: SYS-Siegrist2026 | D11: 数据表版本溯源：旧版 README 声明归属同组早期论文（Parametric assessment of regionalized...），官方 SI2/runtime 归属 SPC 2026；作者 2025-08 后未再修改数据 | E11: SRC-XLS-OLD README; SRC-README | F11: 来源体系同一性 | G11: 旧版=早期论文流传版（含 L6=3 bug）；官方 mmc2=当前版 | H11: 以官方 SI2（mmc2）为当前权威版；旧版仅作版本证据。规则沉淀：版本核验先看文件内部 README 归属与论文 DOI 是否一致 | I11: 已解决 | J11: 数据来源 | K11: 2026-09-26 | M11: 否 | O11: PS-SPI
A12: Q08 | B12: 来源 | C12: 候选数据 | D12: 参数原始文献（Sheehan/Dalgaard/Brasil 等）为数据表内的二级引用，未独立核对原文 | E12: SRC-XLS-OLD Data sources overview | F12: 候选证据等级 | G12: 全部参数候选标二级引用 | H12: 当前采用可用；GSA/跨源比较前需独立核对原文 | I12: 已解决 | J12: 候选数据 | K12: 2026-09-26 | M12: 否 | O12: PS-SPI
A13: Q09 | B13: 参数 | C13: P08;P14 | D13: 脱脂模块质量不闭合：1.27 kg 脱皮豆 vs 1 kg 白豆片+0.24 kg 油，差 0.03 kg/kg | E13: 上一轮审计 A05；SPI前景清单质量平衡1.xlsx | F13: CHK02/CHK15；全流程物理闭合 | G13: 不硬补差额 | H13: 按作者参数化代表清单采用并在方法中说明；差额成分列入待补 | I13: 未解决 | J13: 问题表 | K13: 2026-09-26 | M13: 否 | O13: M2
A14: Q10 | B14: 文件 | C14: SRC-XLS-OLD | D14: 本轮附件曾缺当前版详细工作簿与 runtime 文件；2026-09-26 均已补齐（官方 SI2 mmc2.xlsx + GitHub runtime） | E14: 交接文档§3；GitHub siegarmi/ppplca（2026-09-26 下载复核） | F14: 证据链完整性（非当前阻塞） | G14: SI2 与 runtime 互为印证：39 个 SPI 参数完全一致；SPI!I48=0.0629995 | H14: 证据链完整闭合，无需进一步补充 | I14: 已解决 | J14: 待补清单 | K14: 2026-09-26 | M14: 否 | O14: PS-SPI

Sheet 绘图确认
A1: 绘图确认
A2: 科学字段由模型过程和模型流派生；用户只确认展开、显示、标签和样式。
A3: 只确认展开、显示和标签；L/M列自动引用模型流，不能手填科学数值。
A4: 对象ID | B4: 对象类型 | C4: 来源ID | D4: 所属车间 | E4: 来源过程ID | F4: 目标过程ID | G4: 主支线ID | H4: 展开方式 | I4: 是否显示 | J4: 显示标签 | K4: 是否显示数值 | L4: 代表值 | M4: 单位 | N4: 标签模式 | O4: 样式角色 | P4: 数据功能确认 | Q4: 绘图功能确认 | R4: Draw.io对象ID | S4: QA状态 | T4: 关联问题ID | U4: 备注
A5: F01 | B5: Edge | C5: SRC-CLCA-AUDIT | D5: 预处理 | F5: M1-OP1 | G5: 主线 | H5: as_modelled | I5: 是 | J5: 原始大豆 2.7229 kg | K5: 是 | L5: =IF(模型流与公式!P5="","",模型流与公式!P5) | M5: =IF(模型流与公式!Q5="","",模型流与公式!Q5) | N5: name_value_unit | O5: input_box | P5: 已确认(补记2026-09-27) | Q5: 待用户确认 | R5: ext_F01 | S5: PASS 2026-09-27 v15机器回归
A6: F02 | B6: Edge | C6: SRC-CLCA-AUDIT | D6: 预处理 | E6: M1-OP1 | F6: M2-OP1 | G6: 主线 | H6: as_modelled | I6: 是 | J6: 去壳大豆 2.5212 kg | K6: 是 | L6: =IF(模型流与公式!P6="","",模型流与公式!P6) | M6: =IF(模型流与公式!Q6="","",模型流与公式!Q6) | N6: name_value_unit | O6: link_label | P6: 已确认(补记2026-09-27) | Q6: 待用户确认 | R6: lab_F02 | S6: PASS 2026-09-27 v15机器回归
A7: F03 | B7: Edge | C7: SRC-XLS-OLD | D7: 预处理 | E7: M1-OP1 | G7: 主线 | H7: as_modelled | I7: 是 | J7: 豆壳 0.2017 kg | K7: 是 | L7: =IF(模型流与公式!P7="","",模型流与公式!P7) | M7: =IF(模型流与公式!Q7="","",模型流与公式!Q7) | N7: name_value_unit | O7: output_box | P7: 已确认(补记2026-09-27) | Q7: 待用户确认 | R7: out_F03 | S7: PASS 2026-09-27 v15机器回归
A8: F04 | B8: Edge | C8: SRC-XLS-OLD | D8: 预处理 | F8: M1 | G8: 主线 | H8: as_modelled | I8: 是 | J8: 电力 0.01639 kWh | K8: 是 | L8: =IF(模型流与公式!P8="","",模型流与公式!P8) | M8: =IF(模型流与公式!Q8="","",模型流与公式!Q8) | N8: value_unit | O8: module_energy | P8: 已确认(补记2026-09-27) | Q8: 待用户确认 | R8: energy_M1_e | S8: PASS 2026-09-27 v15机器回归
A9: F05 | B9: Edge | C9: SRC-XLS-OLD | D9: 预处理 | F9: M2 | G9: 主线 | H9: as_modelled | I9: 是 | J9: 工艺水 0.6251 kg | K9: 是 | L9: =IF(模型流与公式!P9="","",模型流与公式!P9) | M9: =IF(模型流与公式!Q9="","",模型流与公式!Q9) | N9: name_value_unit | O9: module_box | P9: 已确认(补记2026-09-27) | Q9: 待用户确认 | R9: ext_F05 | S9: PASS 2026-09-27 v15机器回归
A10: F06 | B10: Edge | C10: SRC-XLS-OLD | D10: 预处理 | F10: M2-OP3 | G10: 主线 | H10: as_modelled | I10: 是 | J10: 新鲜正己烷 0.002728 kg | K10: 是 | L10: =IF(模型流与公式!P10="","",模型流与公式!P10) | M10: =IF(模型流与公式!Q10="","",模型流与公式!Q10) | N10: name_value_unit | O10: input_box | P10: 已确认(补记2026-09-27) | Q10: 待用户确认 | R10: ext_F06 | S10: PASS 2026-09-27 v15机器回归
A11: F07 | B11: Edge | C11: SRC-XLS-OLD | D11: 预处理 | F11: M2 | G11: 主线 | H11: as_modelled | I11: 是 | J11: 电力 0.07885 kWh | K11: 是 | L11: =IF(模型流与公式!P11="","",模型流与公式!P11) | M11: =IF(模型流与公式!Q11="","",模型流与公式!Q11) | N11: value_unit | O11: module_energy | P11: 已确认(补记2026-09-27) | Q11: 待用户确认 | R11: energy_M2_e | S11: PASS 2026-09-27 v15机器回归
A12: F08 | B12: Edge | C12: SRC-XLS-OLD | D12: 预处理 | F12: M2 | G12: 主线 | H12: as_modelled | I12: 是 | J12: 热 1.88975 MJ | K12: 是 | L12: =IF(模型流与公式!P12="","",模型流与公式!P12) | M12: =IF(模型流与公式!Q12="","",模型流与公式!Q12) | N12: value_unit | O12: module_energy | P12: 已确认(补记2026-09-27) | Q12: 待用户确认 | R12: energy_M2_h | S12: PASS 2026-09-27 v15机器回归
A13: F09 | B13: Edge | C13: SRC-XLS-OLD | D13: 预处理 | E13: M2-OP4 | F13: M3-OP1 | G13: 主线 | H13: as_modelled | I13: 是 | J13: 白豆片 1.9852 kg 干物质 88% | K13: 是 | L13: =IF(模型流与公式!P13="","",模型流与公式!P13) | M13: =IF(模型流与公式!Q13="","",模型流与公式!Q13) | N13: name_value_unit | O13: link_label | P13: 已确认(补记2026-09-27) | Q13: 待用户确认 | R13: lab_F09 | S13: PASS 2026-09-27 v15机器回归
A14: F10 | B14: Edge | C14: SRC-XLS-OLD | D14: 预处理 | E14: M2-OP3 | G14: 主线 | H14: as_modelled | I14: 是 | J14: 豆油 0.4764 kg | K14: 是 | L14: =IF(模型流与公式!P14="","",模型流与公式!P14) | M14: =IF(模型流与公式!Q14="","",模型流与公式!Q14) | N14: name_value_unit | O14: output_box | P14: 已确认(补记2026-09-27) | Q14: 待用户确认 | R14: out_F10 | S14: PASS 2026-09-27 v15机器回归
A15: F11 | B15: Edge | C15: SRC-XLS-OLD | D15: 预处理 | E15: M2 | G15: 主线 | H15: as_modelled | I15: 是 | J15: 工艺废水 0.6251 kg | K15: 是 | L15: =IF(模型流与公式!P15="","",模型流与公式!P15) | M15: =IF(模型流与公式!Q15="","",模型流与公式!Q15) | N15: name_value_unit | O15: module_box | P15: 已确认(补记2026-09-27) | Q15: 待用户确认 | R15: out_F11 | S15: PASS 2026-09-27 v15机器回归
A16: F12 | B16: Edge | C16: SRC-XLS-OLD | D16: 预处理 | E16: M2-OP3 | G16: 主线 | H16: as_modelled | I16: 是 | J16: 正己烷排放 0.002728 kg | K16: 是 | L16: =IF(模型流与公式!P16="","",模型流与公式!P16) | M16: =IF(模型流与公式!Q16="","",模型流与公式!Q16) | N16: name_value_unit | O16: output_box | P16: 已确认(补记2026-09-27) | Q16: 待用户确认 | R16: out_F12 | S16: PASS 2026-09-27 v15机器回归
A17: F13 | B17: Edge | C17: SRC-XLS-OLD | D17: 蛋白分离 | F17: M3 | G17: 主线 | H17: as_modelled | I17: 否 | J17: （工艺投水，不进 LCI 图面） | K17: 否 | L17: =IF(模型流与公式!P17="","",模型流与公式!P17) | M17: =IF(模型流与公式!Q17="","",模型流与公式!Q17) | N17: none | O17: omit | P17: 已确认(补记2026-09-27) | Q17: 待用户确认 | S17: PASS 2026-09-27 v15机器回归 | T17: Q04
A18: F14 | B18: Edge | C18: SRC-XLS-OLD | D18: 蛋白分离 | F18: M3 | G18: 主线 | H18: as_modelled | I18: 否 | J18: （工艺投水，不进 LCI 图面） | K18: 否 | L18: =IF(模型流与公式!P18="","",模型流与公式!P18) | M18: =IF(模型流与公式!Q18="","",模型流与公式!Q18) | N18: none | O18: omit | P18: 已确认(补记2026-09-27) | Q18: 待用户确认 | S18: PASS 2026-09-27 v15机器回归 | T18: Q04
A19: F15 | B19: Edge | C19: SRC-XLS-OLD | D19: 蛋白分离 | F19: M3-OP1 | G19: 主线 | H19: as_modelled | I19: 是 | J19: NaOH 10% 溶液 0.1241 L* | K19: 是 | L19: =IF(模型流与公式!P19="","",模型流与公式!P19) | M19: =IF(模型流与公式!Q19="","",模型流与公式!Q19) | N19: name_value_unit | O19: input_box | P19: 已确认(补记2026-09-27) | Q19: 待用户确认 | R19: ext_F15 | S19: PASS 2026-09-27 v15机器回归 | T19: Q05
A20: F16 | B20: Edge | C20: SRC-XLS-OLD | D20: 蛋白分离 | F20: M3-OP3 | G20: 主线 | H20: as_modelled | I20: 是 | J20: HCl 10% 溶液 0.1737 L* | K20: 是 | L20: =IF(模型流与公式!P20="","",模型流与公式!P20) | M20: =IF(模型流与公式!Q20="","",模型流与公式!Q20) | N20: name_value_unit | O20: input_box | P20: 已确认(补记2026-09-27) | Q20: 待用户确认 | R20: ext_F16 | S20: PASS 2026-09-27 v15机器回归 | T20: Q05
